Workbook

Sheet Dashboard
A1: DASHBOARD — Báo cáo hiệu quả truyền thông & ROI (đối soát với Booklet 2)
A2: • Dữ liệu: 191 dòng thô gộp còn 145 liên hệ duy nhất, tỉ lệ trùng khoảng 24,1%.
A3: • Mọi con số bên dưới là công thức tham chiếu Contacts_Attribution và Nguồn & ROI; sửa dữ liệu thì dashboard tự cập nhật.
A4: • Số liệu Google, TikTok, Email, Zalo là GIẢ ĐỊNH (chia từ nhóm web chưa gắn UTM); Facebook và Đối tác trường lấy từ Booklet 2.
A6: 1. Dữ liệu thô → dữ liệu sạch
A7: Chỉ số | B7: Giá trị
A8: Số dòng thô (3 nguồn) | B8: 191
A9: Số liên hệ duy nhất sau khi gộp | B9: =COUNTA(Contacts_Attribution!$A$7:$A$151) -> 145
A10: Số bản ghi bị gộp | B10: =B8-B9 -> 46
A11: Tỉ lệ trùng lặp | B11: =B10/B8 -> 0.2408377
A13: 2. Phễu kinh doanh
A14: Chỉ số | B14: Giá trị
A15: Đã đăng ký trên website | B15: ='Nguồn & ROI'!C13 -> 119
A16: Đã thanh toán (thí sinh chính thức) | B16: ='Nguồn & ROI'!E13 -> 66
A17: Lead chưa đăng ký | B17: ='Nguồn & ROI'!D13 -> 26
A18: Tỉ lệ thanh toán / đăng ký web | B18: ='Nguồn & ROI'!F13 -> 0.55462185
A19: Doanh thu ghi nhận (VND) | B19: ='Nguồn & ROI'!H13 -> 18100000
A20: Tổng ngân sách truyền thông (VND) | B20: ='Nguồn & ROI'!G13 -> 8500000
A21: ROI toàn chương trình | B21: ='Nguồn & ROI'!I13 -> 1.1294118
A23: 3. Hiệu quả 6 kênh có ngân sách
A24: Kênh | B24: Đăng ký web | C24: Đã thanh toán | D24: ROI | E24: CPA thanh toán (VND)
A25: ='Nguồn & ROI'!A5 -> Facebook | B25: ='Nguồn & ROI'!C5 -> 19 | C25: ='Nguồn & ROI'!E5 -> 9 | D25: ='Nguồn & ROI'!I5 -> 0.21666667 | E25: ='CPA Analysis'!G5 -> 333333.33
A26: ='Nguồn & ROI'!A6 -> Google | B26: ='Nguồn & ROI'!C6 -> 13 | C26: ='Nguồn & ROI'!E6 -> 2 | D26: ='Nguồn & ROI'!I6 -> -0.6 | E26: ='CPA Analysis'!G6 -> 1250000
A27: ='Nguồn & ROI'!A7 -> TikTok | B27: ='Nguồn & ROI'!C7 -> 9 | C27: ='Nguồn & ROI'!E7 -> 0 | D27: ='Nguồn & ROI'!I7 -> -1 | E27: ='CPA Analysis'!G7 -> n/a
A28: ='Nguồn & ROI'!A8 -> Email | B28: ='Nguồn & ROI'!C8 -> 5 | C28: ='Nguồn & ROI'!E8 -> 3 | D28: ='Nguồn & ROI'!I8 -> 6.5 | E28: ='CPA Analysis'!G8 -> 66666.667
A29: ='Nguồn & ROI'!A9 -> Zalo | B29: ='Nguồn & ROI'!C9 -> 5 | C29: ='Nguồn & ROI'!E9 -> 3 | D29: ='Nguồn & ROI'!I9 -> 0.5 | E29: ='CPA Analysis'!G9 -> 333333.33
A30: ='Nguồn & ROI'!A10 -> Đối tác trường | B30: ='Nguồn & ROI'!C10 -> 7 | C30: ='Nguồn & ROI'!E10 -> 4 | D30: ='Nguồn & ROI'!I10 -> 2.3333333 | E30: ='CPA Analysis'!G10 -> 75000

Sheet Contacts_Attribution
A1: CONTACTS_ATTRIBUTION — Gán kênh cho 145 liên hệ duy nhất (nguồn: Master_Contacts + Main_Signups_Clean, Booklet 2)
A2: • 1 dòng = 1 Contact ID (đã gộp trùng), không chứa thông tin cá nhân.
A3: • Cột H (theo dữ liệu Booklet 2): Partner = info → Đối tác trường; Partner = metaads hoặc có FB Lead Form → Facebook; chỉ có Talkshow Google Form → Talkshow; còn lại → Website trực tiếp / chưa gắn UTM.
A4: • Cột I (GIẢ ĐỊNH, ô vàng): 32 liên hệ web chưa gắn UTM được chia cho Google 13, TikTok 9, Email 5, Zalo 5 vì Booklet 2 không có UTM của 4 kênh này. Xoá ô để trả liên hệ về nhóm Website trực tiếp.
A5: • Lệ phí chỉ tính cho dòng "Đã thanh toán" (khớp Dashboard Booklet 2: 18,1 triệu VND). Suất miễn phí tính là đã thanh toán nhưng doanh thu = 0.
A6: Contact ID | B6: Đăng ký web | C6: Trạng thái thanh toán | D6: Lệ phí ghi nhận (VND) | E6: Partner (UTM) | F6: Có FB Lead Form | G6: Có Talkshow Form | H6: Kênh gán theo dữ liệu Booklet 2 | I6: Điều chỉnh GIẢ ĐỊNH (Google/TikTok/Email/Zalo) | J6: Kênh cuối cùng
A7: PT-001 | B7: Có | C7: Đã thanh toán | D7: 500000 | F7: Có | G7: Không | H7: =IF(E7="info","Đối tác trường",IF(OR(E7="metaads",F7="Có"),"Facebook",IF(G7="Có","Talkshow","Website trực tiếp / chưa gắn UTM"))) -> Facebook | J7: =IF(I7<>"",I7,H7) -> Facebook
A8: PT-002 | B8: Có | C8: Đã thanh toán | D8: 500000 | F8: Không | G8: Không | H8: =IF(E8="info","Đối tác trường",IF(OR(E8="metaads",F8="Có"),"Facebook",IF(G8="Có","Talkshow","Website trực tiếp / chưa gắn UTM"))) -> Website trực tiếp / chưa gắn UTM | J8: =IF(I8<>"",I8,H8) -> Website trực tiếp / chưa gắn UTM
A9: PT-003 | B9: Có | C9: Đã thanh toán | D9: 500000 | F9: Không | G9: Không | H9: =IF(E9="info","Đối tác trường",IF(OR(E9="metaads",F9="Có"),"Facebook",IF(G9="Có","Talkshow","Website trực tiếp / chưa gắn UTM"))) -> Website trực tiếp / chưa gắn UTM | I9: Zalo | J9: =IF(I9<>"",I9,H9) -> Zalo
A10: PT-004 | B10: Có | C10: Đã thanh toán | D10: 500000 | F10: Không | G10: Không | H10: =IF(E10="info","Đối tác trường",IF(OR(E10="metaads",F10="Có"),"Facebook",IF(G10="Có","Talkshow","Website trực tiếp / chưa gắn UTM"))) -> Website trực tiếp / chưa gắn UTM | I10: Zalo | J10: =IF(I10<>"",I10,H10) -> Zalo
A11: PT-005 | B11: Có | C11: Đã thanh toán | D11: 500000 | F11: Không | G11: Có | H11: =IF(E11="info","Đối tác trường",IF(OR(E11="metaads",F11="Có"),"Facebook",IF(G11="Có","Talkshow","Website trực tiếp / chưa gắn UTM"))) -> Talkshow | J11: =IF(I11<>"",I11,H11) -> Talkshow
A12: PT-006 | B12: Có | C12: Đã thanh toán | D12: 500000 | F12: Không | G12: Không | H12: =IF(E12="info","Đối tác trường",IF(OR(E12="metaads",F12="Có"),"Facebook",IF(G12="Có","Talkshow","Website trực tiếp / chưa gắn UTM"))) -> Website trực tiếp / chưa gắn UTM | I12: Google | J12: =IF(I12<>"",I12,H12) -> Google
A13: PT-007 | B13: Có | C13: Miễn phí (free) | D13: 0 | E13: info | F13: Không | G13: Không | H13: =IF(E13="info","Đối tác trường",IF(OR(E13="metaads",F13="Có"),"Facebook",IF(G13="Có","Talkshow","Website trực tiếp / chưa gắn UTM"))) -> Đối tác trường | J13: =IF(I13<>"",I13,H13) -> Đối tác trường
A14: PT-008 | B14: Có | C14: Đã thanh toán | D14: 500000 | F14: Không | G14: Không | H14: =IF(E14="info","Đối tác trường",IF(OR(E14="metaads",F14="Có"),"Facebook",IF(G14="Có","Talkshow","Website trực tiếp / chưa gắn UTM"))) -> Website trực tiếp / chưa gắn UTM | I14: Google | J14: =IF(I14<>"",I14,H14) -> Google
A15: PT-009 | B15: Có | C15: Đã thanh toán | D15: 500000 | F15: Không | G15: Không | H15: =IF(E15="info","Đối tác trường",IF(OR(E15="metaads",F15="Có"),"Facebook",IF(G15="Có","Talkshow","Website trực tiếp / chưa gắn UTM"))) -> Website trực tiếp / chưa gắn UTM | J15: =IF(I15<>"",I15,H15) -> Website trực tiếp / chưa gắn UTM
A16: PT-010 | B16: Có | C16: Đã thanh toán | D16: 500000 | F16: Không | G16: Không | H16: =IF(E16="info","Đối tác trường",IF(OR(E16="metaads",F16="Có"),"Facebook",IF(G16="Có","Talkshow","Website trực tiếp / chưa gắn UTM"))) -> Website trực tiếp / chưa gắn UTM | J16: =IF(I16<>"",I16,H16) -> Website trực tiếp / chưa gắn UTM
A17: PT-011 | B17: Có | C17: Đã thanh toán | D17: 500000 | F17: Không | G17: Không | H17: =IF(E17="info","Đối tác trường",IF(OR(E17="metaads",F17="Có"),"Facebook",IF(G17="Có","Talkshow","Website trực tiếp / chưa gắn UTM"))) -> Website trực tiếp / chưa gắn UTM | J17: =IF(I17<>"",I17,H17) -> Website trực tiếp / chưa gắn UTM
A18: PT-012 | B18: Có | C18: Đã thanh toán | D18: 500000 | F18: Không | G18: Không | H18: =IF(E18="info","Đối tác trường",IF(OR(E18="metaads",F18="Có"),"Facebook",IF(G18="Có","Talkshow","Website trực tiếp / chưa gắn UTM"))) -> Website trực tiếp / chưa gắn UTM | I18: Email | J18: =IF(I18<>"",I18,H18) -> Email
A19: PT-013 | B19: Có | C19: Đã thanh toán | D19: 500000 | F19: Không | G19: Có | H19: =IF(E19="info","Đối tác trường",IF(OR(E19="metaads",F19="Có"),"Facebook",IF(G19="Có","Talkshow","Website trực tiếp / chưa gắn UTM"))) -> Talkshow | J19: =IF(I19<>"",I19,H19) -> Talkshow
A20: PT-014 | B20: Có | C20: Đã thanh toán | D20: 500000 | F20: Không | G20: Không | H20: =IF(E20="info","Đối tác trường",IF(OR(E20="metaads",F20="Có"),"Facebook",IF(G20="Có","Talkshow","Website trực tiếp / chưa gắn UTM"))) -> Website trực tiếp / chưa gắn UTM | I20: Email | J20: =IF(I20<>"",I20,H20) -> Email
A21: PT-015 | B21: Có | C21: Đã thanh toán | D21: 500000 | E21: metaads | F21: Không | G21: Không | H21: =IF(E21="info","Đối tác trường",IF(OR(E21="metaads",F21="Có"),"Facebook",IF(G21="Có","Talkshow","Website trực tiếp / chưa gắn UTM"))) -> Facebook | J21: =IF(I21<>"",I21,H21) -> Facebook
A22: PT-016 | B22: Có | C22: Đã thanh toán | D22: 500000 | F22: Không | G22: Có | H22: =IF(E22="info","Đối tác trường",IF(OR(E22="metaads",F22="Có"),"Facebook",IF(G22="Có","Talkshow","Website trực tiếp / chưa gắn UTM"))) -> Talkshow | J22: =IF(I22<>"",I22,H22) -> Talkshow
A23: PT-017 | B23: Có | C23: Đã thanh toán | D23: 500000 | F23: Không | G23: Không | H23: =IF(E23="info","Đối tác trường",IF(OR(E23="metaads",F23="Có"),"Facebook",IF(G23="Có","Talkshow","Website trực tiếp / chưa gắn UTM"))) -> Website trực tiếp / chưa gắn UTM | I23: Zalo | J23: =IF(I23<>"",I23,H23) -> Zalo
A24: PT-018 | B24: Có | C24: Đã thanh toán | D24: 500000 | F24: Không | G24: Không | H24: =IF(E24="info","Đối tác trường",IF(OR(E24="metaads",F24="Có"),"Facebook",IF(G24="Có","Talkshow","Website trực tiếp / chưa gắn UTM"))) -> Website trực tiếp / chưa gắn UTM | J24: =IF(I24<>"",I24,H24) -> Website trực tiếp / chưa gắn UTM
A25: PT-019 | B25: Có | C25: Đã thanh toán | D25: 500000 | E25: info | F25: Không | G25: Không | H25: =IF(E25="info","Đối tác trường",IF(OR(E25="metaads",F25="Có"),"Facebook",IF(G25="Có","Talkshow","Website trực tiếp / chưa gắn UTM"))) -> Đối tác trường | J25: =IF(I25<>"",I25,H25) -> Đối tác trường
A26: PT-020 | B26: Có | C26: Đã thanh toán | D26: 500000 | E26: metaads | F26: Không | G26: Không | H26: =IF(E26="info","Đối tác trường",IF(OR(E26="metaads",F26="Có"),"Facebook",IF(G26="Có","Talkshow","Website trực tiếp / chưa gắn UTM"))) -> Facebook | J26: =IF(I26<>"",I26,H26) -> Facebook
A27: PT-021 | B27: Có | C27: Đã thanh toán | D27: 500000 | F27: Không | G27: Không | H27: =IF(E27="info","Đối tác trường",IF(OR(E27="metaads",F27="Có"),"Facebook",IF(G27="Có","Talkshow","Website trực tiếp / chưa gắn UTM"))) -> Website trực tiếp / chưa gắn UTM | J27: =IF(I27<>"",I27,H27) -> Website trực tiếp / chưa gắn UTM
A28: PT-022 | B28: Có | C28: Đã thanh toán | D28: 500000 | F28: Không | G28: Không | H28: =IF(E28="info","Đối tác trường",IF(OR(E28="metaads",F28="Có"),"Facebook",IF(G28="Có","Talkshow","Website trực tiếp / chưa gắn UTM"))) -> Website trực tiếp / chưa gắn UTM | I28: Email | J28: =IF(I28<>"",I28,H28) -> Email
A29: PT-023 | B29: Có | C29: Đã thanh toán | D29: 500000 | E29: info | F29: Có | G29: Không | H29: =IF(E29="info","Đối tác trường",IF(OR(E29="metaads",F29="Có"),"Facebook",IF(G29="Có","Talkshow","Website trực tiếp / chưa gắn UTM"))) -> Đối tác trường | J29: =IF(I29<>"",I29,H29) -> Đối tác trường
A30: PT-024 | B30: Có | C30: Đã thanh toán | D30: 500000 | E30: metaads | F30: Không | G30: Có | H30: =IF(E30="info","Đối tác trường",IF(OR(E30="metaads",F30="Có"),"Facebook",IF(G30="Có","Talkshow","Website trực tiếp / chưa gắn UTM"))) -> Facebook | J30: =IF(I30<>"",I30,H30) -> Facebook
A31: PT-025 | B31: Có | C31: Đã thanh toán | D31: 500000 | F31: Không | G31: Không | H31: =IF(E31="info","Đối tác trường",IF(OR(E31="metaads",F31="Có"),"Facebook",IF(G31="Có","Talkshow","Website trực tiếp / chưa gắn UTM"))) -> Website trực tiếp / chưa gắn UTM | J31: =IF(I31<>"",I31,H31) -> Website trực tiếp / chưa gắn UTM
A32: PT-026 | B32: Có | C32: Đã thanh toán | D32: 500000 | F32: Có | G32: Không | H32: =IF(E32="info","Đối tác trường",IF(OR(E32="metaads",F32="Có"),"Facebook",IF(G32="Có","Talkshow","Website trực tiếp / chưa gắn UTM"))) -> Facebook | J32: =IF(I32<>"",I32,H32) -> Facebook
A33: PT-027 | B33: Có | C33: Đã thanh toán | D33: 500000 | F33: Không | G33: Không | H33: =IF(E33="info","Đối tác trường",IF(OR(E33="metaads",F33="Có"),"Facebook",IF(G33="Có","Talkshow","Website trực tiếp / chưa gắn UTM"))) -> Website trực tiếp / chưa gắn UTM | J33: =IF(I33<>"",I33,H33) -> Website trực tiếp / chưa gắn UTM
A34: PT-028 | B34: Có | C34: Đã thanh toán | D34: 500000 | F34: Không | G34: Có | H34: =IF(E34="info","Đối tác trường",IF(OR(E34="metaads",F34="Có"),"Facebook",IF(G34="Có","Talkshow","Website trực tiếp / chưa gắn UTM"))) -> Talkshow | J34: =IF(I34<>"",I34,H34) -> Talkshow
A35: PT-029 | B35: Có | C35: Đã thanh toán | D35: 500000 | F35: Có | G35: Không | H35: =IF(E35="info","Đối tác trường",IF(OR(E35="metaads",F35="Có"),"Facebook",IF(G35="Có","Talkshow","Website trực tiếp / chưa gắn UTM"))) -> Facebook | J35: =IF(I35<>"",I35,H35) -> Facebook
A36: PT-030 | B36: Có | C36: Đã thanh toán | D36: 500000 | F36: Không | G36: Không | H36: =IF(E36="info","Đối tác trường",IF(OR(E36="metaads",F36="Có"),"Facebook",IF(G36="Có","Talkshow","Website trực tiếp / chưa gắn UTM"))) -> Website trực tiếp / chưa gắn UTM | J36: =IF(I36<>"",I36,H36) -> Website trực tiếp / chưa gắn UTM
A37: PT-031 | B37: Có | C37: Đã thanh toán | D37: 500000 | F37: Không | G37: Có | H37: =IF(E37="info","Đối tác trường",IF(OR(E37="metaads",F37="Có"),"Facebook",IF(G37="Có","Talkshow","Website trực tiếp / chưa gắn UTM"))) -> Talkshow | J37: =IF(I37<>"",I37,H37) -> Talkshow
A38: PT-032 | B38: Có | C38: Đã thanh toán | D38: 650000 | F38: Không | G38: Không | H38: =IF(E38="info","Đối tác trường",IF(OR(E38="metaads",F38="Có"),"Facebook",IF(G38="Có","Talkshow","Website trực tiếp / chưa gắn UTM"))) -> Website trực tiếp / chưa gắn UTM | J38: =IF(I38<>"",I38,H38) -> Website trực tiếp / chưa gắn UTM
A39: PT-033 | B39: Có | C39: Đã thanh toán | D39: 650000 | E39: metaads | F39: Không | G39: Không | H39: =IF(E39="info","Đối tác trường",IF(OR(E39="metaads",F39="Có"),"Facebook",IF(G39="Có","Talkshow","Website trực tiếp / chưa gắn UTM"))) -> Facebook | J39: =IF(I39<>"",I39,H39) -> Facebook
A40: PT-034 | B40: Có | C40: Đã thanh toán | D40: 500000 | F40: Không | G40: Không | H40: =IF(E40="info","Đối tác trường",IF(OR(E40="metaads",F40="Có"),"Facebook",IF(G40="Có","Talkshow","Website trực tiếp / chưa gắn UTM"))) -> Website trực tiếp / chưa gắn UTM | J40: =IF(I40<>"",I40,H40) -> Website trực tiếp / chưa gắn UTM
...

Sheet Nguồn & ROI
A1: NGUỒN & ROI — đối soát Booklet 2, đã bổ sung dữ liệu giả định cho Google / TikTok / Email / Zalo
A2: • Chữ xanh = số nhập tay (ngân sách, click, CTR lấy từ báo cáo gốc). Các cột còn lại là công thức trên Contacts_Attribution (cột J).
A4: Kênh (UTM Source) | B4: Liên hệ duy nhất | C4: Đăng ký web | D4: Lead chưa đăng ký | E4: Đã thanh toán | F4: Tỷ lệ chuyển đổi (thanh toán / đăng ký web) | G4: Ngân sách chi tiêu (VNĐ) | H4: Doanh thu thu về (VNĐ) | I4: ROI (%) | J4: Lượt click Logo/Banner | K4: CTR (%) | L4: Nguồn số liệu
A5: Facebook | B5: =COUNTIFS(Contacts_Attribution!$J$7:$J$151,A5) -> 35 | C5: =COUNTIFS(Contacts_Attribution!$J$7:$J$151,A5,Contacts_Attribution!$B$7:$B$151,"Có") -> 19 | D5: =B5-C5 -> 16 | E5: =COUNTIFS(Contacts_Attribution!$J$7:$J$151,A5,Contacts_Attribution!$C$7:$C$151,"Đã thanh toán")+COUNTIFS(Contacts_Attribution!$J$7:$J$151,A5,Contacts_Attribution!$C$7:$C$151,"Miễn phí (free)") -> 9 | F5: =IF(C5=0,0,E5/C5) -> 0.47368421 | G5: 3000000 | H5: =SUMIFS(Contacts_Attribution!$D$7:$D$151,Contacts_Attribution!$J$7:$J$151,A5) -> 3650000 | I5: =IF(G5=0,"n/a",(H5-G5)/G5) -> 0.21666667 | J5: 450 | K5: 0.025 | L5: Booklet 2 (metaads + FB Lead Form) – giữ nguyên
A6: Google | B6: =COUNTIFS(Contacts_Attribution!$J$7:$J$151,A6) -> 13 | C6: =COUNTIFS(Contacts_Attribution!$J$7:$J$151,A6,Contacts_Attribution!$B$7:$B$151,"Có") -> 13 | D6: =B6-C6 -> 0 | E6: =COUNTIFS(Contacts_Attribution!$J$7:$J$151,A6,Contacts_Attribution!$C$7:$C$151,"Đã thanh toán")+COUNTIFS(Contacts_Attribution!$J$7:$J$151,A6,Contacts_Attribution!$C$7:$C$151,"Miễn phí (free)") -> 2 | F6: =IF(C6=0,0,E6/C6) -> 0.15384615 | G6: 2500000 | H6: =SUMIFS(Contacts_Attribution!$D$7:$D$151,Contacts_Attribution!$J$7:$J$151,A6) -> 1000000 | I6: =IF(G6=0,"n/a",(H6-G6)/G6) -> -0.6 | J6: 210 | K6: 0.031 | L6: GIẢ ĐỊNH – chia từ nhóm chưa gắn UTM
A7: TikTok | B7: =COUNTIFS(Contacts_Attribution!$J$7:$J$151,A7) -> 9 | C7: =COUNTIFS(Contacts_Attribution!$J$7:$J$151,A7,Contacts_Attribution!$B$7:$B$151,"Có") -> 9 | D7: =B7-C7 -> 0 | E7: =COUNTIFS(Contacts_Attribution!$J$7:$J$151,A7,Contacts_Attribution!$C$7:$C$151,"Đã thanh toán")+COUNTIFS(Contacts_Attribution!$J$7:$J$151,A7,Contacts_Attribution!$C$7:$C$151,"Miễn phí (free)") -> 0 | F7: =IF(C7=0,0,E7/C7) -> 0 | G7: 1500000 | H7: =SUMIFS(Contacts_Attribution!$D$7:$D$151,Contacts_Attribution!$J$7:$J$151,A7) -> 0 | I7: =IF(G7=0,"n/a",(H7-G7)/G7) -> -1 | J7: 85 | K7: 0.012 | L7: GIẢ ĐỊNH – chia từ nhóm chưa gắn UTM
A8: Email | B8: =COUNTIFS(Contacts_Attribution!$J$7:$J$151,A8) -> 5 | C8: =COUNTIFS(Contacts_Attribution!$J$7:$J$151,A8,Contacts_Attribution!$B$7:$B$151,"Có") -> 5 | D8: =B8-C8 -> 0 | E8: =COUNTIFS(Contacts_Attribution!$J$7:$J$151,A8,Contacts_Attribution!$C$7:$C$151,"Đã thanh toán")+COUNTIFS(Contacts_Attribution!$J$7:$J$151,A8,Contacts_Attribution!$C$7:$C$151,"Miễn phí (free)") -> 3 | F8: =IF(C8=0,0,E8/C8) -> 0.6 | G8: 200000 | H8: =SUMIFS(Contacts_Attribution!$D$7:$D$151,Contacts_Attribution!$J$7:$J$151,A8) -> 1500000 | I8: =IF(G8=0,"n/a",(H8-G8)/G8) -> 6.5 | J8: 45 | K8: 0.05 | L8: GIẢ ĐỊNH – chia từ nhóm chưa gắn UTM
A9: Zalo | B9: =COUNTIFS(Contacts_Attribution!$J$7:$J$151,A9) -> 5 | C9: =COUNTIFS(Contacts_Attribution!$J$7:$J$151,A9,Contacts_Attribution!$B$7:$B$151,"Có") -> 5 | D9: =B9-C9 -> 0 | E9: =COUNTIFS(Contacts_Attribution!$J$7:$J$151,A9,Contacts_Attribution!$C$7:$C$151,"Đã thanh toán")+COUNTIFS(Contacts_Attribution!$J$7:$J$151,A9,Contacts_Attribution!$C$7:$C$151,"Miễn phí (free)") -> 3 | F9: =IF(C9=0,0,E9/C9) -> 0.6 | G9: 1000000 | H9: =SUMIFS(Contacts_Attribution!$D$7:$D$151,Contacts_Attribution!$J$7:$J$151,A9) -> 1500000 | I9: =IF(G9=0,"n/a",(H9-G9)/G9) -> 0.5 | J9: 90 | K9: 0.045 | L9: GIẢ ĐỊNH – chia từ nhóm chưa gắn UTM
A10: Đối tác trường | B10: =COUNTIFS(Contacts_Attribution!$J$7:$J$151,A10) -> 7 | C10: =COUNTIFS(Contacts_Attribution!$J$7:$J$151,A10,Contacts_Attribution!$B$7:$B$151,"Có") -> 7 | D10: =B10-C10 -> 0 | E10: =COUNTIFS(Contacts_Attribution!$J$7:$J$151,A10,Contacts_Attribution!$C$7:$C$151,"Đã thanh toán")+COUNTIFS(Contacts_Attribution!$J$7:$J$151,A10,Contacts_Attribution!$C$7:$C$151,"Miễn phí (free)") -> 4 | F10: =IF(C10=0,0,E10/C10) -> 0.57142857 | G10: 300000 | H10: =SUMIFS(Contacts_Attribution!$D$7:$D$151,Contacts_Attribution!$J$7:$J$151,A10) -> 1000000 | I10: =IF(G10=0,"n/a",(H10-G10)/G10) -> 2.3333333 | J10: 120 | K10: 0.062 | L10: Booklet 2 (Partner = info) – giữ nguyên
A11: Talkshow | B11: =COUNTIFS(Contacts_Attribution!$J$7:$J$151,A11) -> 21 | C11: =COUNTIFS(Contacts_Attribution!$J$7:$J$151,A11,Contacts_Attribution!$B$7:$B$151,"Có") -> 11 | D11: =B11-C11 -> 10 | E11: =COUNTIFS(Contacts_Attribution!$J$7:$J$151,A11,Contacts_Attribution!$C$7:$C$151,"Đã thanh toán")+COUNTIFS(Contacts_Attribution!$J$7:$J$151,A11,Contacts_Attribution!$C$7:$C$151,"Miễn phí (free)") -> 8 | F11: =IF(C11=0,0,E11/C11) -> 0.72727273 | G11: 0 | H11: =SUMIFS(Contacts_Attribution!$D$7:$D$151,Contacts_Attribution!$J$7:$J$151,A11) -> 2500000 | I11: =IF(G11=0,"n/a",(H11-G11)/G11) -> n/a | J11: n/a | K11: n/a | L11: Booklet 2 (chỉ có Talkshow Google Form)
A12: Website trực tiếp / chưa gắn UTM | B12: =COUNTIFS(Contacts_Attribution!$J$7:$J$151,A12) -> 50 | C12: =COUNTIFS(Contacts_Attribution!$J$7:$J$151,A12,Contacts_Attribution!$B$7:$B$151,"Có") -> 50 | D12: =B12-C12 -> 0 | E12: =COUNTIFS(Contacts_Attribution!$J$7:$J$151,A12,Contacts_Attribution!$C$7:$C$151,"Đã thanh toán")+COUNTIFS(Contacts_Attribution!$J$7:$J$151,A12,Contacts_Attribution!$C$7:$C$151,"Miễn phí (free)") -> 37 | F12: =IF(C12=0,0,E12/C12) -> 0.74 | G12: 0 | H12: =SUMIFS(Contacts_Attribution!$D$7:$D$151,Contacts_Attribution!$J$7:$J$151,A12) -> 6950000 | I12: =IF(G12=0,"n/a",(H12-G12)/G12) -> n/a | J12: n/a | K12: n/a | L12: Booklet 2 – phần còn lại sau khi chia
A13: Tổng | B13: =SUM(B5:B12) -> 145 | C13: =SUM(C5:C12) -> 119 | D13: =SUM(D5:D12) -> 26 | E13: =SUM(E5:E12) -> 66 | F13: =IF(C13=0,0,E13/C13) -> 0.55462185 | G13: =SUM(G5:G12) -> 8500000 | H13: =SUM(H5:H12) -> 18100000 | I13: =IF(G13=0,"n/a",(H13-G13)/G13) -> 1.1294118
A15: Ghi chú:
A16: • Tổng khớp Dashboard Booklet 2: 145 liên hệ, 119 đăng ký web, 66 thanh toán, doanh thu 18,1 triệu VND.
A17: • Facebook và Đối tác trường: số liệu lấy thẳng từ Booklet 2 (đã gộp trùng) nên không phải sửa thêm; chỉ khác báo cáo gốc do gốc đếm dòng thô.
A18: • Google, TikTok, Email, Zalo: số đăng ký/thanh toán/doanh thu là GIẢ ĐỊNH, tạo bằng cách gán 32 liên hệ web chưa gắn UTM (xem cột I, Contacts_Attribution). Ngân sách, click, CTR giữ nguyên báo cáo gốc.
A19: • Doanh thu chỉ tính dòng có lệ phí ghi nhận; nhóm Website trực tiếp là phần dư nên doanh thu bình quân/người thấp do nhiều dòng đã thanh toán để trống lệ phí.
A20: • Tổng ngân sách 8,5 triệu VNĐ và ROI tổng tính trên cả 8 nhóm (2 nhóm không có ngân sách đóng góp doanh thu mà không tốn chi phí).

Sheet CPA Analysis
A1: CPA ANALYSIS — chi phí trên mỗi đầu ra (6 kênh có ngân sách)
A2: • "Thi thực tế" là số GIẢ ĐỊNH (chữ xanh, ô vàng): Booklet 2 không có điểm danh thi; giả định ≤ số đã thanh toán.
A4: Nguồn | B4: Lead cơ bản (Đăng ký web) | C4: Qualified Lead (Thanh toán) | D4: Active Candidate (Thi thực tế) – giả định | E4: Ngân sách chi tiêu (VNĐ) | F4: CPA – Lead cơ bản (VNĐ) | G4: CPA – Qualified Lead (VNĐ) | H4: CPA – Active Candidate (VNĐ)
A5: ='Nguồn & ROI'!A5 -> Facebook | B5: ='Nguồn & ROI'!C5 -> 19 | C5: ='Nguồn & ROI'!E5 -> 9 | D5: 8 | E5: ='Nguồn & ROI'!G5 -> 3000000 | F5: =IF(B5=0,"n/a",E5/B5) -> 157894.74 | G5: =IF(C5=0,"n/a",E5/C5) -> 333333.33 | H5: =IF(D5=0,"n/a",E5/D5) -> 375000
A6: ='Nguồn & ROI'!A6 -> Google | B6: ='Nguồn & ROI'!C6 -> 13 | C6: ='Nguồn & ROI'!E6 -> 2 | D6: 2 | E6: ='Nguồn & ROI'!G6 -> 2500000 | F6: =IF(B6=0,"n/a",E6/B6) -> 192307.69 | G6: =IF(C6=0,"n/a",E6/C6) -> 1250000 | H6: =IF(D6=0,"n/a",E6/D6) -> 1250000
A7: ='Nguồn & ROI'!A7 -> TikTok | B7: ='Nguồn & ROI'!C7 -> 9 | C7: ='Nguồn & ROI'!E7 -> 0 | D7: 0 | E7: ='Nguồn & ROI'!G7 -> 1500000 | F7: =IF(B7=0,"n/a",E7/B7) -> 166666.67 | G7: =IF(C7=0,"n/a",E7/C7) -> n/a | H7: =IF(D7=0,"n/a",E7/D7) -> n/a
A8: ='Nguồn & ROI'!A8 -> Email | B8: ='Nguồn & ROI'!C8 -> 5 | C8: ='Nguồn & ROI'!E8 -> 3 | D8: 3 | E8: ='Nguồn & ROI'!G8 -> 200000 | F8: =IF(B8=0,"n/a",E8/B8) -> 40000 | G8: =IF(C8=0,"n/a",E8/C8) -> 66666.667 | H8: =IF(D8=0,"n/a",E8/D8) -> 66666.667
A9: ='Nguồn & ROI'!A9 -> Zalo | B9: ='Nguồn & ROI'!C9 -> 5 | C9: ='Nguồn & ROI'!E9 -> 3 | D9: 2 | E9: ='Nguồn & ROI'!G9 -> 1000000 | F9: =IF(B9=0,"n/a",E9/B9) -> 200000 | G9: =IF(C9=0,"n/a",E9/C9) -> 333333.33 | H9: =IF(D9=0,"n/a",E9/D9) -> 500000
A10: ='Nguồn & ROI'!A10 -> Đối tác trường | B10: ='Nguồn & ROI'!C10 -> 7 | C10: ='Nguồn & ROI'!E10 -> 4 | D10: 4 | E10: ='Nguồn & ROI'!G10 -> 300000 | F10: =IF(B10=0,"n/a",E10/B10) -> 42857.143 | G10: =IF(C10=0,"n/a",E10/C10) -> 75000 | H10: =IF(D10=0,"n/a",E10/D10) -> 75000

Sheet Theo dõi Quyền lợi
A1: THEO DÕI QUYỀN LỢI NHÀ TÀI TRỢ
A3: Hạng mục Quyền lợi | B3: Tình trạng hoàn thành | C3: Vị trí xuất hiện | D3: Thời gian triển khai | E3: Ghi chú / Quyền lợi chưa thực hiện
A4: Logo trên Website chính thức | B4: Hoàn thành 100% | C4: Trang chủ (Header & Footer) | D4: 01/08 - 30/10/2026 | E4: Đúng tiến độ
A5: Bài đăng tuyển dụng trên Fanpage | B5: Hoàn thành 50% | C5: Fanpage Python Master | D5: 15/08 và 15/09/2026 | E5: Đang chờ duyệt nội dung bài đăng số 2
A6: Logo trên Standee/Banner Offline | B6: Chưa bắt đầu | C6: 3 điểm cầu: Hà Nội, Đà Nẵng, TP.HCM | D6: 25/10/2026 | E6: Đang trong quá trình in ấn
A7: Video TVC phát tại Chung kết | B7: Hoàn thành 100% | C7: Màn hình LED sân khấu chính | D7: 30/10/2026 | E7: Đã kiểm tra chất lượng video
A8: Mention trong Email gửi thí sinh | B8: Hoàn thành 100% | C8: Chân trang email thông báo lịch thi | D8: 20/10/2026 | E8: ="Đã gửi thành công cho "&'Nguồn & ROI'!E13&" thí sinh (nhóm S1 – đã thanh toán, đều có email hợp lệ)" -> Đã gửi thành công cho 66 thí sinh (nhóm S1 – đã thanh toán, đều có email hợp lệ)
A10: • Đã sửa: số thí sinh nhận email từ 97 (báo cáo gốc) thành số thí sinh đã thanh toán theo Booklet 2 (66 người).
A11: • Cần xác nhận: báo cáo ghi 3 điểm cầu (có Đà Nẵng) nhưng Booklet 2 chỉ có danh sách thi Hà Nội và TP.HCM; giữ nguyên nội dung gốc.

Sheet Hiệu quả Kênh
A1: HIỆU QUẢ KÊNH TRUYỀN THÔNG
A3: Kênh truyền thông | B3: Lượt tiếp cận (Reach) | C3: Lượt tương tác (Engagement) | D3: Tỉ lệ tương tác | E3: Mức độ quan trọng (Khảo sát 1-5)
A4: Fanpage & mạng xã hội chính thức | B4: 55000 | C4: 3200 | D4: =IF(B4=0,0,C4/B4) -> 0.058181818 | E4: 5
A5: Website chương trình (pythonmaster.vn) | B5: 12500 | C5: 850 | D5: =IF(B5=0,0,C5/B5) -> 0.068 | E5: 4
A6: Livestream Chung kết | B6: 8000 | C6: 1200 | D6: =IF(B6=0,0,C6/B6) -> 0.15 | E6: 4
A7: Banner/standee tại 3 điểm cầu offline | B7: 1500 | C7: 150 | D7: =IF(B7=0,0,C7/B7) -> 0.1 | E7: 3
A8: Email/thông báo trực tiếp | B8: 4500 | C8: 900 | D8: =IF(B8=0,0,C8/B8) -> 0.2 | E8: 5
A10: • Giữ nguyên số liệu gốc (Booklet 2 không có dữ liệu reach/engagement). Cột Tỉ lệ tương tác là công thức mới.

Sheet Đối soát
A1: ĐỐI SOÁT — báo cáo gốc vs bản đã sửa (Booklet 2 + giả định)
A3: Kênh | B3: Đăng ký (gốc) | C3: Đăng ký (mới) | D3: Thanh toán (gốc) | E3: Thanh toán (mới) | F3: Doanh thu gốc (VNĐ) | G3: Doanh thu mới (VNĐ) | H3: ROI gốc | I3: ROI mới | J3: Nhận xét
A4: Facebook | B4: 39 | C4: ='Nguồn & ROI'!C5 -> 19 | D4: 4 | E4: ='Nguồn & ROI'!E5 -> 9 | F4: 2000000 | G4: ='Nguồn & ROI'!H5 -> 3650000 | H4: -0.33 | I4: ='Nguồn & ROI'!I5 -> 0.21666667 | J4: Gốc có vẻ đếm dòng thô (gồm cả lead FB chưa đăng ký web); sau gộp trùng chỉ 19 người đăng ký web. Thanh toán tăng do đối chiếu đủ dữ liệu Booklet 2.
A5: Google | B5: 17 | C5: ='Nguồn & ROI'!C6 -> 13 | D5: 3 | E5: ='Nguồn & ROI'!E6 -> 2 | F5: 1500000 | G5: ='Nguồn & ROI'!H6 -> 1000000 | H5: -0.4 | I5: ='Nguồn & ROI'!I6 -> -0.6 | J5: Giả định; giữ xu hướng chuyển đổi thấp, ROI âm.
A6: TikTok | B6: 15 | C6: ='Nguồn & ROI'!C7 -> 9 | D6: 0 | E6: ='Nguồn & ROI'!E7 -> 0 | F6: 0 | G6: ='Nguồn & ROI'!H7 -> 0 | H6: -1 | I6: ='Nguồn & ROI'!I7 -> -1 | J6: Giả định; giữ nguyên kết quả gốc: không có thanh toán.
A7: Email | B7: 9 | C7: ='Nguồn & ROI'!C8 -> 5 | D7: 3 | E7: ='Nguồn & ROI'!E8 -> 3 | F7: 1500000 | G7: ='Nguồn & ROI'!H8 -> 1500000 | H7: 6.5 | I7: ='Nguồn & ROI'!I8 -> 6.5 | J7: Giả định; giữ ROI +650% như gốc.
A8: Zalo | B8: 9 | C8: ='Nguồn & ROI'!C9 -> 5 | D8: 2 | E8: ='Nguồn & ROI'!E9 -> 3 | F8: 2000000 | G8: ='Nguồn & ROI'!H9 -> 1500000 | H8: 1 | I8: ='Nguồn & ROI'!I9 -> 0.5 | J8: Giả định; doanh thu giảm còn 1,5 triệu vì lệ phí chuẩn 500k/người.
A9: Đối tác trường | B9: 8 | C9: ='Nguồn & ROI'!C10 -> 7 | D9: 3 | E9: ='Nguồn & ROI'!E10 -> 4 | F9: 1500000 | G9: ='Nguồn & ROI'!H10 -> 1000000 | H9: 4 | I9: ='Nguồn & ROI'!I10 -> 2.3333333 | J9: Gốc đếm dòng thô (8); sau gộp trùng còn 7 người, 4 người đã thanh toán.
A10: Tổng 6 kênh (gốc | mới) | B10: =SUM(B4:B9) -> 97 | C10: =SUM(C4:C9) -> 58 | D10: =SUM(D4:D9) -> 15 | E10: =SUM(E4:E9) -> 21 | F10: =SUM(F4:F9) -> 8500000 | G10: =SUM(G4:G9) -> 8650000
A11: Talkshow + Website trực tiếp (mới) | C11: ='Nguồn & ROI'!C11+'Nguồn & ROI'!C12 -> 61 | E11: ='Nguồn & ROI'!E11+'Nguồn & ROI'!E12 -> 45 | G11: ='Nguồn & ROI'!H11+'Nguồn & ROI'!H12 -> 9450000
A12: Tổng toàn chương trình | C12: =C10+C11 -> 119 | E12: =E10+E11 -> 66 | G12: =G10+G11 -> 18100000
A14: • Tổng mới = 119 đăng ký web, 66 thanh toán, 18,1 triệu VNĐ, khớp Dashboard Booklet 2. Báo cáo gốc chỉ có 97 đăng ký, 15 thanh toán, 8,5 triệu VNĐ.
A15: • Ngân sách của 6 kênh giữ nguyên báo cáo gốc: 8,5 triệu VNĐ.
