Workbook

Sheet Bao_cao_tong_quan
B1: BÁO CÁO ĐIỂM THI — BẢNG B — PYTHON MASTER
B3: ⚠ DỮ LIỆU GIẢ LẬP — điểm là số ngẫu nhiên, không phải kết quả thật; không dùng để công bố, xếp hạng hay đánh giá cá nhân (xem sheet Ghi_chu).
B4: Đơn vị sử dụng báo cáo: | C4: (Điền tên đơn vị / bộ phận sử dụng báo cáo tại đây)
B5: Ngày lập báo cáo: | C5: =TODAY()
B6: Ô nền vàng, chữ xanh dương = nhập tay · chữ đen = công thức · chữ xanh lá = lấy từ sheet khác. Toàn bộ số liệu tự cập nhật khi đổi điểm (Tong_hop) hoặc tham số (Tham_so).
B8: 1. CHỈ SỐ TỔNG QUAN
B9: TỔNG SỐ THÍ SINH | C9: ĐÃ THANH TOÁN | E9: VÀO CHUNG KẾT | G9: ĐẠT NGƯỠNG CHỨNG CHỈ
B10: =COUNTA(Tong_hop!$C$2:$C$96) | C10: =COUNTIF(Tong_hop!$G$2:$G$96,"Có") | E10: =COUNT(Tong_hop!$Q$2:$Q$96) | G10: =COUNTIF(Tong_hop!$S$2:$S$96,"Có")
B11: Bảng B | C11: =IF($B$10=0,"",C10/$B$10) | E11: Top 10% vòng loại | G11: =IF($B$10=0,"",G10/$B$10)
B13: ĐIỂM TB VÒNG LOẠI | C13: ĐIỂM CAO NHẤT (VL) | E13: ĐIỂM THẤP NHẤT (VL) | G13: SỐ NGƯỜI ĐẠT ≥600 (VL)
B14: =AVERAGE(Tong_hop!$K$2:$K$96) | C14: =MAX(Tong_hop!$K$2:$K$96) | E14: =MIN(Tong_hop!$K$2:$K$96) | G14: =COUNTIF(Tong_hop!$K$2:$K$96,">=600")
B15: thang 1.000 điểm | C15: thang 1.000 điểm | E15: thang 1.000 điểm | G15: =IF($B$10=0,"",G14/$B$10)
B17: 2. KẾT QUẢ THEO VÒNG THI (BẢNG B)
B18: Chỉ số | C18: Vòng loại | D18: Chung kết
B19: Số thí sinh có điểm | C19: =COUNT(Tong_hop!$K$2:$K$96) | D19: =COUNT(Tong_hop!$Q$2:$Q$96)
B20: Điểm trung bình | C20: =AVERAGE(Tong_hop!$K$2:$K$96) | D20: =AVERAGE(Tong_hop!$Q$2:$Q$96)
B21: Điểm cao nhất | C21: =MAX(Tong_hop!$K$2:$K$96) | D21: =MAX(Tong_hop!$Q$2:$Q$96)
B22: Điểm thấp nhất | C22: =MIN(Tong_hop!$K$2:$K$96) | D22: =MIN(Tong_hop!$Q$2:$Q$96)
B23: Số người đạt ≥ 600 điểm | C23: =COUNTIF(Tong_hop!$K$2:$K$96,">=600") | D23: =COUNTIF(Tong_hop!$Q$2:$Q$96,">=600")
B24: Tỉ lệ đạt ngưỡng chứng chỉ | C24: =IF(C19=0,"",C23/C19) | D24: =IF(D19=0,"",D23/D19)
B25: ="Chung kết chỉ có "&(D19)&" thí sinh (Top 10% vòng loại) nên số liệu Chung kết kém ổn định. Đề Chung kết khó hơn Vòng loại (Bảng B: từ COS Pro Level 2 lên COS Pro Level 1)."
B27: 3. ĐIỂM TRUNG BÌNH THEO PHẦN THI (% điểm tối đa của phần)
B28: Phần thi | C28: Vòng loại | D28: Chung kết
B29: Đọc hiểu code | C29: =AVERAGE(Tong_hop!$J$2:$J$96)/Cau_truc_de!$E$7 | D29: =IFERROR(AVERAGE(Tong_hop!$P$2:$P$96)/Cau_truc_de!$E$10,"–")
B30: Design (thiết kế · viết hàm) | C30: =AVERAGE(Tong_hop!$I$2:$I$96)/Cau_truc_de!$E$6 | D30: =IFERROR(AVERAGE(Tong_hop!$O$2:$O$96)/Cau_truc_de!$E$9,"–")
B31: Debugging | C31: =AVERAGE(Tong_hop!$H$2:$H$96)/Cau_truc_de!$E$5 | D31: =IFERROR(AVERAGE(Tong_hop!$N$2:$N$96)/Cau_truc_de!$E$8,"–")
B32: Điểm trung bình của phần thi ÷ điểm tối đa của phần đó (sheet Cau_truc_de). Không so sánh trực tiếp % giữa hai vòng vì độ khó khác nhau.
B35: 4. PHÂN LOẠI THÍ SINH VÒNG LOẠI THEO TỔNG ĐIỂM
B36: Xếp loại | C36: Số người | D36: % | E36: Điều kiện (tổng /1000)
B37: Giỏi | C37: =Phan_loai!C6 | D37: =Phan_loai!D6 | E37: ="≥ "&Tham_so!$B$9
B38: Khá | C38: =Phan_loai!C7 | D38: =Phan_loai!D7 | E38: ="từ "&Tham_so!$B$10&" đến dưới "&Tham_so!$B$9
B39: Trung bình | C39: =Phan_loai!C8 | D39: =Phan_loai!D8 | E39: ="từ "&Tham_so!$B$11&" đến dưới "&Tham_so!$B$10
B40: Yếu | C40: =Phan_loai!C9 | D40: =Phan_loai!D9 | E40: ="dưới "&Tham_so!$B$11
B41: Tổng | C41: =SUM(C37:C40) | D41: =SUM(D37:D40)
B44: 5. PHÂN BỐ TỔNG ĐIỂM VÒNG LOẠI (thang 1.000)
B45: Khoảng điểm | C45: Từ | D45: Đến (không gồm) | E45: Số thí sinh
B46: =C46&" – "&IF(D46>1000,1000,D46-1) | C46: 0 | D46: 100 | E46: =COUNTIFS(Tong_hop!$K$2:$K$96,">="&C46,Tong_hop!$K$2:$K$96,"<"&D46)
B47: =C47&" – "&IF(D47>1000,1000,D47-1) | C47: 100 | D47: 200 | E47: =COUNTIFS(Tong_hop!$K$2:$K$96,">="&C47,Tong_hop!$K$2:$K$96,"<"&D47)
B48: =C48&" – "&IF(D48>1000,1000,D48-1) | C48: 200 | D48: 300 | E48: =COUNTIFS(Tong_hop!$K$2:$K$96,">="&C48,Tong_hop!$K$2:$K$96,"<"&D48)
B49: =C49&" – "&IF(D49>1000,1000,D49-1) | C49: 300 | D49: 400 | E49: =COUNTIFS(Tong_hop!$K$2:$K$96,">="&C49,Tong_hop!$K$2:$K$96,"<"&D49)
...

Sheet Tong_hop
A1: STT | B1: Email | C1: Họ tên | D1: Bảng | E1: Trường | F1: Tỉnh/TP | G1: Đã thanh toán | H1: VL – Debugging (/280) | I1: VL – Design (/280) | J1: VL – Đọc hiểu code (/440) | K1: VL – Tổng (/1000) | L1: VL – Hạng trong bảng | M1: Vượt vòng loại (Top 10%) | N1: CK – Debugging (/240) | O1: CK – Design (/420) | P1: CK – Đọc hiểu code (/340) | Q1: CK – Tổng (/1000) | R1: CK – Hạng trong bảng | S1: Chứng chỉ COS Pro (≥600) | T1: VL – Xếp loại | U1: CK – Xếp loại | V1: Dữ liệu giả lập
A2: 1 | B2: cuongquocbui192@gmail.com | C2: Bùi Quốc Cường | D2: Bảng B | E2: Đại học Bách Khoa Hà Nội | F2: TP. Hồ Chí Minh | G2: Không | H2: 280 | I2: 280 | J2: 390 | K2: =SUM(H2:J2) | L2: =COUNTIF($K$2:$K$96,">"&K2)+1 | M2: =IF(L2<=Tham_so!$B$5,"Có","Không") | N2: 150 | O2: 350 | P2: 230 | Q2: =IF(COUNT(N2:P2)=0,"",SUM(N2:P2)) | R2: =IF(Q2="","",COUNTIF($Q$2:$Q$96,">"&Q2)+1) | S2: =IF(OR(K2>=Tham_so!$B$3,AND(ISNUMBER(Q2),Q2>=Tham_so!$B$3)),"Có","Không") | T2: =IF(K2>=Tham_so!$B$9,"Giỏi",IF(K2>=Tham_so!$B$10,"Khá",IF(K2>=Tham_so!$B$11,"Trung bình","Yếu"))) | U2: =IF(Q2="","",IF(Q2>=Tham_so!$B$9,"Giỏi",IF(Q2>=Tham_so!$B$10,"Khá",IF(Q2>=Tham_so!$B$11,"Trung bình","Yếu")))) | V2: Có
A3: 2 | B3: maikimhoang104@gmail.com | C3: Hoàng Kim Mai | D3: Bảng B | E3: Học viện Công nghệ Bưu chính Viễn thông (PTIT) | F3: Quảng Ninh | G3: Không | H3: 230 | I3: 230 | J3: 440 | K3: =SUM(H3:J3) | L3: =COUNTIF($K$2:$K$96,">"&K3)+1 | M3: =IF(L3<=Tham_so!$B$5,"Có","Không") | N3: 210 | O3: 420 | P3: 260 | Q3: =IF(COUNT(N3:P3)=0,"",SUM(N3:P3)) | R3: =IF(Q3="","",COUNTIF($Q$2:$Q$96,">"&Q3)+1) | S3: =IF(OR(K3>=Tham_so!$B$3,AND(ISNUMBER(Q3),Q3>=Tham_so!$B$3)),"Có","Không") | T3: =IF(K3>=Tham_so!$B$9,"Giỏi",IF(K3>=Tham_so!$B$10,"Khá",IF(K3>=Tham_so!$B$11,"Trung bình","Yếu"))) | U3: =IF(Q3="","",IF(Q3>=Tham_so!$B$9,"Giỏi",IF(Q3>=Tham_so!$B$10,"Khá",IF(Q3>=Tham_so!$B$11,"Trung bình","Yếu")))) | V3: Có
A4: 3 | B4: hungxuanvu253@gmail.com | C4: Vũ Xuân Hùng | D4: Bảng B | E4: Đại học Khoa học Tự nhiên TP.HCM | F4: Thái Nguyên | G4: Không | H4: 230 | I4: 240 | J4: 400 | K4: =SUM(H4:J4) | L4: =COUNTIF($K$2:$K$96,">"&K4)+1 | M4: =IF(L4<=Tham_so!$B$5,"Có","Không") | N4: 130 | O4: 340 | P4: 280 | Q4: =IF(COUNT(N4:P4)=0,"",SUM(N4:P4)) | R4: =IF(Q4="","",COUNTIF($Q$2:$Q$96,">"&Q4)+1) | S4: =IF(OR(K4>=Tham_so!$B$3,AND(ISNUMBER(Q4),Q4>=Tham_so!$B$3)),"Có","Không") | T4: =IF(K4>=Tham_so!$B$9,"Giỏi",IF(K4>=Tham_so!$B$10,"Khá",IF(K4>=Tham_so!$B$11,"Trung bình","Yếu"))) | U4: =IF(Q4="","",IF(Q4>=Tham_so!$B$9,"Giỏi",IF(Q4>=Tham_so!$B$10,"Khá",IF(Q4>=Tham_so!$B$11,"Trung bình","Yếu")))) | V4: Có
A5: 4 | B5: hungminhly687@gmail.com | C5: Lý Minh Hùng | D5: Bảng B | E5: Đại học Công nghệ - ĐHQGHN | F5: Hà Tĩnh | G5: Không | H5: 250 | I5: 230 | J5: 380 | K5: =SUM(H5:J5) | L5: =COUNTIF($K$2:$K$96,">"&K5)+1 | M5: =IF(L5<=Tham_so!$B$5,"Có","Không") | N5: 120 | O5: 280 | P5: 230 | Q5: =IF(COUNT(N5:P5)=0,"",SUM(N5:P5)) | R5: =IF(Q5="","",COUNTIF($Q$2:$Q$96,">"&Q5)+1) | S5: =IF(OR(K5>=Tham_so!$B$3,AND(ISNUMBER(Q5),Q5>=Tham_so!$B$3)),"Có","Không") | T5: =IF(K5>=Tham_so!$B$9,"Giỏi",IF(K5>=Tham_so!$B$10,"Khá",IF(K5>=Tham_so!$B$11,"Trung bình","Yếu"))) | U5: =IF(Q5="","",IF(Q5>=Tham_so!$B$9,"Giỏi",IF(Q5>=Tham_so!$B$10,"Khá",IF(Q5>=Tham_so!$B$11,"Trung bình","Yếu")))) | V5: Có
A6: 5 | B6: maingochoang945@gmail.com | C6: Hoàng Ngọc Mai | D6: Bảng B | E6: Đại học Bách Khoa TP.HCM | F6: Nghệ An | G6: Không | H6: 230 | I6: 190 | J6: 440 | K6: =SUM(H6:J6) | L6: =COUNTIF($K$2:$K$96,">"&K6)+1 | M6: =IF(L6<=Tham_so!$B$5,"Có","Không") | N6: 100 | O6: 300 | P6: 210 | Q6: =IF(COUNT(N6:P6)=0,"",SUM(N6:P6)) | R6: =IF(Q6="","",COUNTIF($Q$2:$Q$96,">"&Q6)+1) | S6: =IF(OR(K6>=Tham_so!$B$3,AND(ISNUMBER(Q6),Q6>=Tham_so!$B$3)),"Có","Không") | T6: =IF(K6>=Tham_so!$B$9,"Giỏi",IF(K6>=Tham_so!$B$10,"Khá",IF(K6>=Tham_so!$B$11,"Trung bình","Yếu"))) | U6: =IF(Q6="","",IF(Q6>=Tham_so!$B$9,"Giỏi",IF(Q6>=Tham_so!$B$10,"Khá",IF(Q6>=Tham_so!$B$11,"Trung bình","Yếu")))) | V6: Có
A7: 6 | B7: sonquochuynh931@gmail.com | C7: Huỳnh Quốc Sơn | D7: Bảng B | E7: Đại học Khoa học Tự nhiên TP.HCM | F7: Hải Phòng | G7: Không | H7: 150 | I7: 270 | J7: 420 | K7: =SUM(H7:J7) | L7: =COUNTIF($K$2:$K$96,">"&K7)+1 | M7: =IF(L7<=Tham_so!$B$5,"Có","Không") | N7: 110 | O7: 310 | P7: 220 | Q7: =IF(COUNT(N7:P7)=0,"",SUM(N7:P7)) | R7: =IF(Q7="","",COUNTIF($Q$2:$Q$96,">"&Q7)+1) | S7: =IF(OR(K7>=Tham_so!$B$3,AND(ISNUMBER(Q7),Q7>=Tham_so!$B$3)),"Có","Không") | T7: =IF(K7>=Tham_so!$B$9,"Giỏi",IF(K7>=Tham_so!$B$10,"Khá",IF(K7>=Tham_so!$B$11,"Trung bình","Yếu"))) | U7: =IF(Q7="","",IF(Q7>=Tham_so!$B$9,"Giỏi",IF(Q7>=Tham_so!$B$10,"Khá",IF(Q7>=Tham_so!$B$11,"Trung bình","Yếu")))) | V7: Có
A8: 7 | B8: tuananhdang463@gmail.com | C8: Đặng Anh Tuấn | D8: Bảng B | E8: Đại học Công nghiệp Hà Nội | F8: Thái Nguyên | G8: Không | H8: 210 | I8: 200 | J8: 420 | K8: =SUM(H8:J8) | L8: =COUNTIF($K$2:$K$96,">"&K8)+1 | M8: =IF(L8<=Tham_so!$B$5,"Có","Không") | N8: 150 | O8: 330 | P8: 220 | Q8: =IF(COUNT(N8:P8)=0,"",SUM(N8:P8)) | R8: =IF(Q8="","",COUNTIF($Q$2:$Q$96,">"&Q8)+1) | S8: =IF(OR(K8>=Tham_so!$B$3,AND(ISNUMBER(Q8),Q8>=Tham_so!$B$3)),"Có","Không") | T8: =IF(K8>=Tham_so!$B$9,"Giỏi",IF(K8>=Tham_so!$B$10,"Khá",IF(K8>=Tham_so!$B$11,"Trung bình","Yếu"))) | U8: =IF(Q8="","",IF(Q8>=Tham_so!$B$9,"Giỏi",IF(Q8>=Tham_so!$B$10,"Khá",IF(Q8>=Tham_so!$B$11,"Trung bình","Yếu")))) | V8: Có
A9: 8 | B9: khangminhdang733@gmail.com | C9: Đặng Minh Khang | D9: Bảng B | E9: Đại học Kinh tế Quốc dân | F9: Hải Dương | G9: Không | H9: 230 | I9: 230 | J9: 350 | K9: =SUM(H9:J9) | L9: =COUNTIF($K$2:$K$96,">"&K9)+1 | M9: =IF(L9<=Tham_so!$B$5,"Có","Không") | N9: 140 | O9: 210 | P9: 170 | Q9: =IF(COUNT(N9:P9)=0,"",SUM(N9:P9)) | R9: =IF(Q9="","",COUNTIF($Q$2:$Q$96,">"&Q9)+1) | S9: =IF(OR(K9>=Tham_so!$B$3,AND(ISNUMBER(Q9),Q9>=Tham_so!$B$3)),"Có","Không") | T9: =IF(K9>=Tham_so!$B$9,"Giỏi",IF(K9>=Tham_so!$B$10,"Khá",IF(K9>=Tham_so!$B$11,"Trung bình","Yếu"))) | U9: =IF(Q9="","",IF(Q9>=Tham_so!$B$9,"Giỏi",IF(Q9>=Tham_so!$B$10,"Khá",IF(Q9>=Tham_so!$B$11,"Trung bình","Yếu")))) | V9: Có
A10: 9 | B10: thaothanhdang998@gmail.com | C10: Đặng Thanh Thảo | D10: Bảng B | E10: Đại học Bách Khoa Hà Nội | F10: Thái Nguyên | G10: Không | H10: 240 | I10: 130 | J10: 420 | K10: =SUM(H10:J10) | L10: =COUNTIF($K$2:$K$96,">"&K10)+1 | M10: =IF(L10<=Tham_so!$B$5,"Có","Không") | N10: 130 | O10: 210 | P10: 290 | Q10: =IF(COUNT(N10:P10)=0,"",SUM(N10:P10)) | R10: =IF(Q10="","",COUNTIF($Q$2:$Q$96,">"&Q10)+1) | S10: =IF(OR(K10>=Tham_so!$B$3,AND(ISNUMBER(Q10),Q10>=Tham_so!$B$3)),"Có","Không") | T10: =IF(K10>=Tham_so!$B$9,"Giỏi",IF(K10>=Tham_so!$B$10,"Khá",IF(K10>=Tham_so!$B$11,"Trung bình","Yếu"))) | U10: =IF(Q10="","",IF(Q10>=Tham_so!$B$9,"Giỏi",IF(Q10>=Tham_so!$B$10,"Khá",IF(Q10>=Tham_so!$B$11,"Trung bình","Yếu")))) | V10: Có
A11: 10 | B11: anhongho911@gmail.com | C11: Hồ Hồng An | D11: Bảng B | E11: Đại học Sư phạm Kỹ thuật TP.HCM | F11: Quảng Ninh | G11: Có | H11: 200 | I11: 160 | J11: 400 | K11: =SUM(H11:J11) | L11: =COUNTIF($K$2:$K$96,">"&K11)+1 | M11: =IF(L11<=Tham_so!$B$5,"Có","Không") | N11: 140 | O11: 220 | P11: 230 | Q11: =IF(COUNT(N11:P11)=0,"",SUM(N11:P11)) | R11: =IF(Q11="","",COUNTIF($Q$2:$Q$96,">"&Q11)+1) | S11: =IF(OR(K11>=Tham_so!$B$3,AND(ISNUMBER(Q11),Q11>=Tham_so!$B$3)),"Có","Không") | T11: =IF(K11>=Tham_so!$B$9,"Giỏi",IF(K11>=Tham_so!$B$10,"Khá",IF(K11>=Tham_so!$B$11,"Trung bình","Yếu"))) | U11: =IF(Q11="","",IF(Q11>=Tham_so!$B$9,"Giỏi",IF(Q11>=Tham_so!$B$10,"Khá",IF(Q11>=Tham_so!$B$11,"Trung bình","Yếu")))) | V11: Có
A12: 11 | B12: myanhbui140@gmail.com | C12: Bùi Ánh My | D12: Bảng B | E12: Đại học Duy Tân | F12: Bình Dương | G12: Không | H12: 180 | I12: 180 | J12: 400 | K12: =SUM(H12:J12) | L12: =COUNTIF($K$2:$K$96,">"&K12)+1 | M12: =IF(L12<=Tham_so!$B$5,"Có","Không") | Q12: =IF(COUNT(N12:P12)=0,"",SUM(N12:P12)) | R12: =IF(Q12="","",COUNTIF($Q$2:$Q$96,">"&Q12)+1) | S12: =IF(OR(K12>=Tham_so!$B$3,AND(ISNUMBER(Q12),Q12>=Tham_so!$B$3)),"Có","Không") | T12: =IF(K12>=Tham_so!$B$9,"Giỏi",IF(K12>=Tham_so!$B$10,"Khá",IF(K12>=Tham_so!$B$11,"Trung bình","Yếu"))) | U12: =IF(Q12="","",IF(Q12>=Tham_so!$B$9,"Giỏi",IF(Q12>=Tham_so!$B$10,"Khá",IF(Q12>=Tham_so!$B$11,"Trung bình","Yếu")))) | V12: Có
A13: 12 | B13: phongminhngo990@gmail.com | C13: Ngô Minh Phong | D13: Bảng B | E13: Đại học Kinh tế Quốc dân | F13: Đà Nẵng | G13: Không | H13: 240 | I13: 180 | J13: 340 | K13: =SUM(H13:J13) | L13: =COUNTIF($K$2:$K$96,">"&K13)+1 | M13: =IF(L13<=Tham_so!$B$5,"Có","Không") | Q13: =IF(COUNT(N13:P13)=0,"",SUM(N13:P13)) | R13: =IF(Q13="","",COUNTIF($Q$2:$Q$96,">"&Q13)+1) | S13: =IF(OR(K13>=Tham_so!$B$3,AND(ISNUMBER(Q13),Q13>=Tham_so!$B$3)),"Có","Không") | T13: =IF(K13>=Tham_so!$B$9,"Giỏi",IF(K13>=Tham_so!$B$10,"Khá",IF(K13>=Tham_so!$B$11,"Trung bình","Yếu"))) | U13: =IF(Q13="","",IF(Q13>=Tham_so!$B$9,"Giỏi",IF(Q13>=Tham_so!$B$10,"Khá",IF(Q13>=Tham_so!$B$11,"Trung bình","Yếu")))) | V13: Có
A14: 13 | B14: phuongthule236@gmail.com | C14: Lê Thu Phương | D14: Bảng B | E14: Đại học Bách Khoa TP.HCM | F14: Bắc Ninh | G14: Không | H14: 180 | I14: 150 | J14: 430 | K14: =SUM(H14:J14) | L14: =COUNTIF($K$2:$K$96,">"&K14)+1 | M14: =IF(L14<=Tham_so!$B$5,"Có","Không") | Q14: =IF(COUNT(N14:P14)=0,"",SUM(N14:P14)) | R14: =IF(Q14="","",COUNTIF($Q$2:$Q$96,">"&Q14)+1) | S14: =IF(OR(K14>=Tham_so!$B$3,AND(ISNUMBER(Q14),Q14>=Tham_so!$B$3)),"Có","Không") | T14: =IF(K14>=Tham_so!$B$9,"Giỏi",IF(K14>=Tham_so!$B$10,"Khá",IF(K14>=Tham_so!$B$11,"Trung bình","Yếu"))) | U14: =IF(Q14="","",IF(Q14>=Tham_so!$B$9,"Giỏi",IF(Q14>=Tham_so!$B$10,"Khá",IF(Q14>=Tham_so!$B$11,"Trung bình","Yếu")))) | V14: Có
A15: 14 | B15: giangdiemho291@gmail.com | C15: Hồ Diễm Giang | D15: Bảng B | E15: Đại học Sư phạm Kỹ thuật TP.HCM | F15: Nghệ An | G15: Không | H15: 180 | I15: 200 | J15: 340 | K15: =SUM(H15:J15) | L15: =COUNTIF($K$2:$K$96,">"&K15)+1 | M15: =IF(L15<=Tham_so!$B$5,"Có","Không") | Q15: =IF(COUNT(N15:P15)=0,"",SUM(N15:P15)) | R15: =IF(Q15="","",COUNTIF($Q$2:$Q$96,">"&Q15)+1) | S15: =IF(OR(K15>=Tham_so!$B$3,AND(ISNUMBER(Q15),Q15>=Tham_so!$B$3)),"Có","Không") | T15: =IF(K15>=Tham_so!$B$9,"Giỏi",IF(K15>=Tham_so!$B$10,"Khá",IF(K15>=Tham_so!$B$11,"Trung bình","Yếu"))) | U15: =IF(Q15="","",IF(Q15>=Tham_so!$B$9,"Giỏi",IF(Q15>=Tham_so!$B$10,"Khá",IF(Q15>=Tham_so!$B$11,"Trung bình","Yếu")))) | V15: Có
A16: 15 | B16: namcongbui774@gmail.com | C16: Bùi Công Nam | D16: Bảng B | E16: Đại học Duy Tân | F16: Hải Phòng | G16: Không | H16: 220 | I16: 140 | J16: 330 | K16: =SUM(H16:J16) | L16: =COUNTIF($K$2:$K$96,">"&K16)+1 | M16: =IF(L16<=Tham_so!$B$5,"Có","Không") | Q16: =IF(COUNT(N16:P16)=0,"",SUM(N16:P16)) | R16: =IF(Q16="","",COUNTIF($Q$2:$Q$96,">"&Q16)+1) | S16: =IF(OR(K16>=Tham_so!$B$3,AND(ISNUMBER(Q16),Q16>=Tham_so!$B$3)),"Có","Không") | T16: =IF(K16>=Tham_so!$B$9,"Giỏi",IF(K16>=Tham_so!$B$10,"Khá",IF(K16>=Tham_so!$B$11,"Trung bình","Yếu"))) | U16: =IF(Q16="","",IF(Q16>=Tham_so!$B$9,"Giỏi",IF(Q16>=Tham_so!$B$10,"Khá",IF(Q16>=Tham_so!$B$11,"Trung bình","Yếu")))) | V16: Có
A17: 16 | B17: thangduydo333@gmail.com | C17: Đỗ Duy Thắng | D17: Bảng B | E17: Đại học CNTT - ĐHQG TP.HCM | F17: Lâm Đồng | G17: Không | H17: 200 | I17: 120 | J17: 370 | K17: =SUM(H17:J17) | L17: =COUNTIF($K$2:$K$96,">"&K17)+1 | M17: =IF(L17<=Tham_so!$B$5,"Có","Không") | Q17: =IF(COUNT(N17:P17)=0,"",SUM(N17:P17)) | R17: =IF(Q17="","",COUNTIF($Q$2:$Q$96,">"&Q17)+1) | S17: =IF(OR(K17>=Tham_so!$B$3,AND(ISNUMBER(Q17),Q17>=Tham_so!$B$3)),"Có","Không") | T17: =IF(K17>=Tham_so!$B$9,"Giỏi",IF(K17>=Tham_so!$B$10,"Khá",IF(K17>=Tham_so!$B$11,"Trung bình","Yếu"))) | U17: =IF(Q17="","",IF(Q17>=Tham_so!$B$9,"Giỏi",IF(Q17>=Tham_so!$B$10,"Khá",IF(Q17>=Tham_so!$B$11,"Trung bình","Yếu")))) | V17: Có
A18: 17 | B18: baoxuanbui904@gmail.com | C18: Bùi Xuân Bảo | D18: Bảng B | E18: Đại học Công nghiệp Hà Nội | F18: Đà Nẵng | G18: Không | H18: 170 | I18: 170 | J18: 330 | K18: =SUM(H18:J18) | L18: =COUNTIF($K$2:$K$96,">"&K18)+1 | M18: =IF(L18<=Tham_so!$B$5,"Có","Không") | Q18: =IF(COUNT(N18:P18)=0,"",SUM(N18:P18)) | R18: =IF(Q18="","",COUNTIF($Q$2:$Q$96,">"&Q18)+1) | S18: =IF(OR(K18>=Tham_so!$B$3,AND(ISNUMBER(Q18),Q18>=Tham_so!$B$3)),"Có","Không") | T18: =IF(K18>=Tham_so!$B$9,"Giỏi",IF(K18>=Tham_so!$B$10,"Khá",IF(K18>=Tham_so!$B$11,"Trung bình","Yếu"))) | U18: =IF(Q18="","",IF(Q18>=Tham_so!$B$9,"Giỏi",IF(Q18>=Tham_so!$B$10,"Khá",IF(Q18>=Tham_so!$B$11,"Trung bình","Yếu")))) | V18: Có
A19: 18 | B19: cuonghuudang940@gmail.com | C19: Đặng Hữu Cường | D19: Bảng B | E19: Đại học FPT | F19: Thanh Hóa | G19: Không | H19: 110 | I19: 140 | J19: 420 | K19: =SUM(H19:J19) | L19: =COUNTIF($K$2:$K$96,">"&K19)+1 | M19: =IF(L19<=Tham_so!$B$5,"Có","Không") | Q19: =IF(COUNT(N19:P19)=0,"",SUM(N19:P19)) | R19: =IF(Q19="","",COUNTIF($Q$2:$Q$96,">"&Q19)+1) | S19: =IF(OR(K19>=Tham_so!$B$3,AND(ISNUMBER(Q19),Q19>=Tham_so!$B$3)),"Có","Không") | T19: =IF(K19>=Tham_so!$B$9,"Giỏi",IF(K19>=Tham_so!$B$10,"Khá",IF(K19>=Tham_so!$B$11,"Trung bình","Yếu"))) | U19: =IF(Q19="","",IF(Q19>=Tham_so!$B$9,"Giỏi",IF(Q19>=Tham_so!$B$10,"Khá",IF(Q19>=Tham_so!$B$11,"Trung bình","Yếu")))) | V19: Có
A20: 19 | B20: tuanquocngo255@gmail.com | C20: Ngô Quốc Tuấn | D20: Bảng B | E20: Đại học Công nghệ - ĐHQGHN | F20: Đà Nẵng | G20: Không | H20: 150 | I20: 220 | J20: 280 | K20: =SUM(H20:J20) | L20: =COUNTIF($K$2:$K$96,">"&K20)+1 | M20: =IF(L20<=Tham_so!$B$5,"Có","Không") | Q20: =IF(COUNT(N20:P20)=0,"",SUM(N20:P20)) | R20: =IF(Q20="","",COUNTIF($Q$2:$Q$96,">"&Q20)+1) | S20: =IF(OR(K20>=Tham_so!$B$3,AND(ISNUMBER(Q20),Q20>=Tham_so!$B$3)),"Có","Không") | T20: =IF(K20>=Tham_so!$B$9,"Giỏi",IF(K20>=Tham_so!$B$10,"Khá",IF(K20>=Tham_so!$B$11,"Trung bình","Yếu"))) | U20: =IF(Q20="","",IF(Q20>=Tham_so!$B$9,"Giỏi",IF(Q20>=Tham_so!$B$10,"Khá",IF(Q20>=Tham_so!$B$11,"Trung bình","Yếu")))) | V20: Có
A21: 20 | B21: minhquocbui841@gmail.com | C21: Bùi Quốc Minh | D21: Bảng B | E21: Đại học Công nghiệp Hà Nội | F21: TP. Hồ Chí Minh | G21: Không | H21: 160 | I21: 150 | J21: 330 | K21: =SUM(H21:J21) | L21: =COUNTIF($K$2:$K$96,">"&K21)+1 | M21: =IF(L21<=Tham_so!$B$5,"Có","Không") | Q21: =IF(COUNT(N21:P21)=0,"",SUM(N21:P21)) | R21: =IF(Q21="","",COUNTIF($Q$2:$Q$96,">"&Q21)+1) | S21: =IF(OR(K21>=Tham_so!$B$3,AND(ISNUMBER(Q21),Q21>=Tham_so!$B$3)),"Có","Không") | T21: =IF(K21>=Tham_so!$B$9,"Giỏi",IF(K21>=Tham_so!$B$10,"Khá",IF(K21>=Tham_so!$B$11,"Trung bình","Yếu"))) | U21: =IF(Q21="","",IF(Q21>=Tham_so!$B$9,"Giỏi",IF(Q21>=Tham_so!$B$10,"Khá",IF(Q21>=Tham_so!$B$11,"Trung bình","Yếu")))) | V21: Có
A22: 21 | B22: hahongbui529@gmail.com | C22: Bùi Hồng Hà | D22: Bảng B | E22: Đại học Việt - Hàn (Đà Nẵng) | F22: Nam Định | G22: Có | H22: 120 | I22: 160 | J22: 350 | K22: =SUM(H22:J22) | L22: =COUNTIF($K$2:$K$96,">"&K22)+1 | M22: =IF(L22<=Tham_so!$B$5,"Có","Không") | Q22: =IF(COUNT(N22:P22)=0,"",SUM(N22:P22)) | R22: =IF(Q22="","",COUNTIF($Q$2:$Q$96,">"&Q22)+1) | S22: =IF(OR(K22>=Tham_so!$B$3,AND(ISNUMBER(Q22),Q22>=Tham_so!$B$3)),"Có","Không") | T22: =IF(K22>=Tham_so!$B$9,"Giỏi",IF(K22>=Tham_so!$B$10,"Khá",IF(K22>=Tham_so!$B$11,"Trung bình","Yếu"))) | U22: =IF(Q22="","",IF(Q22>=Tham_so!$B$9,"Giỏi",IF(Q22>=Tham_so!$B$10,"Khá",IF(Q22>=Tham_so!$B$11,"Trung bình","Yếu")))) | V22: Có
A23: 22 | B23: hunghuubui880@gmail.com | C23: Bùi Hữu Hùng | D23: Bảng B | E23: Đại học Duy Tân | F23: Hải Dương | G23: Không | H23: 190 | I23: 130 | J23: 310 | K23: =SUM(H23:J23) | L23: =COUNTIF($K$2:$K$96,">"&K23)+1 | M23: =IF(L23<=Tham_so!$B$5,"Có","Không") | Q23: =IF(COUNT(N23:P23)=0,"",SUM(N23:P23)) | R23: =IF(Q23="","",COUNTIF($Q$2:$Q$96,">"&Q23)+1) | S23: =IF(OR(K23>=Tham_so!$B$3,AND(ISNUMBER(Q23),Q23>=Tham_so!$B$3)),"Có","Không") | T23: =IF(K23>=Tham_so!$B$9,"Giỏi",IF(K23>=Tham_so!$B$10,"Khá",IF(K23>=Tham_so!$B$11,"Trung bình","Yếu"))) | U23: =IF(Q23="","",IF(Q23>=Tham_so!$B$9,"Giỏi",IF(Q23>=Tham_so!$B$10,"Khá",IF(Q23>=Tham_so!$B$11,"Trung bình","Yếu")))) | V23: Có
... A96: 95 | B96: buithitrang789@gmail.com | C96: Bùi Thị Trang | D96: Bảng B | E96: Học viện Công nghệ Bưu chính Viễn thông - PTIT | F96: TP. Hồ Chí Minh | G96: Có | H96: 160 | I96: 140 | J96: 280 | K96: =SUM(H96:J96) | L96: =COUNTIF($K$2:$K$96,">"&K96)+1 | M96: =IF(L96<=Tham_so!$B$5,"Có","Không") | Q96: =IF(COUNT(N96:P96)=0,"",SUM(N96:P96)) | R96: =IF(Q96="","",COUNTIF($Q$2:$Q$96,">"&Q96)+1) | S96: =IF(OR(K96>=Tham_so!$B$3,AND(ISNUMBER(Q96),Q96>=Tham_so!$B$3)),"Có","Không") | T96: =IF(K96>=Tham_so!$B$9,"Giỏi",IF(K96>=Tham_so!$B$10,"Khá",IF(K96>=Tham_so!$B$11,"Trung bình","Yếu"))) | U96: =IF(Q96="","",IF(Q96>=Tham_so!$B$9,"Giỏi",IF(Q96>=Tham_so!$B$10,"Khá",IF(Q96>=Tham_so!$B$11,"Trung bình","Yếu")))) | V96: Có

Sheet Phan_loai
A1: PHÂN LOẠI ĐIỂM — BẢNG B (dữ liệu GIẢ LẬP)
A2: Xếp loại theo tổng điểm /1000, ngưỡng lấy từ sheet Tham_so. Chung kết chỉ có vài người nên tỷ lệ % ở vòng này kém ổn định.
A5: Xếp loại | B5: Điều kiện (tổng /1000) | C5: Bảng B – Vòng loại | E5: Bảng B – Chung kết
C6: Số người | D6: % | E6: Số người | F6: %
A7: Giỏi | B7: ="≥ "&Tham_so!$B$9 | C7: =COUNTIF(Tong_hop!$T$2:$T$96,$A7) | D7: =IF(C$11=0,"",C7/C$11) | E7: =COUNTIF(Tong_hop!$U$2:$U$96,$A7) | F7: =IF(E$11=0,"",E7/E$11)
A8: Khá | B8: ="từ "&Tham_so!$B$10&" đến dưới "&Tham_so!$B$9 | C8: =COUNTIF(Tong_hop!$T$2:$T$96,$A8) | D8: =IF(C$11=0,"",C8/C$11) | E8: =COUNTIF(Tong_hop!$U$2:$U$96,$A8) | F8: =IF(E$11=0,"",E8/E$11)
A9: Trung bình | B9: ="từ "&Tham_so!$B$11&" đến dưới "&Tham_so!$B$10 | C9: =COUNTIF(Tong_hop!$T$2:$T$96,$A9) | D9: =IF(C$11=0,"",C9/C$11) | E9: =COUNTIF(Tong_hop!$U$2:$U$96,$A9) | F9: =IF(E$11=0,"",E9/E$11)
A10: Yếu | B10: ="dưới "&Tham_so!$B$11 | C10: =COUNTIF(Tong_hop!$T$2:$T$96,$A10) | D10: =IF(C$11=0,"",C10/C$11) | E10: =COUNTIF(Tong_hop!$U$2:$U$96,$A10) | F10: =IF(E$11=0,"",E10/E$11)
A11: Tổng | C11: =SUM(C7:C10) | D11: =IF(C11=0,"",SUM(D7:D10)) | E11: =SUM(E7:E10) | F11: =IF(E11=0,"",SUM(F7:F10))
A14: CHỈ SỐ TỔNG QUAN
A15: Chỉ số | C15: Bảng B – Vòng loại | E15: Bảng B – Chung kết
A16: Số thí sinh có điểm | C16: =COUNT(Tong_hop!$K$2:$K$96) | E16: =COUNT(Tong_hop!$Q$2:$Q$96)
A17: Điểm trung bình | C17: =IFERROR(AVERAGE(Tong_hop!$K$2:$K$96),"") | E17: =IFERROR(AVERAGE(Tong_hop!$Q$2:$Q$96),"")
A18: Điểm cao nhất | C18: =IF(C16=0,"",MAX(Tong_hop!$K$2:$K$96)) | E18: =IF(E16=0,"",MAX(Tong_hop!$Q$2:$Q$96))
A19: Điểm thấp nhất | C19: =IF(C16=0,"",MIN(Tong_hop!$K$2:$K$96)) | E19: =IF(E16=0,"",MIN(Tong_hop!$Q$2:$Q$96))
A20: Số người đạt ngưỡng chứng chỉ | C20: =COUNTIF(Tong_hop!$K$2:$K$96,">="&Tham_so!$B$3) | E20: =COUNTIF(Tong_hop!$Q$2:$Q$96,">="&Tham_so!$B$3)

Sheet Chi_tiet_diem
A1: Email | B1: Họ tên | C1: Bảng | D1: Vòng | E1: Cấp COS Pro | F1: Phần thi | G1: Điểm | H1: Điểm tối đa | I1: % điểm | J1: Dữ liệu giả lập
A2: cuongquocbui192@gmail.com | B2: Bùi Quốc Cường | C2: Bảng B | D2: Vòng loại | E2: COS Pro Level 2 | F2: Debugging | G2: =INDEX(Tong_hop!$H$2:$H$96,MATCH($A2,Tong_hop!$B$2:$B$96,0)) | H2: 280 | I2: =IF(H2=0,"",G2/H2) | J2: Có
A3: cuongquocbui192@gmail.com | B3: Bùi Quốc Cường | C3: Bảng B | D3: Vòng loại | E3: COS Pro Level 2 | F3: Design | G3: =INDEX(Tong_hop!$I$2:$I$96,MATCH($A3,Tong_hop!$B$2:$B$96,0)) | H3: 280 | I3: =IF(H3=0,"",G3/H3) | J3: Có
A4: cuongquocbui192@gmail.com | B4: Bùi Quốc Cường | C4: Bảng B | D4: Vòng loại | E4: COS Pro Level 2 | F4: Đọc hiểu code | G4: =INDEX(Tong_hop!$J$2:$J$96,MATCH($A4,Tong_hop!$B$2:$B$96,0)) | H4: 440 | I4: =IF(H4=0,"",G4/H4) | J4: Có
A5: cuongquocbui192@gmail.com | B5: Bùi Quốc Cường | C5: Bảng B | D5: Chung kết | E5: COS Pro Level 1 | F5: Debugging | G5: =INDEX(Tong_hop!$N$2:$N$96,MATCH($A5,Tong_hop!$B$2:$B$96,0)) | H5: 240 | I5: =IF(H5=0,"",G5/H5) | J5: Có
A6: cuongquocbui192@gmail.com | B6: Bùi Quốc Cường | C6: Bảng B | D6: Chung kết | E6: COS Pro Level 1 | F6: Design | G6: =INDEX(Tong_hop!$O$2:$O$96,MATCH($A6,Tong_hop!$B$2:$B$96,0)) | H6: 420 | I6: =IF(H6=0,"",G6/H6) | J6: Có
A7: cuongquocbui192@gmail.com | B7: Bùi Quốc Cường | C7: Bảng B | D7: Chung kết | E7: COS Pro Level 1 | F7: Đọc hiểu code | G7: =INDEX(Tong_hop!$P$2:$P$96,MATCH($A7,Tong_hop!$B$2:$B$96,0)) | H7: 340 | I7: =IF(H7=0,"",G7/H7) | J7: Có
A8: maikimhoang104@gmail.com | B8: Hoàng Kim Mai | C8: Bảng B | D8: Vòng loại | E8: COS Pro Level 2 | F8: Debugging | G8: =INDEX(Tong_hop!$H$2:$H$96,MATCH($A8,Tong_hop!$B$2:$B$96,0)) | H8: 280 | I8: =IF(H8=0,"",G8/H8) | J8: Có
A9: maikimhoang104@gmail.com | B9: Hoàng Kim Mai | C9: Bảng B | D9: Vòng loại | E9: COS Pro Level 2 | F9: Design | G9: =INDEX(Tong_hop!$I$2:$I$96,MATCH($A9,Tong_hop!$B$2:$B$96,0)) | H9: 280 | I9: =IF(H9=0,"",G9/H9) | J9: Có
A10: maikimhoang104@gmail.com | B10: Hoàng Kim Mai | C10: Bảng B | D10: Vòng loại | E10: COS Pro Level 2 | F10: Đọc hiểu code | G10: =INDEX(Tong_hop!$J$2:$J$96,MATCH($A10,Tong_hop!$B$2:$B$96,0)) | H10: 440 | I10: =IF(H10=0,"",G10/H10) | J10: Có
A11: maikimhoang104@gmail.com | B11: Hoàng Kim Mai | C11: Bảng B | D11: Chung kết | E11: COS Pro Level 1 | F11: Debugging | G11: =INDEX(Tong_hop!$N$2:$N$96,MATCH($A11,Tong_hop!$B$2:$B$96,0)) | H11: 240 | I11: =IF(H11=0,"",G11/H11) | J11: Có
A12: maikimhoang104@gmail.com | B12: Hoàng Kim Mai | C12: Bảng B | D12: Chung kết | E12: COS Pro Level 1 | F12: Design | G12: =INDEX(Tong_hop!$O$2:$O$96,MATCH($A12,Tong_hop!$B$2:$B$96,0)) | H12: 420 | I12: =IF(H12=0,"",G12/H12) | J12: Có
A13: maikimhoang104@gmail.com | B13: Hoàng Kim Mai | C13: Bảng B | D13: Chung kết | E13: COS Pro Level 1 | F13: Đọc hiểu code | G13: =INDEX(Tong_hop!$P$2:$P$96,MATCH($A13,Tong_hop!$B$2:$B$96,0)) | H13: 340 | I13: =IF(H13=0,"",G13/H13) | J13: Có
A14: hungxuanvu253@gmail.com | B14: Vũ Xuân Hùng | C14: Bảng B | D14: Vòng loại | E14: COS Pro Level 2 | F14: Debugging | G14: =INDEX(Tong_hop!$H$2:$H$96,MATCH($A14,Tong_hop!$B$2:$B$96,0)) | H14: 280 | I14: =IF(H14=0,"",G14/H14) | J14: Có
A15: hungxuanvu253@gmail.com | B15: Vũ Xuân Hùng | C15: Bảng B | D15: Vòng loại | E15: COS Pro Level 2 | F15: Design | G15: =INDEX(Tong_hop!$I$2:$I$96,MATCH($A15,Tong_hop!$B$2:$B$96,0)) | H15: 280 | I15: =IF(H15=0,"",G15/H15) | J15: Có
A16: hungxuanvu253@gmail.com | B16: Vũ Xuân Hùng | C16: Bảng B | D16: Vòng loại | E16: COS Pro Level 2 | F16: Đọc hiểu code | G16: =INDEX(Tong_hop!$J$2:$J$96,MATCH($A16,Tong_hop!$B$2:$B$96,0)) | H16: 440 | I16: =IF(H16=0,"",G16/H16) | J16: Có
A17: hungxuanvu253@gmail.com | B17: Vũ Xuân Hùng | C17: Bảng B | D17: Chung kết | E17: COS Pro Level 1 | F17: Debugging | G17: =INDEX(Tong_hop!$N$2:$N$96,MATCH($A17,Tong_hop!$B$2:$B$96,0)) | H17: 240 | I17: =IF(H17=0,"",G17/H17) | J17: Có
A18: hungxuanvu253@gmail.com | B18: Vũ Xuân Hùng | C18: Bảng B | D18: Chung kết | E18: COS Pro Level 1 | F18: Design | G18: =INDEX(Tong_hop!$O$2:$O$96,MATCH($A18,Tong_hop!$B$2:$B$96,0)) | H18: 420 | I18: =IF(H18=0,"",G18/H18) | J18: Có
A19: hungxuanvu253@gmail.com | B19: Vũ Xuân Hùng | C19: Bảng B | D19: Chung kết | E19: COS Pro Level 1 | F19: Đọc hiểu code | G19: =INDEX(Tong_hop!$P$2:$P$96,MATCH($A19,Tong_hop!$B$2:$B$96,0)) | H19: 340 | I19: =IF(H19=0,"",G19/H19) | J19: Có
A20: hungminhly687@gmail.com | B20: Lý Minh Hùng | C20: Bảng B | D20: Vòng loại | E20: COS Pro Level 2 | F20: Debugging | G20: =INDEX(Tong_hop!$H$2:$H$96,MATCH($A20,Tong_hop!$B$2:$B$96,0)) | H20: 280 | I20: =IF(H20=0,"",G20/H20) | J20: Có
A21: hungminhly687@gmail.com | B21: Lý Minh Hùng | C21: Bảng B | D21: Vòng loại | E21: COS Pro Level 2 | F21: Design | G21: =INDEX(Tong_hop!$I$2:$I$96,MATCH($A21,Tong_hop!$B$2:$B$96,0)) | H21: 280 | I21: =IF(H21=0,"",G21/H21) | J21: Có
A22: hungminhly687@gmail.com | B22: Lý Minh Hùng | C22: Bảng B | D22: Vòng loại | E22: COS Pro Level 2 | F22: Đọc hiểu code | G22: =INDEX(Tong_hop!$J$2:$J$96,MATCH($A22,Tong_hop!$B$2:$B$96,0)) | H22: 440 | I22: =IF(H22=0,"",G22/H22) | J22: Có
A23: hungminhly687@gmail.com | B23: Lý Minh Hùng | C23: Bảng B | D23: Chung kết | E23: COS Pro Level 1 | F23: Debugging | G23: =INDEX(Tong_hop!$N$2:$N$96,MATCH($A23,Tong_hop!$B$2:$B$96,0)) | H23: 240 | I23: =IF(H23=0,"",G23/H23) | J23: Có
A24: hungminhly687@gmail.com | B24: Lý Minh Hùng | C24: Bảng B | D24: Chung kết | E24: COS Pro Level 1 | F24: Design | G24: =INDEX(Tong_hop!$O$2:$O$96,MATCH($A24,Tong_hop!$B$2:$B$96,0)) | H24: 420 | I24: =IF(H24=0,"",G24/H24) | J24: Có
A25: hungminhly687@gmail.com | B25: Lý Minh Hùng | C25: Bảng B | D25: Chung kết | E25: COS Pro Level 1 | F25: Đọc hiểu code | G25: =INDEX(Tong_hop!$P$2:$P$96,MATCH($A25,Tong_hop!$B$2:$B$96,0)) | H25: 340 | I25: =IF(H25=0,"",G25/H25) | J25: Có
A26: maingochoang945@gmail.com | B26: Hoàng Ngọc Mai | C26: Bảng B | D26: Vòng loại | E26: COS Pro Level 2 | F26: Debugging | G26: =INDEX(Tong_hop!$H$2:$H$96,MATCH($A26,Tong_hop!$B$2:$B$96,0)) | H26: 280 | I26: =IF(H26=0,"",G26/H26) | J26: Có
A27: maingochoang945@gmail.com | B27: Hoàng Ngọc Mai | C27: Bảng B | D27: Vòng loại | E27: COS Pro Level 2 | F27: Design | G27: =INDEX(Tong_hop!$I$2:$I$96,MATCH($A27,Tong_hop!$B$2:$B$96,0)) | H27: 280 | I27: =IF(H27=0,"",G27/H27) | J27: Có
A28: maingochoang945@gmail.com | B28: Hoàng Ngọc Mai | C28: Bảng B | D28: Vòng loại | E28: COS Pro Level 2 | F28: Đọc hiểu code | G28: =INDEX(Tong_hop!$J$2:$J$96,MATCH($A28,Tong_hop!$B$2:$B$96,0)) | H28: 440 | I28: =IF(H28=0,"",G28/H28) | J28: Có
A29: maingochoang945@gmail.com | B29: Hoàng Ngọc Mai | C29: Bảng B | D29: Chung kết | E29: COS Pro Level 1 | F29: Debugging | G29: =INDEX(Tong_hop!$N$2:$N$96,MATCH($A29,Tong_hop!$B$2:$B$96,0)) | H29: 240 | I29: =IF(H29=0,"",G29/H29) | J29: Có
A30: maingochoang945@gmail.com | B30: Hoàng Ngọc Mai | C30: Bảng B | D30: Chung kết | E30: COS Pro Level 1 | F30: Design | G30: =INDEX(Tong_hop!$O$2:$O$96,MATCH($A30,Tong_hop!$B$2:$B$96,0)) | H30: 420 | I30: =IF(H30=0,"",G30/H30) | J30: Có
A31: maingochoang945@gmail.com | B31: Hoàng Ngọc Mai | C31: Bảng B | D31: Chung kết | E31: COS Pro Level 1 | F31: Đọc hiểu code | G31: =INDEX(Tong_hop!$P$2:$P$96,MATCH($A31,Tong_hop!$B$2:$B$96,0)) | H31: 340 | I31: =IF(H31=0,"",G31/H31) | J31: Có
A32: sonquochuynh931@gmail.com | B32: Huỳnh Quốc Sơn | C32: Bảng B | D32: Vòng loại | E32: COS Pro Level 2 | F32: Debugging | G32: =INDEX(Tong_hop!$H$2:$H$96,MATCH($A32,Tong_hop!$B$2:$B$96,0)) | H32: 280 | I32: =IF(H32=0,"",G32/H32) | J32: Có
A33: sonquochuynh931@gmail.com | B33: Huỳnh Quốc Sơn | C33: Bảng B | D33: Vòng loại | E33: COS Pro Level 2 | F33: Design | G33: =INDEX(Tong_hop!$I$2:$I$96,MATCH($A33,Tong_hop!$B$2:$B$96,0)) | H33: 280 | I33: =IF(H33=0,"",G33/H33) | J33: Có
A34: sonquochuynh931@gmail.com | B34: Huỳnh Quốc Sơn | C34: Bảng B | D34: Vòng loại | E34: COS Pro Level 2 | F34: Đọc hiểu code | G34: =INDEX(Tong_hop!$J$2:$J$96,MATCH($A34,Tong_hop!$B$2:$B$96,0)) | H34: 440 | I34: =IF(H34=0,"",G34/H34) | J34: Có
A35: sonquochuynh931@gmail.com | B35: Huỳnh Quốc Sơn | C35: Bảng B | D35: Chung kết | E35: COS Pro Level 1 | F35: Debugging | G35: =INDEX(Tong_hop!$N$2:$N$96,MATCH($A35,Tong_hop!$B$2:$B$96,0)) | H35: 240 | I35: =IF(H35=0,"",G35/H35) | J35: Có
A36: sonquochuynh931@gmail.com | B36: Huỳnh Quốc Sơn | C36: Bảng B | D36: Chung kết | E36: COS Pro Level 1 | F36: Design | G36: =INDEX(Tong_hop!$O$2:$O$96,MATCH($A36,Tong_hop!$B$2:$B$96,0)) | H36: 420 | I36: =IF(H36=0,"",G36/H36) | J36: Có
A37: sonquochuynh931@gmail.com | B37: Huỳnh Quốc Sơn | C37: Bảng B | D37: Chung kết | E37: COS Pro Level 1 | F37: Đọc hiểu code | G37: =INDEX(Tong_hop!$P$2:$P$96,MATCH($A37,Tong_hop!$B$2:$B$96,0)) | H37: 340 | I37: =IF(H37=0,"",G37/H37) | J37: Có
A38: tuananhdang463@gmail.com | B38: Đặng Anh Tuấn | C38: Bảng B | D38: Vòng loại | E38: COS Pro Level 2 | F38: Debugging | G38: =INDEX(Tong_hop!$H$2:$H$96,MATCH($A38,Tong_hop!$B$2:$B$96,0)) | H38: 280 | I38: =IF(H38=0,"",G38/H38) | J38: Có
A39: tuananhdang463@gmail.com | B39: Đặng Anh Tuấn | C39: Bảng B | D39: Vòng loại | E39: COS Pro Level 2 | F39: Design | G39: =INDEX(Tong_hop!$I$2:$I$96,MATCH($A39,Tong_hop!$B$2:$B$96,0)) | H39: 280 | I39: =IF(H39=0,"",G39/H39) | J39: Có
A40: tuananhdang463@gmail.com | B40: Đặng Anh Tuấn | C40: Bảng B | D40: Vòng loại | E40: COS Pro Level 2 | F40: Đọc hiểu code | G40: =INDEX(Tong_hop!$J$2:$J$96,MATCH($A40,Tong_hop!$B$2:$B$96,0)) | H40: 440 | I40: =IF(H40=0,"",G40/H40) | J40: Có
...

Sheet Cau_truc_de
A1: CẤU TRÚC ĐỀ THI — BẢNG B
A2: Nguồn: https://pythonmaster.vn/#exam_structure (mục 'Cấu trúc thi'), đọc ngày 20/09/2026. Mỗi vòng 10 câu, thang 1.000 điểm.
A4: Vòng | B4: Cấp COS Pro | C4: Phần thi | D4: Câu | E4: Điểm tối đa
A5: Vòng loại | B5: COS Pro Level 2 | C5: Debugging | E5: 280
A6: Vòng loại | B6: COS Pro Level 2 | C6: Design | E6: 280
A7: Vòng loại | B7: COS Pro Level 2 | C7: Đọc hiểu code | E7: 440
A8: Chung kết | B8: COS Pro Level 1 | C8: Debugging | E8: 240
A9: Chung kết | B9: COS Pro Level 1 | C9: Design | E9: 420
A10: Chung kết | B10: COS Pro Level 1 | C10: Đọc hiểu code | E10: 340
A12: Kiểm tra tổng điểm từng vòng
A13: Vòng loại | E13: =SUMIFS($E$5:$E$10,$A$5:$A$10,A13)
A14: Chung kết | E14: =SUMIFS($E$5:$E$10,$A$5:$A$10,A14)

Sheet Tham_so
A1: THAM SỐ — BẢNG B (sửa ô xanh dương, các ô còn lại tự tính)
A3: Ngưỡng nhận chứng chỉ COS Pro (/1000, ở bất kỳ vòng nào) | B3: 600 | C3: Nguồn: pythonmaster.vn/#exam_structure — 'đạt ≥600/1000 điểm ở bất kỳ vòng nào'
A4: Tỷ lệ Top vào chung kết | B4: 0.1 | C4: Nguồn: pythonmaster.vn — 'Top 10% vượt qua vòng loại sẽ tham gia vòng chung kết' (làm tròn LÊN)
A5: Số người vào chung kết — Bảng B | B5: =ROUNDUP(ROUND(COUNTA(Tong_hop!$B$2:$B$96)*$B$4,6),0) | C5: Số thí sinh của bảng × tỷ lệ Top, làm tròn lên
A8: XẾP LOẠI THEO TỔNG ĐIỂM (/1000) — ngưỡng 800 và 400 là giả định, sửa được
A9: Giỏi khi tổng điểm ≥ | B9: 800
A10: Khá khi tổng điểm ≥ (mặc định bằng ngưỡng chứng chỉ) | B10: =$B$3
A11: Trung bình khi tổng điểm ≥ | B11: 400
A12: Yếu: tổng điểm dưới ngưỡng Trung bình

Sheet Ghi_chu
A1: GHI CHÚ — BẢNG B — ĐỌC TRƯỚC KHI DÙNG
A3: DỮ LIỆU GIẢ LẬP | B3: Toàn bộ điểm trong file là số ngẫu nhiên do mô hình sinh ra, KHÔNG phải kết quả thật của thí sinh. Không dùng để công bố, xếp hạng hay đánh giá từng cá nhân.
A4: Hai file | B4: Đây là file của Bảng B (95 người). File của bảng còn lại có cùng cấu trúc và cách sinh điểm.
A5: Nguồn cấu trúc | B5: Cấu trúc đề, thang 1.000 điểm, tỷ lệ Top 10% vào chung kết và ngưỡng 600 điểm lấy từ pythonmaster.vn/#exam_structure (xem sheet Cau_truc_de). Cuộc thi thật: Vòng loại từ 20/09/2026, Chung kết 10/10/2026 nên chưa có điểm thật.
A6: Danh sách thí sinh | B6: 95 người thuộc Bảng B: 78 người gốc + 17 người mới (PT-001 → PT-018). 29 người đã thanh toán; cột 'Đã thanh toán' cho phép lọc riêng nhóm này.
A7: Cách sinh điểm | B7: 78 người đầu giữ nguyên điểm từ file gốc. 17 người mới sinh bằng seed = 9999: năng lực ẩn ~ N(560, 160); Debugging ×0.90, Design ×0.75, Đọc hiểu ×1.10; làm tròn bước 10; không vượt điểm tối đa. Đề Chung kết khó hơn (Level 2 → Level 1).
A8: Quy tắc vào chung kết | B8: Top 10% theo tổng điểm Vòng loại, làm tròn lên: 10 người. Chỉ những người này có điểm Chung kết. Tổng, hạng, cột 'Vượt vòng loại', 'Chứng chỉ' và xếp loại là công thức, tự cập nhật khi đổi tham số (sheet Tham_so) hoặc điểm.
A9: Xếp loại | B9: Giỏi ≥ 800, Khá ≥ 600 (bằng ngưỡng chứng chỉ trên web), Trung bình ≥ 400, Yếu < 400, tính theo tổng điểm /1000.
A10: Đồng hạng | B10: Hạng tính kiểu thi đấu (đồng điểm cùng hạng). Nếu có đồng hạng ở ranh giới top 10, số người vào CK có thể nhiều hơn 10.
A11: Thay bằng điểm thật | B11: Ghi đè các ô nền đỏ nhạt ở các cột điểm phần trong sheet Tong_hop. Sheet Chi_tiet_diem tự lấy điểm theo email.
A12: Quy ước màu | B12: Chữ xanh dương = số nhập tay · chữ đen = công thức · chữ xanh lá = lấy từ sheet khác · ô nền đỏ nhạt = dữ liệu giả lập · ô nền xanh nhạt = 'Có'.
