Workbook

Sheet Tong_hop
A1: STT | B1: Email | C1: Họ tên | D1: Bảng | E1: Trường | F1: Tỉnh/TP | G1: Đã thanh toán | H1: VL – Đọc hiểu code (/500) | I1: VL – Thiết kế · viết hàm (/500) | J1: VL – Tổng (/1000) | K1: VL – Hạng trong bảng | L1: Vượt vòng loại (Top 10%) | M1: CK – Debugging (/280) | N1: CK – Design (/280) | O1: CK – Đọc hiểu code (/440) | P1: CK – Tổng (/1000) | Q1: CK – Hạng trong bảng | R1: Chứng chỉ COS Pro (≥600) | S1: VL – Xếp loại | T1: CK – Xếp loại | U1: Dữ liệu giả lập
A2: 1 | B2: phongthanhle754@gmail.com | C2: Lê Thành Phong | D2: Bảng A | E2: THPT Nguyễn Thị Minh Khai | F2: Khánh Hòa | G2: Không | H2: 460 | I2: 320 | J2: =SUM(H2:I2) | K2: =COUNTIF($J$2:$J$25,">"&J2)+1 | L2: =IF(K2<=Tham_so!$B$5,"Có","Không") | M2: 160 | N2: 70 | O2: 290 | P2: =IF(COUNT(M2:O2)=0,"",SUM(M2:O2)) | Q2: =IF(P2="","",COUNTIF($P$2:$P$25,">"&P2)+1) | R2: =IF(OR(J2>=Tham_so!$B$3,AND(ISNUMBER(P2),P2>=Tham_so!$B$3)),"Có","Không") | S2: =IF(J2>=Tham_so!$B$9,"Giỏi",IF(J2>=Tham_so!$B$10,"Khá",IF(J2>=Tham_so!$B$11,"Trung bình","Yếu"))) | T2: =IF(P2="","",IF(P2>=Tham_so!$B$9,"Giỏi",IF(P2>=Tham_so!$B$10,"Khá",IF(P2>=Tham_so!$B$11,"Trung bình","Yếu")))) | U2: Có
A3: 2 | B3: vietducdo703@gmail.com | C3: Đỗ Đức Việt | D3: Bảng A | E3: THPT Nguyễn Huệ | F3: Thanh Hóa | G3: Không | H3: 390 | I3: 380 | J3: =SUM(H3:I3) | K3: =COUNTIF($J$2:$J$25,">"&J3)+1 | L3: =IF(K3<=Tham_so!$B$5,"Có","Không") | M3: 160 | N3: 100 | O3: 270 | P3: =IF(COUNT(M3:O3)=0,"",SUM(M3:O3)) | Q3: =IF(P3="","",COUNTIF($P$2:$P$25,">"&P3)+1) | R3: =IF(OR(J3>=Tham_so!$B$3,AND(ISNUMBER(P3),P3>=Tham_so!$B$3)),"Có","Không") | S3: =IF(J3>=Tham_so!$B$9,"Giỏi",IF(J3>=Tham_so!$B$10,"Khá",IF(J3>=Tham_so!$B$11,"Trung bình","Yếu"))) | T3: =IF(P3="","",IF(P3>=Tham_so!$B$9,"Giỏi",IF(P3>=Tham_so!$B$10,"Khá",IF(P3>=Tham_so!$B$11,"Trung bình","Yếu")))) | U3: Có
A4: 3 | B4: diepanhngo708@gmail.com | C4: Ngô Ánh Diệp | D4: Bảng A | E4: THPT Lương Thế Vinh | F4: Quảng Ninh | G4: Có | H4: 380 | I4: 340 | J4: =SUM(H4:I4) | K4: =COUNTIF($J$2:$J$25,">"&J4)+1 | L4: =IF(K4<=Tham_so!$B$5,"Có","Không") | M4: 140 | N4: 90 | O4: 250 | P4: =IF(COUNT(M4:O4)=0,"",SUM(M4:O4)) | Q4: =IF(P4="","",COUNTIF($P$2:$P$25,">"&P4)+1) | R4: =IF(OR(J4>=Tham_so!$B$3,AND(ISNUMBER(P4),P4>=Tham_so!$B$3)),"Có","Không") | S4: =IF(J4>=Tham_so!$B$9,"Giỏi",IF(J4>=Tham_so!$B$10,"Khá",IF(J4>=Tham_so!$B$11,"Trung bình","Yếu"))) | T4: =IF(P4="","",IF(P4>=Tham_so!$B$9,"Giỏi",IF(P4>=Tham_so!$B$10,"Khá",IF(P4>=Tham_so!$B$11,"Trung bình","Yếu")))) | U4: Có
A5: 4 | B5: baovandang431@gmail.com | C5: Đặng Văn Bảo | D5: Bảng A | E5: THPT Việt Đức | F5: Nghệ An | G5: Không | H5: 380 | I5: 320 | J5: =SUM(H5:I5) | K5: =COUNTIF($J$2:$J$25,">"&J5)+1 | L5: =IF(K5<=Tham_so!$B$5,"Có","Không") | P5: =IF(COUNT(M5:O5)=0,"",SUM(M5:O5)) | Q5: =IF(P5="","",COUNTIF($P$2:$P$25,">"&P5)+1) | R5: =IF(OR(J5>=Tham_so!$B$3,AND(ISNUMBER(P5),P5>=Tham_so!$B$3)),"Có","Không") | S5: =IF(J5>=Tham_so!$B$9,"Giỏi",IF(J5>=Tham_so!$B$10,"Khá",IF(J5>=Tham_so!$B$11,"Trung bình","Yếu"))) | T5: =IF(P5="","",IF(P5>=Tham_so!$B$9,"Giỏi",IF(P5>=Tham_so!$B$10,"Khá",IF(P5>=Tham_so!$B$11,"Trung bình","Yếu")))) | U5: Có
A6: 5 | B6: chithanhbui743@gmail.com | C6: Bùi Thanh Chi | D6: Bảng A | E6: THPT Kim Liên | F6: Khánh Hòa | G6: Không | H6: 350 | I6: 310 | J6: =SUM(H6:I6) | K6: =COUNTIF($J$2:$J$25,">"&J6)+1 | L6: =IF(K6<=Tham_so!$B$5,"Có","Không") | P6: =IF(COUNT(M6:O6)=0,"",SUM(M6:O6)) | Q6: =IF(P6="","",COUNTIF($P$2:$P$25,">"&P6)+1) | R6: =IF(OR(J6>=Tham_so!$B$3,AND(ISNUMBER(P6),P6>=Tham_so!$B$3)),"Có","Không") | S6: =IF(J6>=Tham_so!$B$9,"Giỏi",IF(J6>=Tham_so!$B$10,"Khá",IF(J6>=Tham_so!$B$11,"Trung bình","Yếu"))) | T6: =IF(P6="","",IF(P6>=Tham_so!$B$9,"Giỏi",IF(P6>=Tham_so!$B$10,"Khá",IF(P6>=Tham_so!$B$11,"Trung bình","Yếu")))) | U6: Có
A7: 6 | B7: hunganhle722@gmail.com | C7: Lê Anh Hùng | D7: Bảng A | E7: THPT Nguyễn Thị Minh Khai | F7: Thái Nguyên | G7: Không | H7: 350 | I7: 310 | J7: =SUM(H7:I7) | K7: =COUNTIF($J$2:$J$25,">"&J7)+1 | L7: =IF(K7<=Tham_so!$B$5,"Có","Không") | P7: =IF(COUNT(M7:O7)=0,"",SUM(M7:O7)) | Q7: =IF(P7="","",COUNTIF($P$2:$P$25,">"&P7)+1) | R7: =IF(OR(J7>=Tham_so!$B$3,AND(ISNUMBER(P7),P7>=Tham_so!$B$3)),"Có","Không") | S7: =IF(J7>=Tham_so!$B$9,"Giỏi",IF(J7>=Tham_so!$B$10,"Khá",IF(J7>=Tham_so!$B$11,"Trung bình","Yếu"))) | T7: =IF(P7="","",IF(P7>=Tham_so!$B$9,"Giỏi",IF(P7>=Tham_so!$B$10,"Khá",IF(P7>=Tham_so!$B$11,"Trung bình","Yếu")))) | U7: Có
A8: 7 | B8: hoangocdang962@gmail.com | C8: Đặng Ngọc Hoa | D8: Bảng A | E8: THPT Lê Quý Đôn | F8: TP. Hồ Chí Minh | G8: Không | H8: 330 | I8: 240 | J8: =SUM(H8:I8) | K8: =COUNTIF($J$2:$J$25,">"&J8)+1 | L8: =IF(K8<=Tham_so!$B$5,"Có","Không") | P8: =IF(COUNT(M8:O8)=0,"",SUM(M8:O8)) | Q8: =IF(P8="","",COUNTIF($P$2:$P$25,">"&P8)+1) | R8: =IF(OR(J8>=Tham_so!$B$3,AND(ISNUMBER(P8),P8>=Tham_so!$B$3)),"Có","Không") | S8: =IF(J8>=Tham_so!$B$9,"Giỏi",IF(J8>=Tham_so!$B$10,"Khá",IF(J8>=Tham_so!$B$11,"Trung bình","Yếu"))) | T8: =IF(P8="","",IF(P8>=Tham_so!$B$9,"Giỏi",IF(P8>=Tham_so!$B$10,"Khá",IF(P8>=Tham_so!$B$11,"Trung bình","Yếu")))) | U8: Có
A9: 8 | B9: linhdiemdang377@gmail.com | C9: Đặng Diễm Linh | D9: Bảng A | E9: THPT Chu Văn An | F9: Khánh Hòa | G9: Không | H9: 380 | I9: 190 | J9: =SUM(H9:I9) | K9: =COUNTIF($J$2:$J$25,">"&J9)+1 | L9: =IF(K9<=Tham_so!$B$5,"Có","Không") | P9: =IF(COUNT(M9:O9)=0,"",SUM(M9:O9)) | Q9: =IF(P9="","",COUNTIF($P$2:$P$25,">"&P9)+1) | R9: =IF(OR(J9>=Tham_so!$B$3,AND(ISNUMBER(P9),P9>=Tham_so!$B$3)),"Có","Không") | S9: =IF(J9>=Tham_so!$B$9,"Giỏi",IF(J9>=Tham_so!$B$10,"Khá",IF(J9>=Tham_so!$B$11,"Trung bình","Yếu"))) | T9: =IF(P9="","",IF(P9>=Tham_so!$B$9,"Giỏi",IF(P9>=Tham_so!$B$10,"Khá",IF(P9>=Tham_so!$B$11,"Trung bình","Yếu")))) | U9: Có
A10: 9 | B10: linhngocdo961@gmail.com | C10: Đỗ Ngọc Linh | D10: Bảng A | E10: THPT Chu Văn An | F10: Quảng Ninh | G10: Có | H10: 270 | I10: 240 | J10: =SUM(H10:I10) | K10: =COUNTIF($J$2:$J$25,">"&J10)+1 | L10: =IF(K10<=Tham_so!$B$5,"Có","Không") | P10: =IF(COUNT(M10:O10)=0,"",SUM(M10:O10)) | Q10: =IF(P10="","",COUNTIF($P$2:$P$25,">"&P10)+1) | R10: =IF(OR(J10>=Tham_so!$B$3,AND(ISNUMBER(P10),P10>=Tham_so!$B$3)),"Có","Không") | S10: =IF(J10>=Tham_so!$B$9,"Giỏi",IF(J10>=Tham_so!$B$10,"Khá",IF(J10>=Tham_so!$B$11,"Trung bình","Yếu"))) | T10: =IF(P10="","",IF(P10>=Tham_so!$B$9,"Giỏi",IF(P10>=Tham_so!$B$10,"Khá",IF(P10>=Tham_so!$B$11,"Trung bình","Yếu")))) | U10: Có
A11: 10 | B11: nganhongdang774@gmail.com | C11: Đặng Hồng Ngân | D11: Bảng A | E11: THPT Lê Quý Đôn | F11: Bình Dương | G11: Không | H11: 300 | I11: 200 | J11: =SUM(H11:I11) | K11: =COUNTIF($J$2:$J$25,">"&J11)+1 | L11: =IF(K11<=Tham_so!$B$5,"Có","Không") | P11: =IF(COUNT(M11:O11)=0,"",SUM(M11:O11)) | Q11: =IF(P11="","",COUNTIF($P$2:$P$25,">"&P11)+1) | R11: =IF(OR(J11>=Tham_so!$B$3,AND(ISNUMBER(P11),P11>=Tham_so!$B$3)),"Có","Không") | S11: =IF(J11>=Tham_so!$B$9,"Giỏi",IF(J11>=Tham_so!$B$10,"Khá",IF(J11>=Tham_so!$B$11,"Trung bình","Yếu"))) | T11: =IF(P11="","",IF(P11>=Tham_so!$B$9,"Giỏi",IF(P11>=Tham_so!$B$10,"Khá",IF(P11>=Tham_so!$B$11,"Trung bình","Yếu")))) | U11: Có
A12: 11 | B12: datanhdo191@gmail.com | C12: Đỗ Anh Đạt | D12: Bảng A | E12: THPT Lương Thế Vinh | F12: Nam Định | G12: Không | H12: 280 | I12: 200 | J12: =SUM(H12:I12) | K12: =COUNTIF($J$2:$J$25,">"&J12)+1 | L12: =IF(K12<=Tham_so!$B$5,"Có","Không") | P12: =IF(COUNT(M12:O12)=0,"",SUM(M12:O12)) | Q12: =IF(P12="","",COUNTIF($P$2:$P$25,">"&P12)+1) | R12: =IF(OR(J12>=Tham_so!$B$3,AND(ISNUMBER(P12),P12>=Tham_so!$B$3)),"Có","Không") | S12: =IF(J12>=Tham_so!$B$9,"Giỏi",IF(J12>=Tham_so!$B$10,"Khá",IF(J12>=Tham_so!$B$11,"Trung bình","Yếu"))) | T12: =IF(P12="","",IF(P12>=Tham_so!$B$9,"Giỏi",IF(P12>=Tham_so!$B$10,"Khá",IF(P12>=Tham_so!$B$11,"Trung bình","Yếu")))) | U12: Có
A13: 12 | B13: tramanhly371@gmail.com | C13: Lý Ánh Trâm | D13: Bảng A | E13: THPT Việt Đức | F13: Hải Dương | G13: Không | H13: 340 | I13: 100 | J13: =SUM(H13:I13) | K13: =COUNTIF($J$2:$J$25,">"&J13)+1 | L13: =IF(K13<=Tham_so!$B$5,"Có","Không") | P13: =IF(COUNT(M13:O13)=0,"",SUM(M13:O13)) | Q13: =IF(P13="","",COUNTIF($P$2:$P$25,">"&P13)+1) | R13: =IF(OR(J13>=Tham_so!$B$3,AND(ISNUMBER(P13),P13>=Tham_so!$B$3)),"Có","Không") | S13: =IF(J13>=Tham_so!$B$9,"Giỏi",IF(J13>=Tham_so!$B$10,"Khá",IF(J13>=Tham_so!$B$11,"Trung bình","Yếu"))) | T13: =IF(P13="","",IF(P13>=Tham_so!$B$9,"Giỏi",IF(P13>=Tham_so!$B$10,"Khá",IF(P13>=Tham_so!$B$11,"Trung bình","Yếu")))) | U13: Có
A14: 13 | B14: phongquochoang575@gmail.com | C14: Hoàng Quốc Phong | D14: Bảng A | E14: THPT Trần Hưng Đạo | F14: Bắc Ninh | G14: Không | H14: 290 | I14: 120 | J14: =SUM(H14:I14) | K14: =COUNTIF($J$2:$J$25,">"&J14)+1 | L14: =IF(K14<=Tham_so!$B$5,"Có","Không") | P14: =IF(COUNT(M14:O14)=0,"",SUM(M14:O14)) | Q14: =IF(P14="","",COUNTIF($P$2:$P$25,">"&P14)+1) | R14: =IF(OR(J14>=Tham_so!$B$3,AND(ISNUMBER(P14),P14>=Tham_so!$B$3)),"Có","Không") | S14: =IF(J14>=Tham_so!$B$9,"Giỏi",IF(J14>=Tham_so!$B$10,"Khá",IF(J14>=Tham_so!$B$11,"Trung bình","Yếu"))) | T14: =IF(P14="","",IF(P14>=Tham_so!$B$9,"Giỏi",IF(P14>=Tham_so!$B$10,"Khá",IF(P14>=Tham_so!$B$11,"Trung bình","Yếu")))) | U14: Có
A15: 14 | B15: thangcongvu515@gmail.com | C15: Vũ Công Thắng | D15: Bảng A | E15: THPT Trần Hưng Đạo | F15: TP. Hồ Chí Minh | G15: Không | H15: 300 | I15: 110 | J15: =SUM(H15:I15) | K15: =COUNTIF($J$2:$J$25,">"&J15)+1 | L15: =IF(K15<=Tham_so!$B$5,"Có","Không") | P15: =IF(COUNT(M15:O15)=0,"",SUM(M15:O15)) | Q15: =IF(P15="","",COUNTIF($P$2:$P$25,">"&P15)+1) | R15: =IF(OR(J15>=Tham_so!$B$3,AND(ISNUMBER(P15),P15>=Tham_so!$B$3)),"Có","Không") | S15: =IF(J15>=Tham_so!$B$9,"Giỏi",IF(J15>=Tham_so!$B$10,"Khá",IF(J15>=Tham_so!$B$11,"Trung bình","Yếu"))) | T15: =IF(P15="","",IF(P15>=Tham_so!$B$9,"Giỏi",IF(P15>=Tham_so!$B$10,"Khá",IF(P15>=Tham_so!$B$11,"Trung bình","Yếu")))) | U15: Có
A16: 15 | B16: phatminhtran781@gmail.com | C16: Trần Minh Phát | D16: Bảng A | E16: THPT Trần Phú | F16: Hải Dương | G16: Không | H16: 160 | I16: 140 | J16: =SUM(H16:I16) | K16: =COUNTIF($J$2:$J$25,">"&J16)+1 | L16: =IF(K16<=Tham_so!$B$5,"Có","Không") | P16: =IF(COUNT(M16:O16)=0,"",SUM(M16:O16)) | Q16: =IF(P16="","",COUNTIF($P$2:$P$25,">"&P16)+1) | R16: =IF(OR(J16>=Tham_so!$B$3,AND(ISNUMBER(P16),P16>=Tham_so!$B$3)),"Có","Không") | S16: =IF(J16>=Tham_so!$B$9,"Giỏi",IF(J16>=Tham_so!$B$10,"Khá",IF(J16>=Tham_so!$B$11,"Trung bình","Yếu"))) | T16: =IF(P16="","",IF(P16>=Tham_so!$B$9,"Giỏi",IF(P16>=Tham_so!$B$10,"Khá",IF(P16>=Tham_so!$B$11,"Trung bình","Yếu")))) | U16: Có
... A25: 24 | B25: hoangthanhphuc@icloud.com | C25: Hoàng Thanh Phúc | D25: Bảng A | E25: THPT Kim Liên | F25: Đà Nẵng | G25: Không | H25: 100 | I25: 60 | J25: =SUM(H25:I25) | K25: =COUNTIF($J$2:$J$25,">"&J25)+1 | L25: =IF(K25<=Tham_so!$B$5,"Có","Không") | P25: =IF(COUNT(M25:O25)=0,"",SUM(M25:O25)) | Q25: =IF(P25="","",COUNTIF($P$2:$P$25,">"&P25)+1) | R25: =IF(OR(J25>=Tham_so!$B$3,AND(ISNUMBER(P25),P25>=Tham_so!$B$3)),"Có","Không") | S25: =IF(J25>=Tham_so!$B$9,"Giỏi",IF(J25>=Tham_so!$B$10,"Khá",IF(J25>=Tham_so!$B$11,"Trung bình","Yếu"))) | T25: =IF(P25="","",IF(P25>=Tham_so!$B$9,"Giỏi",IF(P25>=Tham_so!$B$10,"Khá",IF(P25>=Tham_so!$B$11,"Trung bình","Yếu")))) | U25: Có

Sheet Phan_loai
A1: PHÂN LOẠI ĐIỂM — BẢNG A (dữ liệu GIẢ LẬP)
A2: Xếp loại theo tổng điểm /1000, ngưỡng lấy từ sheet Tham_so. Chung kết chỉ có vài người nên tỷ lệ % ở vòng này kém ổn định.
A5: Xếp loại | B5: Điều kiện (tổng /1000) | C5: Bảng A – Vòng loại | E5: Bảng A – Chung kết
C6: Số người | D6: % | E6: Số người | F6: %
A7: Giỏi | B7: ="≥ "&Tham_so!$B$9 | C7: =COUNTIF(Tong_hop!$S$2:$S$25,$A7) | D7: =IF(C$11=0,"",C7/C$11) | E7: =COUNTIF(Tong_hop!$T$2:$T$25,$A7) | F7: =IF(E$11=0,"",E7/E$11)
A8: Khá | B8: ="từ "&Tham_so!$B$10&" đến dưới "&Tham_so!$B$9 | C8: =COUNTIF(Tong_hop!$S$2:$S$25,$A8) | D8: =IF(C$11=0,"",C8/C$11) | E8: =COUNTIF(Tong_hop!$T$2:$T$25,$A8) | F8: =IF(E$11=0,"",E8/E$11)
A9: Trung bình | B9: ="từ "&Tham_so!$B$11&" đến dưới "&Tham_so!$B$10 | C9: =COUNTIF(Tong_hop!$S$2:$S$25,$A9) | D9: =IF(C$11=0,"",C9/C$11) | E9: =COUNTIF(Tong_hop!$T$2:$T$25,$A9) | F9: =IF(E$11=0,"",E9/E$11)
A10: Yếu | B10: ="dưới "&Tham_so!$B$11 | C10: =COUNTIF(Tong_hop!$S$2:$S$25,$A10) | D10: =IF(C$11=0,"",C10/C$11) | E10: =COUNTIF(Tong_hop!$T$2:$T$25,$A10) | F10: =IF(E$11=0,"",E10/E$11)
A11: Tổng | C11: =SUM(C7:C10) | D11: =IF(C11=0,"",SUM(D7:D10)) | E11: =SUM(E7:E10) | F11: =IF(E11=0,"",SUM(F7:F10))
A14: CHỈ SỐ TỔNG QUAN
A15: Chỉ số | C15: Bảng A – Vòng loại | E15: Bảng A – Chung kết
A16: Số thí sinh có điểm | C16: =COUNT(Tong_hop!$J$2:$J$25) | E16: =COUNT(Tong_hop!$P$2:$P$25)
A17: Điểm trung bình | C17: =IFERROR(AVERAGE(Tong_hop!$J$2:$J$25),"") | E17: =IFERROR(AVERAGE(Tong_hop!$P$2:$P$25),"")
A18: Điểm cao nhất | C18: =IF(C16=0,"",MAX(Tong_hop!$J$2:$J$25)) | E18: =IF(E16=0,"",MAX(Tong_hop!$P$2:$P$25))
A19: Điểm thấp nhất | C19: =IF(C16=0,"",MIN(Tong_hop!$J$2:$J$25)) | E19: =IF(E16=0,"",MIN(Tong_hop!$P$2:$P$25))
A20: Số người đạt ngưỡng chứng chỉ | C20: =COUNTIF(Tong_hop!$J$2:$J$25,">="&Tham_so!$B$3) | E20: =COUNTIF(Tong_hop!$P$2:$P$25,">="&Tham_so!$B$3)

Sheet Chi_tiet_diem
A1: Email | B1: Họ tên | C1: Bảng | D1: Vòng | E1: Cấp COS Pro | F1: Phần thi | G1: Điểm | H1: Điểm tối đa | I1: % điểm | J1: Dữ liệu giả lập
A2: phongthanhle754@gmail.com | B2: Lê Thành Phong | C2: Bảng A | D2: Vòng loại | E2: COS Pro Level 3 | F2: Đọc hiểu code (điền chỗ trống, Q1–Q5) | G2: =INDEX(Tong_hop!$H$2:$H$25,MATCH($A2,Tong_hop!$B$2:$B$25,0)) | H2: 500 | I2: =IF(H2=0,"",G2/H2) | J2: Có
A3: phongthanhle754@gmail.com | B3: Lê Thành Phong | C3: Bảng A | D3: Vòng loại | E3: COS Pro Level 3 | F3: Thiết kế · viết hàm (Q6–Q10) | G3: =INDEX(Tong_hop!$I$2:$I$25,MATCH($A3,Tong_hop!$B$2:$B$25,0)) | H3: 500 | I3: =IF(H3=0,"",G3/H3) | J3: Có
A4: phongthanhle754@gmail.com | B4: Lê Thành Phong | C4: Bảng A | D4: Chung kết | E4: COS Pro Level 2 | F4: Debugging | G4: =INDEX(Tong_hop!$M$2:$M$25,MATCH($A4,Tong_hop!$B$2:$B$25,0)) | H4: 280 | I4: =IF(H4=0,"",G4/H4) | J4: Có
A5: phongthanhle754@gmail.com | B5: Lê Thành Phong | C5: Bảng A | D5: Chung kết | E5: COS Pro Level 2 | F5: Design | G5: =INDEX(Tong_hop!$N$2:$N$25,MATCH($A5,Tong_hop!$B$2:$B$25,0)) | H5: 280 | I5: =IF(H5=0,"",G5/H5) | J5: Có
A6: phongthanhle754@gmail.com | B6: Lê Thành Phong | C6: Bảng A | D6: Chung kết | E6: COS Pro Level 2 | F6: Đọc hiểu code | G6: =INDEX(Tong_hop!$O$2:$O$25,MATCH($A6,Tong_hop!$B$2:$B$25,0)) | H6: 440 | I6: =IF(H6=0,"",G6/H6) | J6: Có
A7: vietducdo703@gmail.com | B7: Đỗ Đức Việt | C7: Bảng A | D7: Vòng loại | E7: COS Pro Level 3 | F7: Đọc hiểu code (điền chỗ trống, Q1–Q5) | G7: =INDEX(Tong_hop!$H$2:$H$25,MATCH($A7,Tong_hop!$B$2:$B$25,0)) | H7: 500 | I7: =IF(H7=0,"",G7/H7) | J7: Có
A8: vietducdo703@gmail.com | B8: Đỗ Đức Việt | C8: Bảng A | D8: Vòng loại | E8: COS Pro Level 3 | F8: Thiết kế · viết hàm (Q6–Q10) | G8: =INDEX(Tong_hop!$I$2:$I$25,MATCH($A8,Tong_hop!$B$2:$B$25,0)) | H8: 500 | I8: =IF(H8=0,"",G8/H8) | J8: Có
A9: vietducdo703@gmail.com | B9: Đỗ Đức Việt | C9: Bảng A | D9: Chung kết | E9: COS Pro Level 2 | F9: Debugging | G9: =INDEX(Tong_hop!$M$2:$M$25,MATCH($A9,Tong_hop!$B$2:$B$25,0)) | H9: 280 | I9: =IF(H9=0,"",G9/H9) | J9: Có
A10: vietducdo703@gmail.com | B10: Đỗ Đức Việt | C10: Bảng A | D10: Chung kết | E10: COS Pro Level 2 | F10: Design | G10: =INDEX(Tong_hop!$N$2:$N$25,MATCH($A10,Tong_hop!$B$2:$B$25,0)) | H10: 280 | I10: =IF(H10=0,"",G10/H10) | J10: Có
A11: vietducdo703@gmail.com | B11: Đỗ Đức Việt | C11: Bảng A | D11: Chung kết | E11: COS Pro Level 2 | F11: Đọc hiểu code | G11: =INDEX(Tong_hop!$O$2:$O$25,MATCH($A11,Tong_hop!$B$2:$B$25,0)) | H11: 440 | I11: =IF(H11=0,"",G11/H11) | J11: Có
A12: diepanhngo708@gmail.com | B12: Ngô Ánh Diệp | C12: Bảng A | D12: Vòng loại | E12: COS Pro Level 3 | F12: Đọc hiểu code (điền chỗ trống, Q1–Q5) | G12: =INDEX(Tong_hop!$H$2:$H$25,MATCH($A12,Tong_hop!$B$2:$B$25,0)) | H12: 500 | I12: =IF(H12=0,"",G12/H12) | J12: Có
A13: diepanhngo708@gmail.com | B13: Ngô Ánh Diệp | C13: Bảng A | D13: Vòng loại | E13: COS Pro Level 3 | F13: Thiết kế · viết hàm (Q6–Q10) | G13: =INDEX(Tong_hop!$I$2:$I$25,MATCH($A13,Tong_hop!$B$2:$B$25,0)) | H13: 500 | I13: =IF(H13=0,"",G13/H13) | J13: Có
A14: diepanhngo708@gmail.com | B14: Ngô Ánh Diệp | C14: Bảng A | D14: Chung kết | E14: COS Pro Level 2 | F14: Debugging | G14: =INDEX(Tong_hop!$M$2:$M$25,MATCH($A14,Tong_hop!$B$2:$B$25,0)) | H14: 280 | I14: =IF(H14=0,"",G14/H14) | J14: Có
A15: diepanhngo708@gmail.com | B15: Ngô Ánh Diệp | C15: Bảng A | D15: Chung kết | E15: COS Pro Level 2 | F15: Design | G15: =INDEX(Tong_hop!$N$2:$N$25,MATCH($A15,Tong_hop!$B$2:$B$25,0)) | H15: 280 | I15: =IF(H15=0,"",G15/H15) | J15: Có
A16: diepanhngo708@gmail.com | B16: Ngô Ánh Diệp | C16: Bảng A | D16: Chung kết | E16: COS Pro Level 2 | F16: Đọc hiểu code | G16: =INDEX(Tong_hop!$O$2:$O$25,MATCH($A16,Tong_hop!$B$2:$B$25,0)) | H16: 440 | I16: =IF(H16=0,"",G16/H16) | J16: Có
A17: baovandang431@gmail.com | B17: Đặng Văn Bảo | C17: Bảng A | D17: Vòng loại | E17: COS Pro Level 3 | F17: Đọc hiểu code (điền chỗ trống, Q1–Q5) | G17: =INDEX(Tong_hop!$H$2:$H$25,MATCH($A17,Tong_hop!$B$2:$B$25,0)) | H17: 500 | I17: =IF(H17=0,"",G17/H17) | J17: Có
A18: baovandang431@gmail.com | B18: Đặng Văn Bảo | C18: Bảng A | D18: Vòng loại | E18: COS Pro Level 3 | F18: Thiết kế · viết hàm (Q6–Q10) | G18: =INDEX(Tong_hop!$I$2:$I$25,MATCH($A18,Tong_hop!$B$2:$B$25,0)) | H18: 500 | I18: =IF(H18=0,"",G18/H18) | J18: Có
A19: chithanhbui743@gmail.com | B19: Bùi Thanh Chi | C19: Bảng A | D19: Vòng loại | E19: COS Pro Level 3 | F19: Đọc hiểu code (điền chỗ trống, Q1–Q5) | G19: =INDEX(Tong_hop!$H$2:$H$25,MATCH($A19,Tong_hop!$B$2:$B$25,0)) | H19: 500 | I19: =IF(H19=0,"",G19/H19) | J19: Có
A20: chithanhbui743@gmail.com | B20: Bùi Thanh Chi | C20: Bảng A | D20: Vòng loại | E20: COS Pro Level 3 | F20: Thiết kế · viết hàm (Q6–Q10) | G20: =INDEX(Tong_hop!$I$2:$I$25,MATCH($A20,Tong_hop!$B$2:$B$25,0)) | H20: 500 | I20: =IF(H20=0,"",G20/H20) | J20: Có
A21: hunganhle722@gmail.com | B21: Lê Anh Hùng | C21: Bảng A | D21: Vòng loại | E21: COS Pro Level 3 | F21: Đọc hiểu code (điền chỗ trống, Q1–Q5) | G21: =INDEX(Tong_hop!$H$2:$H$25,MATCH($A21,Tong_hop!$B$2:$B$25,0)) | H21: 500 | I21: =IF(H21=0,"",G21/H21) | J21: Có
A22: hunganhle722@gmail.com | B22: Lê Anh Hùng | C22: Bảng A | D22: Vòng loại | E22: COS Pro Level 3 | F22: Thiết kế · viết hàm (Q6–Q10) | G22: =INDEX(Tong_hop!$I$2:$I$25,MATCH($A22,Tong_hop!$B$2:$B$25,0)) | H22: 500 | I22: =IF(H22=0,"",G22/H22) | J22: Có
A23: hoangocdang962@gmail.com | B23: Đặng Ngọc Hoa | C23: Bảng A | D23: Vòng loại | E23: COS Pro Level 3 | F23: Đọc hiểu code (điền chỗ trống, Q1–Q5) | G23: =INDEX(Tong_hop!$H$2:$H$25,MATCH($A23,Tong_hop!$B$2:$B$25,0)) | H23: 500 | I23: =IF(H23=0,"",G23/H23) | J23: Có
A24: hoangocdang962@gmail.com | B24: Đặng Ngọc Hoa | C24: Bảng A | D24: Vòng loại | E24: COS Pro Level 3 | F24: Thiết kế · viết hàm (Q6–Q10) | G24: =INDEX(Tong_hop!$I$2:$I$25,MATCH($A24,Tong_hop!$B$2:$B$25,0)) | H24: 500 | I24: =IF(H24=0,"",G24/H24) | J24: Có
A25: linhdiemdang377@gmail.com | B25: Đặng Diễm Linh | C25: Bảng A | D25: Vòng loại | E25: COS Pro Level 3 | F25: Đọc hiểu code (điền chỗ trống, Q1–Q5) | G25: =INDEX(Tong_hop!$H$2:$H$25,MATCH($A25,Tong_hop!$B$2:$B$25,0)) | H25: 500 | I25: =IF(H25=0,"",G25/H25) | J25: Có
A26: linhdiemdang377@gmail.com | B26: Đặng Diễm Linh | C26: Bảng A | D26: Vòng loại | E26: COS Pro Level 3 | F26: Thiết kế · viết hàm (Q6–Q10) | G26: =INDEX(Tong_hop!$I$2:$I$25,MATCH($A26,Tong_hop!$B$2:$B$25,0)) | H26: 500 | I26: =IF(H26=0,"",G26/H26) | J26: Có
A27: linhngocdo961@gmail.com | B27: Đỗ Ngọc Linh | C27: Bảng A | D27: Vòng loại | E27: COS Pro Level 3 | F27: Đọc hiểu code (điền chỗ trống, Q1–Q5) | G27: =INDEX(Tong_hop!$H$2:$H$25,MATCH($A27,Tong_hop!$B$2:$B$25,0)) | H27: 500 | I27: =IF(H27=0,"",G27/H27) | J27: Có
A28: linhngocdo961@gmail.com | B28: Đỗ Ngọc Linh | C28: Bảng A | D28: Vòng loại | E28: COS Pro Level 3 | F28: Thiết kế · viết hàm (Q6–Q10) | G28: =INDEX(Tong_hop!$I$2:$I$25,MATCH($A28,Tong_hop!$B$2:$B$25,0)) | H28: 500 | I28: =IF(H28=0,"",G28/H28) | J28: Có
A29: nganhongdang774@gmail.com | B29: Đặng Hồng Ngân | C29: Bảng A | D29: Vòng loại | E29: COS Pro Level 3 | F29: Đọc hiểu code (điền chỗ trống, Q1–Q5) | G29: =INDEX(Tong_hop!$H$2:$H$25,MATCH($A29,Tong_hop!$B$2:$B$25,0)) | H29: 500 | I29: =IF(H29=0,"",G29/H29) | J29: Có
A30: nganhongdang774@gmail.com | B30: Đặng Hồng Ngân | C30: Bảng A | D30: Vòng loại | E30: COS Pro Level 3 | F30: Thiết kế · viết hàm (Q6–Q10) | G30: =INDEX(Tong_hop!$I$2:$I$25,MATCH($A30,Tong_hop!$B$2:$B$25,0)) | H30: 500 | I30: =IF(H30=0,"",G30/H30) | J30: Có
A31: datanhdo191@gmail.com | B31: Đỗ Anh Đạt | C31: Bảng A | D31: Vòng loại | E31: COS Pro Level 3 | F31: Đọc hiểu code (điền chỗ trống, Q1–Q5) | G31: =INDEX(Tong_hop!$H$2:$H$25,MATCH($A31,Tong_hop!$B$2:$B$25,0)) | H31: 500 | I31: =IF(H31=0,"",G31/H31) | J31: Có
A32: datanhdo191@gmail.com | B32: Đỗ Anh Đạt | C32: Bảng A | D32: Vòng loại | E32: COS Pro Level 3 | F32: Thiết kế · viết hàm (Q6–Q10) | G32: =INDEX(Tong_hop!$I$2:$I$25,MATCH($A32,Tong_hop!$B$2:$B$25,0)) | H32: 500 | I32: =IF(H32=0,"",G32/H32) | J32: Có
A33: tramanhly371@gmail.com | B33: Lý Ánh Trâm | C33: Bảng A | D33: Vòng loại | E33: COS Pro Level 3 | F33: Đọc hiểu code (điền chỗ trống, Q1–Q5) | G33: =INDEX(Tong_hop!$H$2:$H$25,MATCH($A33,Tong_hop!$B$2:$B$25,0)) | H33: 500 | I33: =IF(H33=0,"",G33/H33) | J33: Có
A34: tramanhly371@gmail.com | B34: Lý Ánh Trâm | C34: Bảng A | D34: Vòng loại | E34: COS Pro Level 3 | F34: Thiết kế · viết hàm (Q6–Q10) | G34: =INDEX(Tong_hop!$I$2:$I$25,MATCH($A34,Tong_hop!$B$2:$B$25,0)) | H34: 500 | I34: =IF(H34=0,"",G34/H34) | J34: Có
A35: phongquochoang575@gmail.com | B35: Hoàng Quốc Phong | C35: Bảng A | D35: Vòng loại | E35: COS Pro Level 3 | F35: Đọc hiểu code (điền chỗ trống, Q1–Q5) | G35: =INDEX(Tong_hop!$H$2:$H$25,MATCH($A35,Tong_hop!$B$2:$B$25,0)) | H35: 500 | I35: =IF(H35=0,"",G35/H35) | J35: Có
A36: phongquochoang575@gmail.com | B36: Hoàng Quốc Phong | C36: Bảng A | D36: Vòng loại | E36: COS Pro Level 3 | F36: Thiết kế · viết hàm (Q6–Q10) | G36: =INDEX(Tong_hop!$I$2:$I$25,MATCH($A36,Tong_hop!$B$2:$B$25,0)) | H36: 500 | I36: =IF(H36=0,"",G36/H36) | J36: Có
A37: thangcongvu515@gmail.com | B37: Vũ Công Thắng | C37: Bảng A | D37: Vòng loại | E37: COS Pro Level 3 | F37: Đọc hiểu code (điền chỗ trống, Q1–Q5) | G37: =INDEX(Tong_hop!$H$2:$H$25,MATCH($A37,Tong_hop!$B$2:$B$25,0)) | H37: 500 | I37: =IF(H37=0,"",G37/H37) | J37: Có
A38: thangcongvu515@gmail.com | B38: Vũ Công Thắng | C38: Bảng A | D38: Vòng loại | E38: COS Pro Level 3 | F38: Thiết kế · viết hàm (Q6–Q10) | G38: =INDEX(Tong_hop!$I$2:$I$25,MATCH($A38,Tong_hop!$B$2:$B$25,0)) | H38: 500 | I38: =IF(H38=0,"",G38/H38) | J38: Có
A39: phatminhtran781@gmail.com | B39: Trần Minh Phát | C39: Bảng A | D39: Vòng loại | E39: COS Pro Level 3 | F39: Đọc hiểu code (điền chỗ trống, Q1–Q5) | G39: =INDEX(Tong_hop!$H$2:$H$25,MATCH($A39,Tong_hop!$B$2:$B$25,0)) | H39: 500 | I39: =IF(H39=0,"",G39/H39) | J39: Có
A40: phatminhtran781@gmail.com | B40: Trần Minh Phát | C40: Bảng A | D40: Vòng loại | E40: COS Pro Level 3 | F40: Thiết kế · viết hàm (Q6–Q10) | G40: =INDEX(Tong_hop!$I$2:$I$25,MATCH($A40,Tong_hop!$B$2:$B$25,0)) | H40: 500 | I40: =IF(H40=0,"",G40/H40) | J40: Có
...

Sheet Cau_truc_de
A1: CẤU TRÚC ĐỀ THI — BẢNG A
A2: Nguồn: https://pythonmaster.vn/#exam_structure (mục 'Cấu trúc thi'), đọc ngày 20/09/2026. Mỗi vòng 10 câu, thang 1.000 điểm.
A4: Vòng | B4: Cấp COS Pro | C4: Phần thi | D4: Câu | E4: Điểm tối đa
A5: Vòng loại | B5: COS Pro Level 3 | C5: Đọc hiểu code (điền chỗ trống) | D5: Q1–Q5 | E5: 500
A6: Vòng loại | B6: COS Pro Level 3 | C6: Thiết kế · viết hàm | D6: Q6–Q10 | E6: 500
A7: Chung kết | B7: COS Pro Level 2 | C7: Debugging | E7: 280
A8: Chung kết | B8: COS Pro Level 2 | C8: Design | E8: 280
A9: Chung kết | B9: COS Pro Level 2 | C9: Đọc hiểu code | E9: 440
A11: Kiểm tra tổng điểm từng vòng
A12: Vòng loại | E12: =SUMIFS($E$5:$E$9,$A$5:$A$9,A12)
A13: Chung kết | E13: =SUMIFS($E$5:$E$9,$A$5:$A$9,A13)

Sheet Tham_so
A1: THAM SỐ — BẢNG A (sửa ô xanh dương, các ô còn lại tự tính)
A3: Ngưỡng nhận chứng chỉ COS Pro (/1000, ở bất kỳ vòng nào) | B3: 600 | C3: Nguồn: pythonmaster.vn/#exam_structure — 'đạt ≥600/1000 điểm ở bất kỳ vòng nào'
A4: Tỷ lệ Top vào chung kết | B4: 0.1 | C4: Nguồn: pythonmaster.vn — 'Top 10% vượt qua vòng loại sẽ tham gia vòng chung kết' (làm tròn LÊN)
A5: Số người vào chung kết — Bảng A | B5: =ROUNDUP(ROUND(COUNTA(Tong_hop!$B$2:$B$25)*$B$4,6),0) | C5: Số thí sinh của bảng × tỷ lệ Top, làm tròn lên
A8: XẾP LOẠI THEO TỔNG ĐIỂM (/1000) — ngưỡng 800 và 400 là giả định, sửa được
A9: Giỏi khi tổng điểm ≥ | B9: 800
A10: Khá khi tổng điểm ≥ (mặc định bằng ngưỡng chứng chỉ) | B10: =$B$3
A11: Trung bình khi tổng điểm ≥ | B11: 400
A12: Yếu: tổng điểm dưới ngưỡng Trung bình

Sheet Ghi_chu
A1: GHI CHÚ — BẢNG A — ĐỌC TRƯỚC KHI DÙNG
A3: DỮ LIỆU GIẢ LẬP | B3: Toàn bộ điểm trong file là số ngẫu nhiên do mô hình sinh ra, KHÔNG phải kết quả thật của thí sinh. Không dùng để công bố, xếp hạng hay đánh giá từng cá nhân.
A4: Hai file | B4: Đây là file của Bảng A (24 người). File của bảng còn lại có cùng cấu trúc và cùng cách sinh điểm.
A5: Nguồn cấu trúc | B5: Cấu trúc đề, thang 1.000 điểm, tỷ lệ Top 10% vào chung kết và ngưỡng 600 điểm lấy từ pythonmaster.vn/#exam_structure (xem sheet Cau_truc_de). Cuộc thi thật: Vòng loại từ 20/09/2026, Chung kết 10/10/2026 nên chưa có điểm thật.
A6: Danh sách thí sinh | B6: 24 người thuộc Bảng A. Có 4 người đã thanh toán; cột 'Đã thanh toán' cho phép lọc riêng nhóm này.
A7: Cách sinh điểm | B7: Mỗi thí sinh có 1 'năng lực ẩn' (phân phối chuẩn, seed = 2028). Điểm từng phần = tỷ lệ theo năng lực + nhiễu, làm tròn bước 10 điểm, không vượt điểm tối đa của phần. Phần Design/Thiết kế khó nhất, Đọc hiểu code dễ nhất. Năng lực ở Chung kết tương quan 0,75 với Vòng loại; đề Chung kết khó hơn (COS Pro Level 3 → Level 2).
A8: Quy tắc vào chung kết | B8: Top 10% theo tổng điểm Vòng loại, làm tròn lên: 3 người. Chỉ những người này có điểm Chung kết. Tổng, hạng, cột 'Vượt vòng loại', 'Chứng chỉ' và xếp loại là công thức, tự cập nhật khi đổi tham số (sheet Tham_so) hoặc điểm.
A9: Xếp loại | B9: Giỏi ≥ 800, Khá ≥ 600 (bằng ngưỡng chứng chỉ trên web), Trung bình ≥ 400, Yếu < 400, tính theo tổng điểm /1000. Ngưỡng 800 và 400 là giả định vì thể lệ không quy định xếp loại; sửa ở sheet Tham_so. Chung kết dùng chung ngưỡng dù đề khó hơn.
A10: Đồng hạng | B10: Hạng tính kiểu thi đấu (đồng điểm cùng hạng).
A11: Thay bằng điểm thật | B11: Ghi đè các ô nền đỏ nhạt ở các cột điểm phần (VL – …, CK – …) trong sheet Tong_hop. Sheet Chi_tiet_diem tự lấy điểm theo email nên vẫn đúng khi bạn sắp xếp lại Tong_hop. Nếu đổi điểm Vòng loại làm thay đổi người vào chung kết, cần nhập điểm Chung kết cho người mới.
A12: Quy ước màu | B12: Chữ xanh dương = số nhập tay · chữ đen = công thức · chữ xanh lá = lấy từ sheet khác · ô nền đỏ nhạt = dữ liệu giả lập · ô nền xanh nhạt = 'Có'.
