Workbook

Sheet Bao_cao_tong_quan
B1: BÁO CÁO ĐIỂM THI TỔNG QUAN — PYTHON MASTER
B3: =IF(COUNTIF(Tong_hop!$X$2:$X$120,"Có")>0,"⚠ DỮ LIỆU GIẢ LẬP — điểm là số ngẫu nhiên, không phải kết quả thật; không dùng để công bố, xếp hạng hay đánh giá cá nhân (xem sheet Ghi_chu).","") -> ⚠ DỮ LIỆU GIẢ LẬP — điểm là số ngẫu nhiên, không phải kết quả thật; không dùng để công bố, xếp hạng hay đánh giá cá nhân (xem sheet Ghi_chu).
B4: Đơn vị sử dụng báo cáo: | C4: (Điền tên đơn vị / bộ phận sử dụng báo cáo tại đây)
B5: Ngày lập báo cáo: | C5: =TODAY() -> 46293
B6: Ô nền vàng, chữ xanh dương = nhập tay · chữ đen = công thức · chữ xanh lá = lấy từ sheet khác.
B8: 1. CHỈ SỐ TỔNG QUAN
B9: TỔNG SỐ THÍ SINH | C9: BẢNG A | E9: BẢNG B | G9: ĐÃ THANH TOÁN
B10: =COUNTA(Tong_hop!$C$2:$C$120) -> 119 | C10: =COUNTIF(Tong_hop!$D$2:$D$120,"Bảng A") -> 24 | E10: =COUNTIF(Tong_hop!$D$2:$D$120,"Bảng B") -> 95 | G10: =COUNTIF(Tong_hop!$G$2:$G$120,"Có") -> 66
B11: Bảng A + Bảng B | C11: =IF($B$10=0,"",C10/$B$10) -> 0.20168067 | E11: =IF($B$10=0,"",E10/$B$10) -> 0.79831933 | G11: =IF($B$10=0,"",G10/$B$10) -> 0.55462185
B13: VÀO CHUNG KẾT | C13: ĐẠT NGƯỠNG CHỨNG CHỈ | E13: ĐIỂM TB VÒNG LOẠI | G13: ĐIỂM CAO NHẤT VÒNG LOẠI
B14: =COUNTIF(Tong_hop!$N$2:$N$120,"Có") -> 15 | C14: =COUNTIF(Tong_hop!$U$2:$U$120,"Có") -> 35 | E14: =AVERAGE(Tong_hop!$L$2:$L$120) -> 527.47899 | G14: =MAX(Tong_hop!$L$2:$L$120) -> 850
B15: ="Top "&TEXT(Tham_so!$B$4,"0%")&" mỗi bảng" -> Top 10% mỗi bảng | C15: =IF($B$10=0,"",C14/$B$10) -> 0.29411765 | E15: thang 1.000 điểm | G15: thang 1.000 điểm
B17: 2. KẾT QUẢ THEO BẢNG THI VÀ VÒNG THI
B18: Chỉ số | C18: Bảng A – Vòng loại | D18: Bảng A – Chung kết | E18: Bảng B – Vòng loại | F18: Bảng B – Chung kết | G18: Toàn bộ – Vòng loại
B19: Số thí sinh có điểm | C19: =COUNTIFS(Tong_hop!$D$2:$D$120,"Bảng A",Tong_hop!$L$2:$L$120,">=0") -> 24 | D19: =COUNTIFS(Tong_hop!$D$2:$D$120,"Bảng A",Tong_hop!$S$2:$S$120,">=0") -> 3 | E19: =COUNTIFS(Tong_hop!$D$2:$D$120,"Bảng B",Tong_hop!$L$2:$L$120,">=0") -> 95 | F19: =COUNTIFS(Tong_hop!$D$2:$D$120,"Bảng B",Tong_hop!$S$2:$S$120,">=0") -> 10 | G19: =COUNTIF(Tong_hop!$L$2:$L$120,">=0") -> 119
B20: Điểm trung bình | C20: =IFERROR(AVERAGEIFS(Tong_hop!$L$2:$L$120,Tong_hop!$D$2:$D$120,"Bảng A"),"") -> 472.5 | D20: =IFERROR(AVERAGEIFS(Tong_hop!$S$2:$S$120,Tong_hop!$D$2:$D$120,"Bảng A"),"") -> 756.66667 | E20: =IFERROR(AVERAGEIFS(Tong_hop!$L$2:$L$120,Tong_hop!$D$2:$D$120,"Bảng B"),"") -> 541.36842 | F20: =IFERROR(AVERAGEIFS(Tong_hop!$S$2:$S$120,Tong_hop!$D$2:$D$120,"Bảng B"),"") -> 936 | G20: =IFERROR(AVERAGE(Tong_hop!$L$2:$L$120),"") -> 527.47899
B21: Điểm cao nhất | C21: =IF(C19=0,"",_xlfn.MAXIFS(Tong_hop!$L$2:$L$120,Tong_hop!$D$2:$D$120,"Bảng A")) -> 670 | D21: =IF(D19=0,"",_xlfn.MAXIFS(Tong_hop!$S$2:$S$120,Tong_hop!$D$2:$D$120,"Bảng A")) -> 780 | E21: =IF(E19=0,"",_xlfn.MAXIFS(Tong_hop!$L$2:$L$120,Tong_hop!$D$2:$D$120,"Bảng B")) -> 850 | F21: =IF(F19=0,"",_xlfn.MAXIFS(Tong_hop!$S$2:$S$120,Tong_hop!$D$2:$D$120,"Bảng B")) -> 990 | G21: =IF(G19=0,"",MAX(Tong_hop!$L$2:$L$120)) -> 850
B22: Điểm thấp nhất | C22: =IF(C19=0,"",_xlfn.MINIFS(Tong_hop!$L$2:$L$120,Tong_hop!$D$2:$D$120,"Bảng A")) -> 260 | D22: =IF(D19=0,"",_xlfn.MINIFS(Tong_hop!$S$2:$S$120,Tong_hop!$D$2:$D$120,"Bảng A")) -> 720 | E22: =IF(E19=0,"",_xlfn.MINIFS(Tong_hop!$L$2:$L$120,Tong_hop!$D$2:$D$120,"Bảng B")) -> 170 | F22: =IF(F19=0,"",_xlfn.MINIFS(Tong_hop!$S$2:$S$120,Tong_hop!$D$2:$D$120,"Bảng B")) -> 860 | G22: =IF(G19=0,"",MIN(Tong_hop!$L$2:$L$120)) -> 170
B23: ="Số người đạt ≥ "&Tham_so!$B$3&" điểm" -> Số người đạt ≥ 600 điểm | C23: =COUNTIFS(Tong_hop!$D$2:$D$120,"Bảng A",Tong_hop!$L$2:$L$120,">="&Tham_so!$B$3) -> 4 | D23: =COUNTIFS(Tong_hop!$D$2:$D$120,"Bảng A",Tong_hop!$S$2:$S$120,">="&Tham_so!$B$3) -> 3 | E23: =COUNTIFS(Tong_hop!$D$2:$D$120,"Bảng B",Tong_hop!$L$2:$L$120,">="&Tham_so!$B$3) -> 31 | F23: =COUNTIFS(Tong_hop!$D$2:$D$120,"Bảng B",Tong_hop!$S$2:$S$120,">="&Tham_so!$B$3) -> 10 | G23: =COUNTIF(Tong_hop!$L$2:$L$120,">="&Tham_so!$B$3) -> 35
B24: Tỉ lệ đạt ngưỡng chứng chỉ | C24: =IF(C19=0,"",C23/C19) -> 0.16666667 | D24: =IF(D19=0,"",D23/D19) -> 1 | E24: =IF(E19=0,"",E23/E19) -> 0.32631579 | F24: =IF(F19=0,"",F23/F19) -> 1 | G24: =IF(G19=0,"",G23/G19) -> 0.29411765
B25: ="Chung kết chỉ có "&(D19+F19)&" thí sinh (Top "&TEXT(Tham_so!$B$4,"0%")&" mỗi bảng) nên số liệu Chung kết kém ổn định. Đề Chung kết khó hơn Vòng loại (Bảng A lên COS Pro Level 2, Bảng B lên Level 1)." -> Chung kết chỉ có 13 thí sinh (Top 10% mỗi bảng) nên số liệu Chung kết kém ổn định. Đề Chung kết khó hơn Vòng loại (Bảng A lên COS Pro Level 2, Bảng B lên Level 1).
B27: 3. ĐIỂM TRUNG BÌNH THEO PHẦN THI (% điểm tối đa của phần)
B28: Phần thi | C28: Bảng A – Vòng loại | D28: Bảng A – Chung kết | E28: Bảng B – Vòng loại | F28: Bảng B – Chung kết
B29: Đọc hiểu code | C29: =IFERROR(AVERAGEIFS(Tong_hop!$I$2:$I$120,Tong_hop!$D$2:$D$120,"Bảng A")/Cau_truc_de!$F$5,"–") -> 0.53583333 | D29: =IFERROR(AVERAGEIFS(Tong_hop!$P$2:$P$120,Tong_hop!$D$2:$D$120,"Bảng A")/Cau_truc_de!$F$9,"–") -> 0.78030303 | E29: =IFERROR(AVERAGEIFS(Tong_hop!$I$2:$I$120,Tong_hop!$D$2:$D$120,"Bảng B")/Cau_truc_de!$F$12,"–") -> 0.59976077 | F29: =IFERROR(AVERAGEIFS(Tong_hop!$P$2:$P$120,Tong_hop!$D$2:$D$120,"Bảng B")/Cau_truc_de!$F$15,"–") -> 0.99705882
B30: Design (thiết kế · viết hàm) | C30: =IFERROR(AVERAGEIFS(Tong_hop!$J$2:$J$120,Tong_hop!$D$2:$D$120,"Bảng A")/Cau_truc_de!$F$6,"–") -> 0.40916667 | D30: =IFERROR(AVERAGEIFS(Tong_hop!$Q$2:$Q$120,Tong_hop!$D$2:$D$120,"Bảng A")/Cau_truc_de!$F$8,"–") -> 0.63095238 | E30: =IFERROR(AVERAGEIFS(Tong_hop!$J$2:$J$120,Tong_hop!$D$2:$D$120,"Bảng B")/Cau_truc_de!$F$11,"–") -> 0.45827068 | F30: =IFERROR(AVERAGEIFS(Tong_hop!$Q$2:$Q$120,Tong_hop!$D$2:$D$120,"Bảng B")/Cau_truc_de!$F$14,"–") -> 0.87142857
B31: Debugging | C31: – | D31: =IFERROR(AVERAGEIFS(Tong_hop!$R$2:$R$120,Tong_hop!$D$2:$D$120,"Bảng A")/Cau_truc_de!$F$7,"–") -> 0.8452381 | E31: =IFERROR(AVERAGEIFS(Tong_hop!$K$2:$K$120,Tong_hop!$D$2:$D$120,"Bảng B")/Cau_truc_de!$F$10,"–") -> 0.53270677 | F31: =IFERROR(AVERAGEIFS(Tong_hop!$R$2:$R$120,Tong_hop!$D$2:$D$120,"Bảng B")/Cau_truc_de!$F$13,"–") -> 0.9625
B32: Phần thi có tỉ lệ điểm thấp nhất | C32: =IFERROR(INDEX($B$29:$B$31,MATCH(MIN(C29:C31),C29:C31,0)),"") -> Design (thiết kế · viết hàm) | D32: =IFERROR(INDEX($B$29:$B$31,MATCH(MIN(D29:D31),D29:D31,0)),"") -> Design (thiết kế · viết hàm) | E32: =IFERROR(INDEX($B$29:$B$31,MATCH(MIN(E29:E31),E29:E31,0)),"") -> Design (thiết kế · viết hàm) | F32: =IFERROR(INDEX($B$29:$B$31,MATCH(MIN(F29:F31),F29:F31,0)),"") -> Design (thiết kế · viết hàm)
B33: Điểm trung bình của phần thi ÷ điểm tối đa của phần đó. Bảng A – Vòng loại chỉ có 2 phần thi, không có Debugging.
B35: 4. PHÂN LOẠI THÍ SINH VÒNG LOẠI THEO TỔNG ĐIỂM
B36: Xếp loại | C36: Bảng A (người) | D36: Bảng A (%) | E36: Bảng B (người) | F36: Bảng B (%) | G36: Điều kiện (tổng /1000)
B37: Giỏi | C37: =Phan_loai!C6 -> Số người | D37: =Phan_loai!D6 -> % | E37: =Phan_loai!G6 -> Số người | F37: =Phan_loai!H6 -> % | G37: =Phan_loai!B6 -> 0
B38: Khá | C38: =Phan_loai!C7 -> 0 | D38: =Phan_loai!D7 -> 0 | E38: =Phan_loai!G7 -> 4 | F38: =Phan_loai!H7 -> 0.042105263 | G38: =Phan_loai!B7 -> ≥ 800
B39: Trung bình | C39: =Phan_loai!C8 -> 4 | D39: =Phan_loai!D8 -> 0.16666667 | E39: =Phan_loai!G8 -> 27 | F39: =Phan_loai!H8 -> 0.28421053 | G39: =Phan_loai!B8 -> từ 600 đến dưới 800
B40: Yếu | C40: =Phan_loai!C9 -> 14 | D40: =Phan_loai!D9 -> 0.58333333 | E40: =Phan_loai!G9 -> 49 | F40: =Phan_loai!H9 -> 0.51578947 | G40: =Phan_loai!B9 -> từ 400 đến dưới 600
B41: Tổng | C41: =SUM(C37:C40) -> 18 | D41: =IF(C41=0,"",SUM(D37:D40)) -> 0.75 | E41: =SUM(E37:E40) -> 80 | F41: =IF(E41=0,"",SUM(F37:F40)) -> 0.84210526
B44: 5. PHÂN BỐ TỔNG ĐIỂM VÒNG LOẠI (thang 1.000)
B45: Khoảng điểm | C45: Từ | D45: Đến (không gồm) | E45: Bảng A | F45: Bảng B | G45: Tổng
B46: =C46&" – "&IF(D46>1000,1000,D46-1) -> 0 – 99 | C46: 0 | D46: 100 | E46: =COUNTIFS(Tong_hop!$D$2:$D$120,"Bảng A",Tong_hop!$L$2:$L$120,">="&$C46,Tong_hop!$L$2:$L$120,"<"&$D46) -> 0 | F46: =COUNTIFS(Tong_hop!$D$2:$D$120,"Bảng B",Tong_hop!$L$2:$L$120,">="&$C46,Tong_hop!$L$2:$L$120,"<"&$D46) -> 0 | G46: =E46+F46 -> 0
B47: =C47&" – "&IF(D47>1000,1000,D47-1) -> 100 – 199 | C47: 100 | D47: 200 | E47: =COUNTIFS(Tong_hop!$D$2:$D$120,"Bảng A",Tong_hop!$L$2:$L$120,">="&$C47,Tong_hop!$L$2:$L$120,"<"&$D47) -> 0 | F47: =COUNTIFS(Tong_hop!$D$2:$D$120,"Bảng B",Tong_hop!$L$2:$L$120,">="&$C47,Tong_hop!$L$2:$L$120,"<"&$D47) -> 1 | G47: =E47+F47 -> 1
B48: =C48&" – "&IF(D48>1000,1000,D48-1) -> 200 – 299 | C48: 200 | D48: 300 | E48: =COUNTIFS(Tong_hop!$D$2:$D$120,"Bảng A",Tong_hop!$L$2:$L$120,">="&$C48,Tong_hop!$L$2:$L$120,"<"&$D48) -> 3 | F48: =COUNTIFS(Tong_hop!$D$2:$D$120,"Bảng B",Tong_hop!$L$2:$L$120,">="&$C48,Tong_hop!$L$2:$L$120,"<"&$D48) -> 5 | G48: =E48+F48 -> 8
...

Sheet Tong_hop
A1: STT | B1: Email | C1: Họ tên | D1: Bảng | E1: Trường | F1: Tỉnh/TP | G1: Đã thanh toán | H1: VL – Cấp COS Pro | I1: VL – Đọc hiểu code | J1: VL – Design (thiết kế · viết hàm) | K1: VL – Debugging | L1: VL – Tổng (/1000) | M1: VL – Hạng trong bảng | N1: Vượt vòng loại (Top 10%) | O1: CK – Cấp COS Pro | P1: CK – Đọc hiểu code | Q1: CK – Design | R1: CK – Debugging | S1: CK – Tổng (/1000) | T1: CK – Hạng trong bảng | U1: Chứng chỉ COS Pro (≥600) | V1: VL – Xếp loại | W1: CK – Xếp loại | X1: Dữ liệu giả lập
A2: 1 | B2: namduong001@ptit.edu.vn | C2: Dương Hoài Nam | D2: Bảng A | E2: THPT Nguyễn Huệ | F2: Hà Nội | G2: Có | H2: =IF(D2="Bảng A","COS Pro Level 3","COS Pro Level 2") -> COS Pro Level 3 | I2: 290 | J2: 250 | L2: =SUM(I2:K2) -> 540 | M2: =COUNTIFS($D$2:$D$120,D2,$L$2:$L$120,">"&L2)+1 -> 8 | N2: =IF(M2<=IF(D2="Bảng A",Tham_so!$B$5,Tham_so!$B$6),"Có","Không") -> Không | O2: =IF(COUNT(P2:R2)=0,"",IF(D2="Bảng A","COS Pro Level 2","COS Pro Level 1")) | S2: =IF(COUNT(P2:R2)=0,"",SUM(P2:R2)) | T2: =IF(S2="","",COUNTIFS($D$2:$D$120,D2,$S$2:$S$120,">"&S2)+1) | U2: =IF(OR(L2>=Tham_so!$B$3,AND(ISNUMBER(S2),S2>=Tham_so!$B$3)),"Có","Không") -> Không | V2: =IF(L2>=Tham_so!$B$9,"Giỏi",IF(L2>=Tham_so!$B$10,"Khá",IF(L2>=Tham_so!$B$11,"Trung bình","Yếu"))) -> Trung bình | W2: =IF(S2="","",IF(S2>=Tham_so!$B$9,"Giỏi",IF(S2>=Tham_so!$B$10,"Khá",IF(S2>=Tham_so!$B$11,"Trung bình","Yếu")))) | X2: Có
A3: 2 | B3: sonmai002@ptit.edu.vn | C3: Mai Minh Sơn | D3: Bảng A | E3: THPT Chu Văn An | F3: Bắc Ninh | G3: Có | H3: =IF(D3="Bảng A","COS Pro Level 3","COS Pro Level 2") -> COS Pro Level 3 | I3: 370 | J3: 230 | L3: =SUM(I3:K3) -> 600 | M3: =COUNTIFS($D$2:$D$120,D3,$L$2:$L$120,">"&L3)+1 -> 3 | N3: =IF(M3<=IF(D3="Bảng A",Tham_so!$B$5,Tham_so!$B$6),"Có","Không") -> Có | O3: =IF(COUNT(P3:R3)=0,"",IF(D3="Bảng A","COS Pro Level 2","COS Pro Level 1")) -> COS Pro Level 2 | P3: 320 | Q3: 180 | R3: 220 | S3: =IF(COUNT(P3:R3)=0,"",SUM(P3:R3)) -> 720 | T3: =IF(S3="","",COUNTIFS($D$2:$D$120,D3,$S$2:$S$120,">"&S3)+1) -> 3 | U3: =IF(OR(L3>=Tham_so!$B$3,AND(ISNUMBER(S3),S3>=Tham_so!$B$3)),"Có","Không") -> Có | V3: =IF(L3>=Tham_so!$B$9,"Giỏi",IF(L3>=Tham_so!$B$10,"Khá",IF(L3>=Tham_so!$B$11,"Trung bình","Yếu"))) -> Khá | W3: =IF(S3="","",IF(S3>=Tham_so!$B$9,"Giỏi",IF(S3>=Tham_so!$B$10,"Khá",IF(S3>=Tham_so!$B$11,"Trung bình","Yếu")))) -> Khá | X3: Có
A4: 3 | B4: giangpham003@ptit.edu.vn | C4: Phạm Hoài Giang | D4: Bảng A | E4: THPT Lê Quý Đôn | F4: Khánh Hòa | G4: Có | H4: =IF(D4="Bảng A","COS Pro Level 3","COS Pro Level 2") -> COS Pro Level 3 | I4: 400 | J4: 270 | L4: =SUM(I4:K4) -> 670 | M4: =COUNTIFS($D$2:$D$120,D4,$L$2:$L$120,">"&L4)+1 -> 1 | N4: =IF(M4<=IF(D4="Bảng A",Tham_so!$B$5,Tham_so!$B$6),"Có","Không") -> Có | O4: =IF(COUNT(P4:R4)=0,"",IF(D4="Bảng A","COS Pro Level 2","COS Pro Level 1")) -> COS Pro Level 2 | P4: 360 | Q4: 190 | R4: 230 | S4: =IF(COUNT(P4:R4)=0,"",SUM(P4:R4)) -> 780 | T4: =IF(S4="","",COUNTIFS($D$2:$D$120,D4,$S$2:$S$120,">"&S4)+1) -> 1 | U4: =IF(OR(L4>=Tham_so!$B$3,AND(ISNUMBER(S4),S4>=Tham_so!$B$3)),"Có","Không") -> Có | V4: =IF(L4>=Tham_so!$B$9,"Giỏi",IF(L4>=Tham_so!$B$10,"Khá",IF(L4>=Tham_so!$B$11,"Trung bình","Yếu"))) -> Khá | W4: =IF(S4="","",IF(S4>=Tham_so!$B$9,"Giỏi",IF(S4>=Tham_so!$B$10,"Khá",IF(S4>=Tham_so!$B$11,"Trung bình","Yếu")))) -> Khá | X4: Có
A5: 4 | B5: vyho004@ptit.edu.vn | C5: Hồ Hữu Vy | D5: Bảng A | E5: THPT Việt Đức | F5: TP. Hồ Chí Minh | G5: Có | H5: =IF(D5="Bảng A","COS Pro Level 3","COS Pro Level 2") -> COS Pro Level 3 | I5: 350 | J5: 210 | L5: =SUM(I5:K5) -> 560 | M5: =COUNTIFS($D$2:$D$120,D5,$L$2:$L$120,">"&L5)+1 -> 6 | N5: =IF(M5<=IF(D5="Bảng A",Tham_so!$B$5,Tham_so!$B$6),"Có","Không") -> Không | O5: =IF(COUNT(P5:R5)=0,"",IF(D5="Bảng A","COS Pro Level 2","COS Pro Level 1")) | S5: =IF(COUNT(P5:R5)=0,"",SUM(P5:R5)) | T5: =IF(S5="","",COUNTIFS($D$2:$D$120,D5,$S$2:$S$120,">"&S5)+1) | U5: =IF(OR(L5>=Tham_so!$B$3,AND(ISNUMBER(S5),S5>=Tham_so!$B$3)),"Có","Không") -> Không | V5: =IF(L5>=Tham_so!$B$9,"Giỏi",IF(L5>=Tham_so!$B$10,"Khá",IF(L5>=Tham_so!$B$11,"Trung bình","Yếu"))) -> Trung bình | W5: =IF(S5="","",IF(S5>=Tham_so!$B$9,"Giỏi",IF(S5>=Tham_so!$B$10,"Khá",IF(S5>=Tham_so!$B$11,"Trung bình","Yếu")))) | X5: Có
A6: 5 | B6: phucvo005@ptit.edu.vn | C6: Võ Phương Phúc | D6: Bảng A | E6: THPT Kim Liên | F6: Nam Định | G6: Có | H6: =IF(D6="Bảng A","COS Pro Level 3","COS Pro Level 2") -> COS Pro Level 3 | I6: 130 | J6: 130 | L6: =SUM(I6:K6) -> 260 | M6: =COUNTIFS($D$2:$D$120,D6,$L$2:$L$120,">"&L6)+1 -> 24 | N6: =IF(M6<=IF(D6="Bảng A",Tham_so!$B$5,Tham_so!$B$6),"Có","Không") -> Không | O6: =IF(COUNT(P6:R6)=0,"",IF(D6="Bảng A","COS Pro Level 2","COS Pro Level 1")) | S6: =IF(COUNT(P6:R6)=0,"",SUM(P6:R6)) | T6: =IF(S6="","",COUNTIFS($D$2:$D$120,D6,$S$2:$S$120,">"&S6)+1) | U6: =IF(OR(L6>=Tham_so!$B$3,AND(ISNUMBER(S6),S6>=Tham_so!$B$3)),"Có","Không") -> Không | V6: =IF(L6>=Tham_so!$B$9,"Giỏi",IF(L6>=Tham_so!$B$10,"Khá",IF(L6>=Tham_so!$B$11,"Trung bình","Yếu"))) -> Yếu | W6: =IF(S6="","",IF(S6>=Tham_so!$B$9,"Giỏi",IF(S6>=Tham_so!$B$10,"Khá",IF(S6>=Tham_so!$B$11,"Trung bình","Yếu")))) | X6: Có
A7: 6 | B7: hoapham006@ptit.edu.vn | C7: Phạm Khánh Hoa | D7: Bảng A | E7: THPT Nguyễn Huệ | F7: Hà Tĩnh | G7: Có | H7: =IF(D7="Bảng A","COS Pro Level 3","COS Pro Level 2") -> COS Pro Level 3 | I7: 280 | J7: 280 | L7: =SUM(I7:K7) -> 560 | M7: =COUNTIFS($D$2:$D$120,D7,$L$2:$L$120,">"&L7)+1 -> 6 | N7: =IF(M7<=IF(D7="Bảng A",Tham_so!$B$5,Tham_so!$B$6),"Có","Không") -> Không | O7: =IF(COUNT(P7:R7)=0,"",IF(D7="Bảng A","COS Pro Level 2","COS Pro Level 1")) | S7: =IF(COUNT(P7:R7)=0,"",SUM(P7:R7)) | T7: =IF(S7="","",COUNTIFS($D$2:$D$120,D7,$S$2:$S$120,">"&S7)+1) | U7: =IF(OR(L7>=Tham_so!$B$3,AND(ISNUMBER(S7),S7>=Tham_so!$B$3)),"Có","Không") -> Không | V7: =IF(L7>=Tham_so!$B$9,"Giỏi",IF(L7>=Tham_so!$B$10,"Khá",IF(L7>=Tham_so!$B$11,"Trung bình","Yếu"))) -> Trung bình | W7: =IF(S7="","",IF(S7>=Tham_so!$B$9,"Giỏi",IF(S7>=Tham_so!$B$10,"Khá",IF(S7>=Tham_so!$B$11,"Trung bình","Yếu")))) | X7: Có
A8: 7 | B8: yenlam007@ptit.edu.vn | C8: Lâm Hoài Yến | D8: Bảng A | E8: THPT Chu Văn An | F8: Hải Phòng | G8: Có | H8: =IF(D8="Bảng A","COS Pro Level 3","COS Pro Level 2") -> COS Pro Level 3 | I8: 340 | J8: 190 | L8: =SUM(I8:K8) -> 530 | M8: =COUNTIFS($D$2:$D$120,D8,$L$2:$L$120,">"&L8)+1 -> 9 | N8: =IF(M8<=IF(D8="Bảng A",Tham_so!$B$5,Tham_so!$B$6),"Có","Không") -> Không | O8: =IF(COUNT(P8:R8)=0,"",IF(D8="Bảng A","COS Pro Level 2","COS Pro Level 1")) | S8: =IF(COUNT(P8:R8)=0,"",SUM(P8:R8)) | T8: =IF(S8="","",COUNTIFS($D$2:$D$120,D8,$S$2:$S$120,">"&S8)+1) | U8: =IF(OR(L8>=Tham_so!$B$3,AND(ISNUMBER(S8),S8>=Tham_so!$B$3)),"Có","Không") -> Không | V8: =IF(L8>=Tham_so!$B$9,"Giỏi",IF(L8>=Tham_so!$B$10,"Khá",IF(L8>=Tham_so!$B$11,"Trung bình","Yếu"))) -> Trung bình | W8: =IF(S8="","",IF(S8>=Tham_so!$B$9,"Giỏi",IF(S8>=Tham_so!$B$10,"Khá",IF(S8>=Tham_so!$B$11,"Trung bình","Yếu")))) | X8: Có
A9: 8 | B9: giangtrinh008@ptit.edu.vn | C9: Trịnh Thị Giang | D9: Bảng A | E9: THPT Lê Quý Đôn | F9: Thái Nguyên | G9: Có | H9: =IF(D9="Bảng A","COS Pro Level 3","COS Pro Level 2") -> COS Pro Level 3 | I9: 300 | J9: 300 | L9: =SUM(I9:K9) -> 600 | M9: =COUNTIFS($D$2:$D$120,D9,$L$2:$L$120,">"&L9)+1 -> 3 | N9: =IF(M9<=IF(D9="Bảng A",Tham_so!$B$5,Tham_so!$B$6),"Có","Không") -> Có | O9: =IF(COUNT(P9:R9)=0,"",IF(D9="Bảng A","COS Pro Level 2","COS Pro Level 1")) | S9: =IF(COUNT(P9:R9)=0,"",SUM(P9:R9)) | T9: =IF(S9="","",COUNTIFS($D$2:$D$120,D9,$S$2:$S$120,">"&S9)+1) | U9: =IF(OR(L9>=Tham_so!$B$3,AND(ISNUMBER(S9),S9>=Tham_so!$B$3)),"Có","Không") -> Có | V9: =IF(L9>=Tham_so!$B$9,"Giỏi",IF(L9>=Tham_so!$B$10,"Khá",IF(L9>=Tham_so!$B$11,"Trung bình","Yếu"))) -> Khá | W9: =IF(S9="","",IF(S9>=Tham_so!$B$9,"Giỏi",IF(S9>=Tham_so!$B$10,"Khá",IF(S9>=Tham_so!$B$11,"Trung bình","Yếu")))) | X9: Có
A10: 9 | B10: yenhoang009@ptit.edu.vn | C10: Hoàng Anh Yến | D10: Bảng A | E10: THPT Việt Đức | F10: Vĩnh Phúc | G10: Có | H10: =IF(D10="Bảng A","COS Pro Level 3","COS Pro Level 2") -> COS Pro Level 3 | I10: 270 | J10: 210 | L10: =SUM(I10:K10) -> 480 | M10: =COUNTIFS($D$2:$D$120,D10,$L$2:$L$120,">"&L10)+1 -> 15 | N10: =IF(M10<=IF(D10="Bảng A",Tham_so!$B$5,Tham_so!$B$6),"Có","Không") -> Không | O10: =IF(COUNT(P10:R10)=0,"",IF(D10="Bảng A","COS Pro Level 2","COS Pro Level 1")) | S10: =IF(COUNT(P10:R10)=0,"",SUM(P10:R10)) | T10: =IF(S10="","",COUNTIFS($D$2:$D$120,D10,$S$2:$S$120,">"&S10)+1) | U10: =IF(OR(L10>=Tham_so!$B$3,AND(ISNUMBER(S10),S10>=Tham_so!$B$3)),"Có","Không") -> Không | V10: =IF(L10>=Tham_so!$B$9,"Giỏi",IF(L10>=Tham_so!$B$10,"Khá",IF(L10>=Tham_so!$B$11,"Trung bình","Yếu"))) -> Trung bình | W10: =IF(S10="","",IF(S10>=Tham_so!$B$9,"Giỏi",IF(S10>=Tham_so!$B$10,"Khá",IF(S10>=Tham_so!$B$11,"Trung bình","Yếu")))) | X10: Có
A11: 10 | B11: cuongtran010@ptit.edu.vn | C11: Trần Thanh Cường | D11: Bảng A | E11: THPT Kim Liên | F11: Đà Nẵng | G11: Có | H11: =IF(D11="Bảng A","COS Pro Level 3","COS Pro Level 2") -> COS Pro Level 3 | I11: 190 | J11: 220 | L11: =SUM(I11:K11) -> 410 | M11: =COUNTIFS($D$2:$D$120,D11,$L$2:$L$120,">"&L11)+1 -> 17 | N11: =IF(M11<=IF(D11="Bảng A",Tham_so!$B$5,Tham_so!$B$6),"Có","Không") -> Không | O11: =IF(COUNT(P11:R11)=0,"",IF(D11="Bảng A","COS Pro Level 2","COS Pro Level 1")) | S11: =IF(COUNT(P11:R11)=0,"",SUM(P11:R11)) | T11: =IF(S11="","",COUNTIFS($D$2:$D$120,D11,$S$2:$S$120,">"&S11)+1) | U11: =IF(OR(L11>=Tham_so!$B$3,AND(ISNUMBER(S11),S11>=Tham_so!$B$3)),"Có","Không") -> Không | V11: =IF(L11>=Tham_so!$B$9,"Giỏi",IF(L11>=Tham_so!$B$10,"Khá",IF(L11>=Tham_so!$B$11,"Trung bình","Yếu"))) -> Trung bình | W11: =IF(S11="","",IF(S11>=Tham_so!$B$9,"Giỏi",IF(S11>=Tham_so!$B$10,"Khá",IF(S11>=Tham_so!$B$11,"Trung bình","Yếu")))) | X11: Có
A12: 11 | B12: dungdang011@ptit.edu.vn | C12: Đặng Thu Dũng | D12: Bảng A | E12: THPT Nguyễn Huệ | F12: Quảng Ninh | G12: Có | H12: =IF(D12="Bảng A","COS Pro Level 3","COS Pro Level 2") -> COS Pro Level 3 | I12: 250 | J12: 70 | L12: =SUM(I12:K12) -> 320 | M12: =COUNTIFS($D$2:$D$120,D12,$L$2:$L$120,">"&L12)+1 -> 20 | N12: =IF(M12<=IF(D12="Bảng A",Tham_so!$B$5,Tham_so!$B$6),"Có","Không") -> Không | O12: =IF(COUNT(P12:R12)=0,"",IF(D12="Bảng A","COS Pro Level 2","COS Pro Level 1")) | S12: =IF(COUNT(P12:R12)=0,"",SUM(P12:R12)) | T12: =IF(S12="","",COUNTIFS($D$2:$D$120,D12,$S$2:$S$120,">"&S12)+1) | U12: =IF(OR(L12>=Tham_so!$B$3,AND(ISNUMBER(S12),S12>=Tham_so!$B$3)),"Có","Không") -> Không | V12: =IF(L12>=Tham_so!$B$9,"Giỏi",IF(L12>=Tham_so!$B$10,"Khá",IF(L12>=Tham_so!$B$11,"Trung bình","Yếu"))) -> Yếu | W12: =IF(S12="","",IF(S12>=Tham_so!$B$9,"Giỏi",IF(S12>=Tham_so!$B$10,"Khá",IF(S12>=Tham_so!$B$11,"Trung bình","Yếu")))) | X12: Có
A13: 12 | B13: phongphan012@ptit.edu.vn | C13: Phan Xuân Phong | D13: Bảng A | E13: THPT Chu Văn An | F13: Phú Thọ | G13: Có | H13: =IF(D13="Bảng A","COS Pro Level 3","COS Pro Level 2") -> COS Pro Level 3 | I13: 270 | J13: 220 | L13: =SUM(I13:K13) -> 490 | M13: =COUNTIFS($D$2:$D$120,D13,$L$2:$L$120,">"&L13)+1 -> 13 | N13: =IF(M13<=IF(D13="Bảng A",Tham_so!$B$5,Tham_so!$B$6),"Có","Không") -> Không | O13: =IF(COUNT(P13:R13)=0,"",IF(D13="Bảng A","COS Pro Level 2","COS Pro Level 1")) | S13: =IF(COUNT(P13:R13)=0,"",SUM(P13:R13)) | T13: =IF(S13="","",COUNTIFS($D$2:$D$120,D13,$S$2:$S$120,">"&S13)+1) | U13: =IF(OR(L13>=Tham_so!$B$3,AND(ISNUMBER(S13),S13>=Tham_so!$B$3)),"Có","Không") -> Không | V13: =IF(L13>=Tham_so!$B$9,"Giỏi",IF(L13>=Tham_so!$B$10,"Khá",IF(L13>=Tham_so!$B$11,"Trung bình","Yếu"))) -> Trung bình | W13: =IF(S13="","",IF(S13>=Tham_so!$B$9,"Giỏi",IF(S13>=Tham_so!$B$10,"Khá",IF(S13>=Tham_so!$B$11,"Trung bình","Yếu")))) | X13: Có
A14: 13 | B14: phongpham013@ptit.edu.vn | C14: Phạm Thu Phong | D14: Bảng A | E14: THPT Lê Quý Đôn | F14: Nghệ An | G14: Có | H14: =IF(D14="Bảng A","COS Pro Level 3","COS Pro Level 2") -> COS Pro Level 3 | I14: 220 | J14: 180 | L14: =SUM(I14:K14) -> 400 | M14: =COUNTIFS($D$2:$D$120,D14,$L$2:$L$120,">"&L14)+1 -> 18 | N14: =IF(M14<=IF(D14="Bảng A",Tham_so!$B$5,Tham_so!$B$6),"Có","Không") -> Không | O14: =IF(COUNT(P14:R14)=0,"",IF(D14="Bảng A","COS Pro Level 2","COS Pro Level 1")) | S14: =IF(COUNT(P14:R14)=0,"",SUM(P14:R14)) | T14: =IF(S14="","",COUNTIFS($D$2:$D$120,D14,$S$2:$S$120,">"&S14)+1) | U14: =IF(OR(L14>=Tham_so!$B$3,AND(ISNUMBER(S14),S14>=Tham_so!$B$3)),"Có","Không") -> Không | V14: =IF(L14>=Tham_so!$B$9,"Giỏi",IF(L14>=Tham_so!$B$10,"Khá",IF(L14>=Tham_so!$B$11,"Trung bình","Yếu"))) -> Trung bình | W14: =IF(S14="","",IF(S14>=Tham_so!$B$9,"Giỏi",IF(S14>=Tham_so!$B$10,"Khá",IF(S14>=Tham_so!$B$11,"Trung bình","Yếu")))) | X14: Có
A15: 14 | B15: vinhbui014@ptit.edu.vn | C15: Bùi Khánh Vinh | D15: Bảng A | E15: THPT Việt Đức | F15: Lâm Đồng | G15: Có | H15: =IF(D15="Bảng A","COS Pro Level 3","COS Pro Level 2") -> COS Pro Level 3 | I15: 250 | J15: 280 | L15: =SUM(I15:K15) -> 530 | M15: =COUNTIFS($D$2:$D$120,D15,$L$2:$L$120,">"&L15)+1 -> 9 | N15: =IF(M15<=IF(D15="Bảng A",Tham_so!$B$5,Tham_so!$B$6),"Có","Không") -> Không | O15: =IF(COUNT(P15:R15)=0,"",IF(D15="Bảng A","COS Pro Level 2","COS Pro Level 1")) | S15: =IF(COUNT(P15:R15)=0,"",SUM(P15:R15)) | T15: =IF(S15="","",COUNTIFS($D$2:$D$120,D15,$S$2:$S$120,">"&S15)+1) | U15: =IF(OR(L15>=Tham_so!$B$3,AND(ISNUMBER(S15),S15>=Tham_so!$B$3)),"Có","Không") -> Không | V15: =IF(L15>=Tham_so!$B$9,"Giỏi",IF(L15>=Tham_so!$B$10,"Khá",IF(L15>=Tham_so!$B$11,"Trung bình","Yếu"))) -> Trung bình | W15: =IF(S15="","",IF(S15>=Tham_so!$B$9,"Giỏi",IF(S15>=Tham_so!$B$10,"Khá",IF(S15>=Tham_so!$B$11,"Trung bình","Yếu")))) | X15: Có
A16: 15 | B16: lanlam015@ptit.edu.vn | C16: Lâm Thị Lan | D16: Bảng A | E16: THPT Kim Liên | F16: Huế | G16: Có | H16: =IF(D16="Bảng A","COS Pro Level 3","COS Pro Level 2") -> COS Pro Level 3 | I16: 430 | J16: 220 | L16: =SUM(I16:K16) -> 650 | M16: =COUNTIFS($D$2:$D$120,D16,$L$2:$L$120,">"&L16)+1 -> 2 | N16: =IF(M16<=IF(D16="Bảng A",Tham_so!$B$5,Tham_so!$B$6),"Có","Không") -> Có | O16: =IF(COUNT(P16:R16)=0,"",IF(D16="Bảng A","COS Pro Level 2","COS Pro Level 1")) -> COS Pro Level 2 | P16: 350 | Q16: 160 | R16: 260 | S16: =IF(COUNT(P16:R16)=0,"",SUM(P16:R16)) -> 770 | T16: =IF(S16="","",COUNTIFS($D$2:$D$120,D16,$S$2:$S$120,">"&S16)+1) -> 2 | U16: =IF(OR(L16>=Tham_so!$B$3,AND(ISNUMBER(S16),S16>=Tham_so!$B$3)),"Có","Không") -> Có | V16: =IF(L16>=Tham_so!$B$9,"Giỏi",IF(L16>=Tham_so!$B$10,"Khá",IF(L16>=Tham_so!$B$11,"Trung bình","Yếu"))) -> Khá | W16: =IF(S16="","",IF(S16>=Tham_so!$B$9,"Giỏi",IF(S16>=Tham_so!$B$10,"Khá",IF(S16>=Tham_so!$B$11,"Trung bình","Yếu")))) -> Khá | X16: Có
A17: 16 | B17: vyle016@ptit.edu.vn | C17: Lê Hải Vy | D17: Bảng A | E17: THPT Nguyễn Huệ | F17: Thanh Hóa | G17: Có | H17: =IF(D17="Bảng A","COS Pro Level 3","COS Pro Level 2") -> COS Pro Level 3 | I17: 290 | J17: 210 | L17: =SUM(I17:K17) -> 500 | M17: =COUNTIFS($D$2:$D$120,D17,$L$2:$L$120,">"&L17)+1 -> 12 | N17: =IF(M17<=IF(D17="Bảng A",Tham_so!$B$5,Tham_so!$B$6),"Có","Không") -> Không | O17: =IF(COUNT(P17:R17)=0,"",IF(D17="Bảng A","COS Pro Level 2","COS Pro Level 1")) | S17: =IF(COUNT(P17:R17)=0,"",SUM(P17:R17)) | T17: =IF(S17="","",COUNTIFS($D$2:$D$120,D17,$S$2:$S$120,">"&S17)+1) | U17: =IF(OR(L17>=Tham_so!$B$3,AND(ISNUMBER(S17),S17>=Tham_so!$B$3)),"Có","Không") -> Không | V17: =IF(L17>=Tham_so!$B$9,"Giỏi",IF(L17>=Tham_so!$B$10,"Khá",IF(L17>=Tham_so!$B$11,"Trung bình","Yếu"))) -> Trung bình | W17: =IF(S17="","",IF(S17>=Tham_so!$B$9,"Giỏi",IF(S17>=Tham_so!$B$10,"Khá",IF(S17>=Tham_so!$B$11,"Trung bình","Yếu")))) | X17: Có
A18: 17 | B18: giangdang017@ptit.edu.vn | C18: Đặng Xuân Giang | D18: Bảng A | E18: THPT Chu Văn An | F18: Đồng Nai | G18: Có | H18: =IF(D18="Bảng A","COS Pro Level 3","COS Pro Level 2") -> COS Pro Level 3 | I18: 240 | J18: 250 | L18: =SUM(I18:K18) -> 490 | M18: =COUNTIFS($D$2:$D$120,D18,$L$2:$L$120,">"&L18)+1 -> 13 | N18: =IF(M18<=IF(D18="Bảng A",Tham_so!$B$5,Tham_so!$B$6),"Có","Không") -> Không | O18: =IF(COUNT(P18:R18)=0,"",IF(D18="Bảng A","COS Pro Level 2","COS Pro Level 1")) | S18: =IF(COUNT(P18:R18)=0,"",SUM(P18:R18)) | T18: =IF(S18="","",COUNTIFS($D$2:$D$120,D18,$S$2:$S$120,">"&S18)+1) | U18: =IF(OR(L18>=Tham_so!$B$3,AND(ISNUMBER(S18),S18>=Tham_so!$B$3)),"Có","Không") -> Không | V18: =IF(L18>=Tham_so!$B$9,"Giỏi",IF(L18>=Tham_so!$B$10,"Khá",IF(L18>=Tham_so!$B$11,"Trung bình","Yếu"))) -> Trung bình | W18: =IF(S18="","",IF(S18>=Tham_so!$B$9,"Giỏi",IF(S18>=Tham_so!$B$10,"Khá",IF(S18>=Tham_so!$B$11,"Trung bình","Yếu")))) | X18: Có
A19: 18 | B19: trangbui018@ptit.edu.vn | C19: Bùi Thị Trang | D19: Bảng A | E19: THPT Lê Quý Đôn | F19: Cần Thơ | G19: Có | H19: =IF(D19="Bảng A","COS Pro Level 3","COS Pro Level 2") -> COS Pro Level 3 | I19: 310 | J19: 200 | L19: =SUM(I19:K19) -> 510 | M19: =COUNTIFS($D$2:$D$120,D19,$L$2:$L$120,">"&L19)+1 -> 11 | N19: =IF(M19<=IF(D19="Bảng A",Tham_so!$B$5,Tham_so!$B$6),"Có","Không") -> Không | O19: =IF(COUNT(P19:R19)=0,"",IF(D19="Bảng A","COS Pro Level 2","COS Pro Level 1")) | S19: =IF(COUNT(P19:R19)=0,"",SUM(P19:R19)) | T19: =IF(S19="","",COUNTIFS($D$2:$D$120,D19,$S$2:$S$120,">"&S19)+1) | U19: =IF(OR(L19>=Tham_so!$B$3,AND(ISNUMBER(S19),S19>=Tham_so!$B$3)),"Có","Không") -> Không | V19: =IF(L19>=Tham_so!$B$9,"Giỏi",IF(L19>=Tham_so!$B$10,"Khá",IF(L19>=Tham_so!$B$11,"Trung bình","Yếu"))) -> Trung bình | W19: =IF(S19="","",IF(S19>=Tham_so!$B$9,"Giỏi",IF(S19>=Tham_so!$B$10,"Khá",IF(S19>=Tham_so!$B$11,"Trung bình","Yếu")))) | X19: Có
A20: 19 | B20: trangta019@ptit.edu.vn | C20: Tạ Thị Trang | D20: Bảng A | E20: THPT Việt Đức | F20: Hải Dương | G20: Có | H20: =IF(D20="Bảng A","COS Pro Level 3","COS Pro Level 2") -> COS Pro Level 3 | I20: 220 | J20: 130 | L20: =SUM(I20:K20) -> 350 | M20: =COUNTIFS($D$2:$D$120,D20,$L$2:$L$120,">"&L20)+1 -> 19 | N20: =IF(M20<=IF(D20="Bảng A",Tham_so!$B$5,Tham_so!$B$6),"Có","Không") -> Không | O20: =IF(COUNT(P20:R20)=0,"",IF(D20="Bảng A","COS Pro Level 2","COS Pro Level 1")) | S20: =IF(COUNT(P20:R20)=0,"",SUM(P20:R20)) | T20: =IF(S20="","",COUNTIFS($D$2:$D$120,D20,$S$2:$S$120,">"&S20)+1) | U20: =IF(OR(L20>=Tham_so!$B$3,AND(ISNUMBER(S20),S20>=Tham_so!$B$3)),"Có","Không") -> Không | V20: =IF(L20>=Tham_so!$B$9,"Giỏi",IF(L20>=Tham_so!$B$10,"Khá",IF(L20>=Tham_so!$B$11,"Trung bình","Yếu"))) -> Yếu | W20: =IF(S20="","",IF(S20>=Tham_so!$B$9,"Giỏi",IF(S20>=Tham_so!$B$10,"Khá",IF(S20>=Tham_so!$B$11,"Trung bình","Yếu")))) | X20: Có
A21: 20 | B21: haimai020@ptit.edu.vn | C21: Mai Gia Hải | D21: Bảng A | E21: THPT Kim Liên | F21: Bình Dương | G21: Có | H21: =IF(D21="Bảng A","COS Pro Level 3","COS Pro Level 2") -> COS Pro Level 3 | I21: 180 | J21: 90 | L21: =SUM(I21:K21) -> 270 | M21: =COUNTIFS($D$2:$D$120,D21,$L$2:$L$120,">"&L21)+1 -> 23 | N21: =IF(M21<=IF(D21="Bảng A",Tham_so!$B$5,Tham_so!$B$6),"Có","Không") -> Không | O21: =IF(COUNT(P21:R21)=0,"",IF(D21="Bảng A","COS Pro Level 2","COS Pro Level 1")) | S21: =IF(COUNT(P21:R21)=0,"",SUM(P21:R21)) | T21: =IF(S21="","",COUNTIFS($D$2:$D$120,D21,$S$2:$S$120,">"&S21)+1) | U21: =IF(OR(L21>=Tham_so!$B$3,AND(ISNUMBER(S21),S21>=Tham_so!$B$3)),"Có","Không") -> Không | V21: =IF(L21>=Tham_so!$B$9,"Giỏi",IF(L21>=Tham_so!$B$10,"Khá",IF(L21>=Tham_so!$B$11,"Trung bình","Yếu"))) -> Yếu | W21: =IF(S21="","",IF(S21>=Tham_so!$B$9,"Giỏi",IF(S21>=Tham_so!$B$10,"Khá",IF(S21>=Tham_so!$B$11,"Trung bình","Yếu")))) | X21: Có
A22: 21 | B22: binhhoang021@ptit.edu.vn | C22: Hoàng Hữu Bình | D22: Bảng A | E22: THPT Nguyễn Huệ | F22: Hà Nội | G22: Có | H22: =IF(D22="Bảng A","COS Pro Level 3","COS Pro Level 2") -> COS Pro Level 3 | I22: 280 | J22: 310 | L22: =SUM(I22:K22) -> 590 | M22: =COUNTIFS($D$2:$D$120,D22,$L$2:$L$120,">"&L22)+1 -> 5 | N22: =IF(M22<=IF(D22="Bảng A",Tham_so!$B$5,Tham_so!$B$6),"Có","Không") -> Không | O22: =IF(COUNT(P22:R22)=0,"",IF(D22="Bảng A","COS Pro Level 2","COS Pro Level 1")) | S22: =IF(COUNT(P22:R22)=0,"",SUM(P22:R22)) | T22: =IF(S22="","",COUNTIFS($D$2:$D$120,D22,$S$2:$S$120,">"&S22)+1) | U22: =IF(OR(L22>=Tham_so!$B$3,AND(ISNUMBER(S22),S22>=Tham_so!$B$3)),"Có","Không") -> Không | V22: =IF(L22>=Tham_so!$B$9,"Giỏi",IF(L22>=Tham_so!$B$10,"Khá",IF(L22>=Tham_so!$B$11,"Trung bình","Yếu"))) -> Trung bình | W22: =IF(S22="","",IF(S22>=Tham_so!$B$9,"Giỏi",IF(S22>=Tham_so!$B$10,"Khá",IF(S22>=Tham_so!$B$11,"Trung bình","Yếu")))) | X22: Có
A23: 22 | B23: hieumai022@ptit.edu.vn | C23: Mai Hải Hiếu | D23: Bảng A | E23: THPT Chu Văn An | F23: Bắc Ninh | G23: Có | H23: =IF(D23="Bảng A","COS Pro Level 3","COS Pro Level 2") -> COS Pro Level 3 | I23: 250 | J23: 200 | L23: =SUM(I23:K23) -> 450 | M23: =COUNTIFS($D$2:$D$120,D23,$L$2:$L$120,">"&L23)+1 -> 16 | N23: =IF(M23<=IF(D23="Bảng A",Tham_so!$B$5,Tham_so!$B$6),"Có","Không") -> Không | O23: =IF(COUNT(P23:R23)=0,"",IF(D23="Bảng A","COS Pro Level 2","COS Pro Level 1")) | S23: =IF(COUNT(P23:R23)=0,"",SUM(P23:R23)) | T23: =IF(S23="","",COUNTIFS($D$2:$D$120,D23,$S$2:$S$120,">"&S23)+1) | U23: =IF(OR(L23>=Tham_so!$B$3,AND(ISNUMBER(S23),S23>=Tham_so!$B$3)),"Có","Không") -> Không | V23: =IF(L23>=Tham_so!$B$9,"Giỏi",IF(L23>=Tham_so!$B$10,"Khá",IF(L23>=Tham_so!$B$11,"Trung bình","Yếu"))) -> Trung bình | W23: =IF(S23="","",IF(S23>=Tham_so!$B$9,"Giỏi",IF(S23>=Tham_so!$B$10,"Khá",IF(S23>=Tham_so!$B$11,"Trung bình","Yếu")))) | X23: Có
A24: 23 | B24: nganphan023@ptit.edu.vn | C24: Phan Anh Ngân | D24: Bảng A | E24: THPT Lê Quý Đôn | F24: Khánh Hòa | G24: Có | H24: =IF(D24="Bảng A","COS Pro Level 3","COS Pro Level 2") -> COS Pro Level 3 | I24: 170 | J24: 130 | L24: =SUM(I24:K24) -> 300 | M24: =COUNTIFS($D$2:$D$120,D24,$L$2:$L$120,">"&L24)+1 -> 21 | N24: =IF(M24<=IF(D24="Bảng A",Tham_so!$B$5,Tham_so!$B$6),"Có","Không") -> Không | O24: =IF(COUNT(P24:R24)=0,"",IF(D24="Bảng A","COS Pro Level 2","COS Pro Level 1")) | S24: =IF(COUNT(P24:R24)=0,"",SUM(P24:R24)) | T24: =IF(S24="","",COUNTIFS($D$2:$D$120,D24,$S$2:$S$120,">"&S24)+1) | U24: =IF(OR(L24>=Tham_so!$B$3,AND(ISNUMBER(S24),S24>=Tham_so!$B$3)),"Có","Không") -> Không | V24: =IF(L24>=Tham_so!$B$9,"Giỏi",IF(L24>=Tham_so!$B$10,"Khá",IF(L24>=Tham_so!$B$11,"Trung bình","Yếu"))) -> Yếu | W24: =IF(S24="","",IF(S24>=Tham_so!$B$9,"Giỏi",IF(S24>=Tham_so!$B$10,"Khá",IF(S24>=Tham_so!$B$11,"Trung bình","Yếu")))) | X24: Có
A25: 24 | B25: nhiduong024@ptit.edu.vn | C25: Dương Hữu Nhi | D25: Bảng A | E25: THPT Việt Đức | F25: TP. Hồ Chí Minh | G25: Có | H25: =IF(D25="Bảng A","COS Pro Level 3","COS Pro Level 2") -> COS Pro Level 3 | I25: 150 | J25: 130 | L25: =SUM(I25:K25) -> 280 | M25: =COUNTIFS($D$2:$D$120,D25,$L$2:$L$120,">"&L25)+1 -> 22 | N25: =IF(M25<=IF(D25="Bảng A",Tham_so!$B$5,Tham_so!$B$6),"Có","Không") -> Không | O25: =IF(COUNT(P25:R25)=0,"",IF(D25="Bảng A","COS Pro Level 2","COS Pro Level 1")) | S25: =IF(COUNT(P25:R25)=0,"",SUM(P25:R25)) | T25: =IF(S25="","",COUNTIFS($D$2:$D$120,D25,$S$2:$S$120,">"&S25)+1) | U25: =IF(OR(L25>=Tham_so!$B$3,AND(ISNUMBER(S25),S25>=Tham_so!$B$3)),"Có","Không") -> Không | V25: =IF(L25>=Tham_so!$B$9,"Giỏi",IF(L25>=Tham_so!$B$10,"Khá",IF(L25>=Tham_so!$B$11,"Trung bình","Yếu"))) -> Yếu | W25: =IF(S25="","",IF(S25>=Tham_so!$B$9,"Giỏi",IF(S25>=Tham_so!$B$10,"Khá",IF(S25>=Tham_so!$B$11,"Trung bình","Yếu")))) | X25: Có
A26: 25 | B26: duyvu025@ptit.edu.vn | C26: Vũ Anh Duy | D26: Bảng B | E26: Đại học FPT | F26: Nam Định | G26: Có | H26: =IF(D26="Bảng A","COS Pro Level 3","COS Pro Level 2") -> COS Pro Level 2 | I26: 290 | J26: 180 | K26: 210 | L26: =SUM(I26:K26) -> 680 | M26: =COUNTIFS($D$2:$D$120,D26,$L$2:$L$120,">"&L26)+1 -> 19 | N26: =IF(M26<=IF(D26="Bảng A",Tham_so!$B$5,Tham_so!$B$6),"Có","Không") -> Không | O26: =IF(COUNT(P26:R26)=0,"",IF(D26="Bảng A","COS Pro Level 2","COS Pro Level 1")) | S26: =IF(COUNT(P26:R26)=0,"",SUM(P26:R26)) | T26: =IF(S26="","",COUNTIFS($D$2:$D$120,D26,$S$2:$S$120,">"&S26)+1) | U26: =IF(OR(L26>=Tham_so!$B$3,AND(ISNUMBER(S26),S26>=Tham_so!$B$3)),"Có","Không") -> Có | V26: =IF(L26>=Tham_so!$B$9,"Giỏi",IF(L26>=Tham_so!$B$10,"Khá",IF(L26>=Tham_so!$B$11,"Trung bình","Yếu"))) -> Khá | W26: =IF(S26="","",IF(S26>=Tham_so!$B$9,"Giỏi",IF(S26>=Tham_so!$B$10,"Khá",IF(S26>=Tham_so!$B$11,"Trung bình","Yếu")))) | X26: Có
A27: 26 | B27: namngo026@ptit.edu.vn | C27: Ngô Minh Nam | D27: Bảng B | E27: Đại học Bách Khoa TP.HCM | F27: Hà Tĩnh | G27: Có | H27: =IF(D27="Bảng A","COS Pro Level 3","COS Pro Level 2") -> COS Pro Level 2 | I27: 270 | J27: 130 | K27: 130 | L27: =SUM(I27:K27) -> 530 | M27: =COUNTIFS($D$2:$D$120,D27,$L$2:$L$120,">"&L27)+1 -> 50 | N27: =IF(M27<=IF(D27="Bảng A",Tham_so!$B$5,Tham_so!$B$6),"Có","Không") -> Không | O27: =IF(COUNT(P27:R27)=0,"",IF(D27="Bảng A","COS Pro Level 2","COS Pro Level 1")) | S27: =IF(COUNT(P27:R27)=0,"",SUM(P27:R27)) | T27: =IF(S27="","",COUNTIFS($D$2:$D$120,D27,$S$2:$S$120,">"&S27)+1) | U27: =IF(OR(L27>=Tham_so!$B$3,AND(ISNUMBER(S27),S27>=Tham_so!$B$3)),"Có","Không") -> Không | V27: =IF(L27>=Tham_so!$B$9,"Giỏi",IF(L27>=Tham_so!$B$10,"Khá",IF(L27>=Tham_so!$B$11,"Trung bình","Yếu"))) -> Trung bình | W27: =IF(S27="","",IF(S27>=Tham_so!$B$9,"Giỏi",IF(S27>=Tham_so!$B$10,"Khá",IF(S27>=Tham_so!$B$11,"Trung bình","Yếu")))) | X27: Có
A28: 27 | B28: hungtrinh027@ptit.edu.vn | C28: Trịnh Ngọc Hùng | D28: Bảng B | E28: Đại học Khoa học Tự nhiên TP.HCM | F28: Hải Phòng | G28: Có | H28: =IF(D28="Bảng A","COS Pro Level 3","COS Pro Level 2") -> COS Pro Level 2 | I28: 260 | J28: 140 | K28: 150 | L28: =SUM(I28:K28) -> 550 | M28: =COUNTIFS($D$2:$D$120,D28,$L$2:$L$120,">"&L28)+1 -> 43 | N28: =IF(M28<=IF(D28="Bảng A",Tham_so!$B$5,Tham_so!$B$6),"Có","Không") -> Không | O28: =IF(COUNT(P28:R28)=0,"",IF(D28="Bảng A","COS Pro Level 2","COS Pro Level 1")) | S28: =IF(COUNT(P28:R28)=0,"",SUM(P28:R28)) | T28: =IF(S28="","",COUNTIFS($D$2:$D$120,D28,$S$2:$S$120,">"&S28)+1) | U28: =IF(OR(L28>=Tham_so!$B$3,AND(ISNUMBER(S28),S28>=Tham_so!$B$3)),"Có","Không") -> Không | V28: =IF(L28>=Tham_so!$B$9,"Giỏi",IF(L28>=Tham_so!$B$10,"Khá",IF(L28>=Tham_so!$B$11,"Trung bình","Yếu"))) -> Trung bình | W28: =IF(S28="","",IF(S28>=Tham_so!$B$9,"Giỏi",IF(S28>=Tham_so!$B$10,"Khá",IF(S28>=Tham_so!$B$11,"Trung bình","Yếu")))) | X28: Có
A29: 28 | B29: huyphan028@ptit.edu.vn | C29: Phan Thu Huy | D29: Bảng B | E29: Đại học CNTT - ĐHQG TP.HCM | F29: Thái Nguyên | G29: Có | H29: =IF(D29="Bảng A","COS Pro Level 3","COS Pro Level 2") -> COS Pro Level 2 | I29: 240 | J29: 160 | K29: 150 | L29: =SUM(I29:K29) -> 550 | M29: =COUNTIFS($D$2:$D$120,D29,$L$2:$L$120,">"&L29)+1 -> 43 | N29: =IF(M29<=IF(D29="Bảng A",Tham_so!$B$5,Tham_so!$B$6),"Có","Không") -> Không | O29: =IF(COUNT(P29:R29)=0,"",IF(D29="Bảng A","COS Pro Level 2","COS Pro Level 1")) | S29: =IF(COUNT(P29:R29)=0,"",SUM(P29:R29)) | T29: =IF(S29="","",COUNTIFS($D$2:$D$120,D29,$S$2:$S$120,">"&S29)+1) | U29: =IF(OR(L29>=Tham_so!$B$3,AND(ISNUMBER(S29),S29>=Tham_so!$B$3)),"Có","Không") -> Không | V29: =IF(L29>=Tham_so!$B$9,"Giỏi",IF(L29>=Tham_so!$B$10,"Khá",IF(L29>=Tham_so!$B$11,"Trung bình","Yếu"))) -> Trung bình | W29: =IF(S29="","",IF(S29>=Tham_so!$B$9,"Giỏi",IF(S29>=Tham_so!$B$10,"Khá",IF(S29>=Tham_so!$B$11,"Trung bình","Yếu")))) | X29: Có
A30: 29 | B30: toanngo029@ptit.edu.vn | C30: Ngô Ngọc Toàn | D30: Bảng B | E30: Đại học Sư phạm Kỹ thuật TP.HCM | F30: Vĩnh Phúc | G30: Có | H30: =IF(D30="Bảng A","COS Pro Level 3","COS Pro Level 2") -> COS Pro Level 2 | I30: 290 | J30: 220 | K30: 190 | L30: =SUM(I30:K30) -> 700 | M30: =COUNTIFS($D$2:$D$120,D30,$L$2:$L$120,">"&L30)+1 -> 14 | N30: =IF(M30<=IF(D30="Bảng A",Tham_so!$B$5,Tham_so!$B$6),"Có","Không") -> Không | O30: =IF(COUNT(P30:R30)=0,"",IF(D30="Bảng A","COS Pro Level 2","COS Pro Level 1")) | S30: =IF(COUNT(P30:R30)=0,"",SUM(P30:R30)) | T30: =IF(S30="","",COUNTIFS($D$2:$D$120,D30,$S$2:$S$120,">"&S30)+1) | U30: =IF(OR(L30>=Tham_so!$B$3,AND(ISNUMBER(S30),S30>=Tham_so!$B$3)),"Có","Không") -> Có | V30: =IF(L30>=Tham_so!$B$9,"Giỏi",IF(L30>=Tham_so!$B$10,"Khá",IF(L30>=Tham_so!$B$11,"Trung bình","Yếu"))) -> Khá | W30: =IF(S30="","",IF(S30>=Tham_so!$B$9,"Giỏi",IF(S30>=Tham_so!$B$10,"Khá",IF(S30>=Tham_so!$B$11,"Trung bình","Yếu")))) | X30: Có
A31: 30 | B31: thanhnguyen030@ptit.edu.vn | C31: Nguyễn Đức Thành | D31: Bảng B | E31: Đại học Duy Tân | F31: Đà Nẵng | G31: Có | H31: =IF(D31="Bảng A","COS Pro Level 3","COS Pro Level 2") -> COS Pro Level 2 | I31: 420 | J31: 200 | K31: 230 | L31: =SUM(I31:K31) -> 850 | M31: =COUNTIFS($D$2:$D$120,D31,$L$2:$L$120,">"&L31)+1 -> 1 | N31: =IF(M31<=IF(D31="Bảng A",Tham_so!$B$5,Tham_so!$B$6),"Có","Không") -> Có | O31: =IF(COUNT(P31:R31)=0,"",IF(D31="Bảng A","COS Pro Level 2","COS Pro Level 1")) -> COS Pro Level 1 | P31: 340 | Q31: 390 | R31: 230 | S31: =IF(COUNT(P31:R31)=0,"",SUM(P31:R31)) -> 960 | T31: =IF(S31="","",COUNTIFS($D$2:$D$120,D31,$S$2:$S$120,">"&S31)+1) -> 5 | U31: =IF(OR(L31>=Tham_so!$B$3,AND(ISNUMBER(S31),S31>=Tham_so!$B$3)),"Có","Không") -> Có | V31: =IF(L31>=Tham_so!$B$9,"Giỏi",IF(L31>=Tham_so!$B$10,"Khá",IF(L31>=Tham_so!$B$11,"Trung bình","Yếu"))) -> Giỏi | W31: =IF(S31="","",IF(S31>=Tham_so!$B$9,"Giỏi",IF(S31>=Tham_so!$B$10,"Khá",IF(S31>=Tham_so!$B$11,"Trung bình","Yếu")))) -> Giỏi | X31: Có
A32: 31 | B32: phucdinh031@ptit.edu.vn | C32: Đinh Minh Phúc | D32: Bảng B | E32: Học viện Công nghệ Bưu chính Viễn thông (PTIT) | F32: Quảng Ninh | G32: Có | H32: =IF(D32="Bảng A","COS Pro Level 3","COS Pro Level 2") -> COS Pro Level 2 | I32: 400 | J32: 190 | K32: 180 | L32: =SUM(I32:K32) -> 770 | M32: =COUNTIFS($D$2:$D$120,D32,$L$2:$L$120,">"&L32)+1 -> 6 | N32: =IF(M32<=IF(D32="Bảng A",Tham_so!$B$5,Tham_so!$B$6),"Có","Không") -> Có | O32: =IF(COUNT(P32:R32)=0,"",IF(D32="Bảng A","COS Pro Level 2","COS Pro Level 1")) -> COS Pro Level 1 | P32: 340 | Q32: 310 | R32: 210 | S32: =IF(COUNT(P32:R32)=0,"",SUM(P32:R32)) -> 860 | T32: =IF(S32="","",COUNTIFS($D$2:$D$120,D32,$S$2:$S$120,">"&S32)+1) -> 10 | U32: =IF(OR(L32>=Tham_so!$B$3,AND(ISNUMBER(S32),S32>=Tham_so!$B$3)),"Có","Không") -> Có | V32: =IF(L32>=Tham_so!$B$9,"Giỏi",IF(L32>=Tham_so!$B$10,"Khá",IF(L32>=Tham_so!$B$11,"Trung bình","Yếu"))) -> Khá | W32: =IF(S32="","",IF(S32>=Tham_so!$B$9,"Giỏi",IF(S32>=Tham_so!$B$10,"Khá",IF(S32>=Tham_so!$B$11,"Trung bình","Yếu")))) -> Giỏi | X32: Có
A33: 32 | B33: toanpham032@ptit.edu.vn | C33: Phạm Anh Toàn | D33: Bảng B | E33: Đại học Bách Khoa Hà Nội | F33: Phú Thọ | G33: Có | H33: =IF(D33="Bảng A","COS Pro Level 3","COS Pro Level 2") -> COS Pro Level 2 | I33: 240 | J33: 120 | K33: 170 | L33: =SUM(I33:K33) -> 530 | M33: =COUNTIFS($D$2:$D$120,D33,$L$2:$L$120,">"&L33)+1 -> 50 | N33: =IF(M33<=IF(D33="Bảng A",Tham_so!$B$5,Tham_so!$B$6),"Có","Không") -> Không | O33: =IF(COUNT(P33:R33)=0,"",IF(D33="Bảng A","COS Pro Level 2","COS Pro Level 1")) | S33: =IF(COUNT(P33:R33)=0,"",SUM(P33:R33)) | T33: =IF(S33="","",COUNTIFS($D$2:$D$120,D33,$S$2:$S$120,">"&S33)+1) | U33: =IF(OR(L33>=Tham_so!$B$3,AND(ISNUMBER(S33),S33>=Tham_so!$B$3)),"Có","Không") -> Không | V33: =IF(L33>=Tham_so!$B$9,"Giỏi",IF(L33>=Tham_so!$B$10,"Khá",IF(L33>=Tham_so!$B$11,"Trung bình","Yếu"))) -> Trung bình | W33: =IF(S33="","",IF(S33>=Tham_so!$B$9,"Giỏi",IF(S33>=Tham_so!$B$10,"Khá",IF(S33>=Tham_so!$B$11,"Trung bình","Yếu")))) | X33: Có
A34: 33 | B34: lamta033@ptit.edu.vn | C34: Tạ Anh Lâm | D34: Bảng B | E34: Đại học Công nghệ - ĐHQGHN | F34: Nghệ An | G34: Có | H34: =IF(D34="Bảng A","COS Pro Level 3","COS Pro Level 2") -> COS Pro Level 2 | I34: 230 | J34: 140 | K34: 110 | L34: =SUM(I34:K34) -> 480 | M34: =COUNTIFS($D$2:$D$120,D34,$L$2:$L$120,">"&L34)+1 -> 63 | N34: =IF(M34<=IF(D34="Bảng A",Tham_so!$B$5,Tham_so!$B$6),"Có","Không") -> Không | O34: =IF(COUNT(P34:R34)=0,"",IF(D34="Bảng A","COS Pro Level 2","COS Pro Level 1")) | S34: =IF(COUNT(P34:R34)=0,"",SUM(P34:R34)) | T34: =IF(S34="","",COUNTIFS($D$2:$D$120,D34,$S$2:$S$120,">"&S34)+1) | U34: =IF(OR(L34>=Tham_so!$B$3,AND(ISNUMBER(S34),S34>=Tham_so!$B$3)),"Có","Không") -> Không | V34: =IF(L34>=Tham_so!$B$9,"Giỏi",IF(L34>=Tham_so!$B$10,"Khá",IF(L34>=Tham_so!$B$11,"Trung bình","Yếu"))) -> Trung bình | W34: =IF(S34="","",IF(S34>=Tham_so!$B$9,"Giỏi",IF(S34>=Tham_so!$B$10,"Khá",IF(S34>=Tham_so!$B$11,"Trung bình","Yếu")))) | X34: Có
A35: 34 | B35: lanhoang034@ptit.edu.vn | C35: Hoàng Nhật Lan | D35: Bảng B | E35: Đại học Kinh tế Quốc dân | F35: Lâm Đồng | G35: Có | H35: =IF(D35="Bảng A","COS Pro Level 3","COS Pro Level 2") -> COS Pro Level 2 | I35: 280 | J35: 150 | K35: 120 | L35: =SUM(I35:K35) -> 550 | M35: =COUNTIFS($D$2:$D$120,D35,$L$2:$L$120,">"&L35)+1 -> 43 | N35: =IF(M35<=IF(D35="Bảng A",Tham_so!$B$5,Tham_so!$B$6),"Có","Không") -> Không | O35: =IF(COUNT(P35:R35)=0,"",IF(D35="Bảng A","COS Pro Level 2","COS Pro Level 1")) | S35: =IF(COUNT(P35:R35)=0,"",SUM(P35:R35)) | T35: =IF(S35="","",COUNTIFS($D$2:$D$120,D35,$S$2:$S$120,">"&S35)+1) | U35: =IF(OR(L35>=Tham_so!$B$3,AND(ISNUMBER(S35),S35>=Tham_so!$B$3)),"Có","Không") -> Không | V35: =IF(L35>=Tham_so!$B$9,"Giỏi",IF(L35>=Tham_so!$B$10,"Khá",IF(L35>=Tham_so!$B$11,"Trung bình","Yếu"))) -> Trung bình | W35: =IF(S35="","",IF(S35>=Tham_so!$B$9,"Giỏi",IF(S35>=Tham_so!$B$10,"Khá",IF(S35>=Tham_so!$B$11,"Trung bình","Yếu")))) | X35: Có
A36: 35 | B36: dunghoang035@ptit.edu.vn | C36: Hoàng Anh Dũng | D36: Bảng B | E36: Đại học FPT | F36: Huế | G36: Có | H36: =IF(D36="Bảng A","COS Pro Level 3","COS Pro Level 2") -> COS Pro Level 2 | I36: 290 | J36: 160 | K36: 150 | L36: =SUM(I36:K36) -> 600 | M36: =COUNTIFS($D$2:$D$120,D36,$L$2:$L$120,">"&L36)+1 -> 30 | N36: =IF(M36<=IF(D36="Bảng A",Tham_so!$B$5,Tham_so!$B$6),"Có","Không") -> Không | O36: =IF(COUNT(P36:R36)=0,"",IF(D36="Bảng A","COS Pro Level 2","COS Pro Level 1")) | S36: =IF(COUNT(P36:R36)=0,"",SUM(P36:R36)) | T36: =IF(S36="","",COUNTIFS($D$2:$D$120,D36,$S$2:$S$120,">"&S36)+1) | U36: =IF(OR(L36>=Tham_so!$B$3,AND(ISNUMBER(S36),S36>=Tham_so!$B$3)),"Có","Không") -> Có | V36: =IF(L36>=Tham_so!$B$9,"Giỏi",IF(L36>=Tham_so!$B$10,"Khá",IF(L36>=Tham_so!$B$11,"Trung bình","Yếu"))) -> Khá | W36: =IF(S36="","",IF(S36>=Tham_so!$B$9,"Giỏi",IF(S36>=Tham_so!$B$10,"Khá",IF(S36>=Tham_so!$B$11,"Trung bình","Yếu")))) | X36: Có
A37: 36 | B37: tuele036@ptit.edu.vn | C37: Lê Phương Tuệ | D37: Bảng B | E37: Đại học Bách Khoa TP.HCM | F37: Thanh Hóa | G37: Có | H37: =IF(D37="Bảng A","COS Pro Level 3","COS Pro Level 2") -> COS Pro Level 2 | I37: 370 | J37: 190 | K37: 210 | L37: =SUM(I37:K37) -> 770 | M37: =COUNTIFS($D$2:$D$120,D37,$L$2:$L$120,">"&L37)+1 -> 6 | N37: =IF(M37<=IF(D37="Bảng A",Tham_so!$B$5,Tham_so!$B$6),"Có","Không") -> Có | O37: =IF(COUNT(P37:R37)=0,"",IF(D37="Bảng A","COS Pro Level 2","COS Pro Level 1")) -> COS Pro Level 1 | P37: 340 | Q37: 400 | R37: 240 | S37: =IF(COUNT(P37:R37)=0,"",SUM(P37:R37)) -> 980 | T37: =IF(S37="","",COUNTIFS($D$2:$D$120,D37,$S$2:$S$120,">"&S37)+1) -> 3 | U37: =IF(OR(L37>=Tham_so!$B$3,AND(ISNUMBER(S37),S37>=Tham_so!$B$3)),"Có","Không") -> Có | V37: =IF(L37>=Tham_so!$B$9,"Giỏi",IF(L37>=Tham_so!$B$10,"Khá",IF(L37>=Tham_so!$B$11,"Trung bình","Yếu"))) -> Khá | W37: =IF(S37="","",IF(S37>=Tham_so!$B$9,"Giỏi",IF(S37>=Tham_so!$B$10,"Khá",IF(S37>=Tham_so!$B$11,"Trung bình","Yếu")))) -> Giỏi | X37: Có
A38: 37 | B38: cuongvu037@ptit.edu.vn | C38: Vũ Tuấn Cường | D38: Bảng B | E38: Đại học Khoa học Tự nhiên TP.HCM | F38: Đồng Nai | G38: Có | H38: =IF(D38="Bảng A","COS Pro Level 3","COS Pro Level 2") -> COS Pro Level 2 | I38: 400 | J38: 170 | K38: 190 | L38: =SUM(I38:K38) -> 760 | M38: =COUNTIFS($D$2:$D$120,D38,$L$2:$L$120,">"&L38)+1 -> 10 | N38: =IF(M38<=IF(D38="Bảng A",Tham_so!$B$5,Tham_so!$B$6),"Có","Không") -> Có | O38: =IF(COUNT(P38:R38)=0,"",IF(D38="Bảng A","COS Pro Level 2","COS Pro Level 1")) -> COS Pro Level 1 | P38: 340 | Q38: 310 | R38: 240 | S38: =IF(COUNT(P38:R38)=0,"",SUM(P38:R38)) -> 890 | T38: =IF(S38="","",COUNTIFS($D$2:$D$120,D38,$S$2:$S$120,">"&S38)+1) -> 8 | U38: =IF(OR(L38>=Tham_so!$B$3,AND(ISNUMBER(S38),S38>=Tham_so!$B$3)),"Có","Không") -> Có | V38: =IF(L38>=Tham_so!$B$9,"Giỏi",IF(L38>=Tham_so!$B$10,"Khá",IF(L38>=Tham_so!$B$11,"Trung bình","Yếu"))) -> Khá | W38: =IF(S38="","",IF(S38>=Tham_so!$B$9,"Giỏi",IF(S38>=Tham_so!$B$10,"Khá",IF(S38>=Tham_so!$B$11,"Trung bình","Yếu")))) -> Giỏi | X38: Có
A39: 38 | B39: tienle038@ptit.edu.vn | C39: Lê Minh Tiến | D39: Bảng B | E39: Đại học CNTT - ĐHQG TP.HCM | F39: Cần Thơ | G39: Có | H39: =IF(D39="Bảng A","COS Pro Level 3","COS Pro Level 2") -> COS Pro Level 2 | I39: 220 | J39: 90 | K39: 160 | L39: =SUM(I39:K39) -> 470 | M39: =COUNTIFS($D$2:$D$120,D39,$L$2:$L$120,">"&L39)+1 -> 66 | N39: =IF(M39<=IF(D39="Bảng A",Tham_so!$B$5,Tham_so!$B$6),"Có","Không") -> Không | O39: =IF(COUNT(P39:R39)=0,"",IF(D39="Bảng A","COS Pro Level 2","COS Pro Level 1")) | S39: =IF(COUNT(P39:R39)=0,"",SUM(P39:R39)) | T39: =IF(S39="","",COUNTIFS($D$2:$D$120,D39,$S$2:$S$120,">"&S39)+1) | U39: =IF(OR(L39>=Tham_so!$B$3,AND(ISNUMBER(S39),S39>=Tham_so!$B$3)),"Có","Không") -> Không | V39: =IF(L39>=Tham_so!$B$9,"Giỏi",IF(L39>=Tham_so!$B$10,"Khá",IF(L39>=Tham_so!$B$11,"Trung bình","Yếu"))) -> Trung bình | W39: =IF(S39="","",IF(S39>=Tham_so!$B$9,"Giỏi",IF(S39>=Tham_so!$B$10,"Khá",IF(S39>=Tham_so!$B$11,"Trung bình","Yếu")))) | X39: Có
A40: 39 | B40: khoita039@ptit.edu.vn | C40: Tạ Xuân Khôi | D40: Bảng B | E40: Đại học Sư phạm Kỹ thuật TP.HCM | F40: Hải Dương | G40: Có | H40: =IF(D40="Bảng A","COS Pro Level 3","COS Pro Level 2") -> COS Pro Level 2 | I40: 270 | J40: 150 | K40: 160 | L40: =SUM(I40:K40) -> 580 | M40: =COUNTIFS($D$2:$D$120,D40,$L$2:$L$120,">"&L40)+1 -> 35 | N40: =IF(M40<=IF(D40="Bảng A",Tham_so!$B$5,Tham_so!$B$6),"Có","Không") -> Không | O40: =IF(COUNT(P40:R40)=0,"",IF(D40="Bảng A","COS Pro Level 2","COS Pro Level 1")) | S40: =IF(COUNT(P40:R40)=0,"",SUM(P40:R40)) | T40: =IF(S40="","",COUNTIFS($D$2:$D$120,D40,$S$2:$S$120,">"&S40)+1) | U40: =IF(OR(L40>=Tham_so!$B$3,AND(ISNUMBER(S40),S40>=Tham_so!$B$3)),"Có","Không") -> Không | V40: =IF(L40>=Tham_so!$B$9,"Giỏi",IF(L40>=Tham_so!$B$10,"Khá",IF(L40>=Tham_so!$B$11,"Trung bình","Yếu"))) -> Trung bình | W40: =IF(S40="","",IF(S40>=Tham_so!$B$9,"Giỏi",IF(S40>=Tham_so!$B$10,"Khá",IF(S40>=Tham_so!$B$11,"Trung bình","Yếu")))) | X40: Có
...

Sheet Phan_loai
A1: PHÂN LOẠI ĐIỂM THEO BẢNG THI (dữ liệu GIẢ LẬP)
A2: Xếp loại theo tổng điểm /1000, ngưỡng lấy từ sheet Tham_so. Chung kết chỉ có ít người nên tỷ lệ % rất kém ổn định.
A5: Xếp loại | B5: Điều kiện (tổng /1000) | C5: Bảng A – Vòng loại | E5: Bảng A – Chung kết | G5: Bảng B – Vòng loại | I5: Bảng B – Chung kết
C6: Số người | D6: % | E6: Số người | F6: % | G6: Số người | H6: % | I6: Số người | J6: %
A7: Giỏi | B7: ="≥ "&Tham_so!$B$9 -> ≥ 800 | C7: =COUNTIFS(Tong_hop!$D$2:$D$120,"Bảng A",Tong_hop!$V$2:$V$120,$A7) -> 0 | D7: =IF(C$11=0,"",C7/C$11) -> 0 | E7: =COUNTIFS(Tong_hop!$D$2:$D$120,"Bảng A",Tong_hop!$W$2:$W$120,$A7) -> 0 | F7: =IF(E$11=0,"",E7/E$11) -> 0 | G7: =COUNTIFS(Tong_hop!$D$2:$D$120,"Bảng B",Tong_hop!$V$2:$V$120,$A7) -> 4 | H7: =IF(G$11=0,"",G7/G$11) -> 0.042105263 | I7: =COUNTIFS(Tong_hop!$D$2:$D$120,"Bảng B",Tong_hop!$W$2:$W$120,$A7) -> 10 | J7: =IF(I$11=0,"",I7/I$11) -> 1
A8: Khá | B8: ="từ "&Tham_so!$B$10&" đến dưới "&Tham_so!$B$9 -> từ 600 đến dưới 800 | C8: =COUNTIFS(Tong_hop!$D$2:$D$120,"Bảng A",Tong_hop!$V$2:$V$120,$A8) -> 4 | D8: =IF(C$11=0,"",C8/C$11) -> 0.16666667 | E8: =COUNTIFS(Tong_hop!$D$2:$D$120,"Bảng A",Tong_hop!$W$2:$W$120,$A8) -> 3 | F8: =IF(E$11=0,"",E8/E$11) -> 1 | G8: =COUNTIFS(Tong_hop!$D$2:$D$120,"Bảng B",Tong_hop!$V$2:$V$120,$A8) -> 27 | H8: =IF(G$11=0,"",G8/G$11) -> 0.28421053 | I8: =COUNTIFS(Tong_hop!$D$2:$D$120,"Bảng B",Tong_hop!$W$2:$W$120,$A8) -> 0 | J8: =IF(I$11=0,"",I8/I$11) -> 0
A9: Trung bình | B9: ="từ "&Tham_so!$B$11&" đến dưới "&Tham_so!$B$10 -> từ 400 đến dưới 600 | C9: =COUNTIFS(Tong_hop!$D$2:$D$120,"Bảng A",Tong_hop!$V$2:$V$120,$A9) -> 14 | D9: =IF(C$11=0,"",C9/C$11) -> 0.58333333 | E9: =COUNTIFS(Tong_hop!$D$2:$D$120,"Bảng A",Tong_hop!$W$2:$W$120,$A9) -> 0 | F9: =IF(E$11=0,"",E9/E$11) -> 0 | G9: =COUNTIFS(Tong_hop!$D$2:$D$120,"Bảng B",Tong_hop!$V$2:$V$120,$A9) -> 49 | H9: =IF(G$11=0,"",G9/G$11) -> 0.51578947 | I9: =COUNTIFS(Tong_hop!$D$2:$D$120,"Bảng B",Tong_hop!$W$2:$W$120,$A9) -> 0 | J9: =IF(I$11=0,"",I9/I$11) -> 0
A10: Yếu | B10: ="dưới "&Tham_so!$B$11 -> dưới 400 | C10: =COUNTIFS(Tong_hop!$D$2:$D$120,"Bảng A",Tong_hop!$V$2:$V$120,$A10) -> 6 | D10: =IF(C$11=0,"",C10/C$11) -> 0.25 | E10: =COUNTIFS(Tong_hop!$D$2:$D$120,"Bảng A",Tong_hop!$W$2:$W$120,$A10) -> 0 | F10: =IF(E$11=0,"",E10/E$11) -> 0 | G10: =COUNTIFS(Tong_hop!$D$2:$D$120,"Bảng B",Tong_hop!$V$2:$V$120,$A10) -> 15 | H10: =IF(G$11=0,"",G10/G$11) -> 0.15789474 | I10: =COUNTIFS(Tong_hop!$D$2:$D$120,"Bảng B",Tong_hop!$W$2:$W$120,$A10) -> 0 | J10: =IF(I$11=0,"",I10/I$11) -> 0
A11: Tổng | C11: =SUM(C7:C10) -> 24 | D11: =IF(C11=0,"",SUM(D7:D10)) -> 1 | E11: =SUM(E7:E10) -> 3 | F11: =IF(E11=0,"",SUM(F7:F10)) -> 1 | G11: =SUM(G7:G10) -> 95 | H11: =IF(G11=0,"",SUM(H7:H10)) -> 1 | I11: =SUM(I7:I10) -> 10 | J11: =IF(I11=0,"",SUM(J7:J10)) -> 1
A14: CHỈ SỐ TỔNG QUAN
A15: Chỉ số | C15: Bảng A – Vòng loại | E15: Bảng A – Chung kết | G15: Bảng B – Vòng loại | I15: Bảng B – Chung kết
A16: Số thí sinh có điểm | C16: =COUNTIFS(Tong_hop!$D$2:$D$120,"Bảng A",Tong_hop!$L$2:$L$120,">=0") -> 24 | E16: =COUNTIFS(Tong_hop!$D$2:$D$120,"Bảng A",Tong_hop!$S$2:$S$120,">=0") -> 3 | G16: =COUNTIFS(Tong_hop!$D$2:$D$120,"Bảng B",Tong_hop!$L$2:$L$120,">=0") -> 95 | I16: =COUNTIFS(Tong_hop!$D$2:$D$120,"Bảng B",Tong_hop!$S$2:$S$120,">=0") -> 10
A17: Điểm trung bình | C17: =IFERROR(AVERAGEIFS(Tong_hop!$L$2:$L$120,Tong_hop!$D$2:$D$120,"Bảng A"),"") -> 472.5 | E17: =IFERROR(AVERAGEIFS(Tong_hop!$S$2:$S$120,Tong_hop!$D$2:$D$120,"Bảng A"),"") -> 756.66667 | G17: =IFERROR(AVERAGEIFS(Tong_hop!$L$2:$L$120,Tong_hop!$D$2:$D$120,"Bảng B"),"") -> 541.36842 | I17: =IFERROR(AVERAGEIFS(Tong_hop!$S$2:$S$120,Tong_hop!$D$2:$D$120,"Bảng B"),"") -> 936
A18: Điểm cao nhất | C18: =IF(C16=0,"",_xlfn.MAXIFS(Tong_hop!$L$2:$L$120,Tong_hop!$D$2:$D$120,"Bảng A")) -> 670 | E18: =IF(E16=0,"",_xlfn.MAXIFS(Tong_hop!$S$2:$S$120,Tong_hop!$D$2:$D$120,"Bảng A")) -> 780 | G18: =IF(G16=0,"",_xlfn.MAXIFS(Tong_hop!$L$2:$L$120,Tong_hop!$D$2:$D$120,"Bảng B")) -> 850 | I18: =IF(I16=0,"",_xlfn.MAXIFS(Tong_hop!$S$2:$S$120,Tong_hop!$D$2:$D$120,"Bảng B")) -> 990
A19: Điểm thấp nhất | C19: =IF(C16=0,"",_xlfn.MINIFS(Tong_hop!$L$2:$L$120,Tong_hop!$D$2:$D$120,"Bảng A")) -> 260 | E19: =IF(E16=0,"",_xlfn.MINIFS(Tong_hop!$S$2:$S$120,Tong_hop!$D$2:$D$120,"Bảng A")) -> 720 | G19: =IF(G16=0,"",_xlfn.MINIFS(Tong_hop!$L$2:$L$120,Tong_hop!$D$2:$D$120,"Bảng B")) -> 170 | I19: =IF(I16=0,"",_xlfn.MINIFS(Tong_hop!$S$2:$S$120,Tong_hop!$D$2:$D$120,"Bảng B")) -> 860
A20: Số người đạt ngưỡng chứng chỉ | C20: =COUNTIFS(Tong_hop!$D$2:$D$120,"Bảng A",Tong_hop!$L$2:$L$120,">="&Tham_so!$B$3) -> 4 | E20: =COUNTIFS(Tong_hop!$D$2:$D$120,"Bảng A",Tong_hop!$S$2:$S$120,">="&Tham_so!$B$3) -> 3 | G20: =COUNTIFS(Tong_hop!$D$2:$D$120,"Bảng B",Tong_hop!$L$2:$L$120,">="&Tham_so!$B$3) -> 31 | I20: =COUNTIFS(Tong_hop!$D$2:$D$120,"Bảng B",Tong_hop!$S$2:$S$120,">="&Tham_so!$B$3) -> 10

Sheet Chi_tiet_diem
A1: Email | B1: Họ tên | C1: Bảng | D1: Vòng | E1: Cấp COS Pro | F1: Phần thi | G1: Điểm | H1: Điểm tối đa | I1: % điểm | J1: Dữ liệu giả lập
A2: namduong001@ptit.edu.vn | B2: Dương Hoài Nam | C2: Bảng A | D2: Vòng loại | E2: COS Pro Level 3 | F2: Đọc hiểu code (điền chỗ trống) | G2: =INDEX(Tong_hop!$I$2:$I$120,MATCH($A2,Tong_hop!$B$2:$B$120,0)) -> 290 | H2: 500 | I2: =IF(H2=0,"",G2/H2) -> 0.58 | J2: Có
A3: namduong001@ptit.edu.vn | B3: Dương Hoài Nam | C3: Bảng A | D3: Vòng loại | E3: COS Pro Level 3 | F3: Thiết kế · viết hàm | G3: =INDEX(Tong_hop!$J$2:$J$120,MATCH($A3,Tong_hop!$B$2:$B$120,0)) -> 250 | H3: 500 | I3: =IF(H3=0,"",G3/H3) -> 0.5 | J3: Có
A4: sonmai002@ptit.edu.vn | B4: Mai Minh Sơn | C4: Bảng A | D4: Vòng loại | E4: COS Pro Level 3 | F4: Đọc hiểu code (điền chỗ trống) | G4: =INDEX(Tong_hop!$I$2:$I$120,MATCH($A4,Tong_hop!$B$2:$B$120,0)) -> 370 | H4: 500 | I4: =IF(H4=0,"",G4/H4) -> 0.74 | J4: Có
A5: sonmai002@ptit.edu.vn | B5: Mai Minh Sơn | C5: Bảng A | D5: Vòng loại | E5: COS Pro Level 3 | F5: Thiết kế · viết hàm | G5: =INDEX(Tong_hop!$J$2:$J$120,MATCH($A5,Tong_hop!$B$2:$B$120,0)) -> 230 | H5: 500 | I5: =IF(H5=0,"",G5/H5) -> 0.46 | J5: Có
A6: sonmai002@ptit.edu.vn | B6: Mai Minh Sơn | C6: Bảng A | D6: Chung kết | E6: COS Pro Level 2 | F6: Debugging | G6: =INDEX(Tong_hop!$R$2:$R$120,MATCH($A6,Tong_hop!$B$2:$B$120,0)) -> 220 | H6: 280 | I6: =IF(H6=0,"",G6/H6) -> 0.78571429 | J6: Có
A7: sonmai002@ptit.edu.vn | B7: Mai Minh Sơn | C7: Bảng A | D7: Chung kết | E7: COS Pro Level 2 | F7: Design | G7: =INDEX(Tong_hop!$Q$2:$Q$120,MATCH($A7,Tong_hop!$B$2:$B$120,0)) -> 180 | H7: 280 | I7: =IF(H7=0,"",G7/H7) -> 0.64285714 | J7: Có
A8: sonmai002@ptit.edu.vn | B8: Mai Minh Sơn | C8: Bảng A | D8: Chung kết | E8: COS Pro Level 2 | F8: Đọc hiểu code | G8: =INDEX(Tong_hop!$P$2:$P$120,MATCH($A8,Tong_hop!$B$2:$B$120,0)) -> 320 | H8: 440 | I8: =IF(H8=0,"",G8/H8) -> 0.72727273 | J8: Có
A9: giangpham003@ptit.edu.vn | B9: Phạm Hoài Giang | C9: Bảng A | D9: Vòng loại | E9: COS Pro Level 3 | F9: Đọc hiểu code (điền chỗ trống) | G9: =INDEX(Tong_hop!$I$2:$I$120,MATCH($A9,Tong_hop!$B$2:$B$120,0)) -> 400 | H9: 500 | I9: =IF(H9=0,"",G9/H9) -> 0.8 | J9: Có
A10: giangpham003@ptit.edu.vn | B10: Phạm Hoài Giang | C10: Bảng A | D10: Vòng loại | E10: COS Pro Level 3 | F10: Thiết kế · viết hàm | G10: =INDEX(Tong_hop!$J$2:$J$120,MATCH($A10,Tong_hop!$B$2:$B$120,0)) -> 270 | H10: 500 | I10: =IF(H10=0,"",G10/H10) -> 0.54 | J10: Có
A11: giangpham003@ptit.edu.vn | B11: Phạm Hoài Giang | C11: Bảng A | D11: Chung kết | E11: COS Pro Level 2 | F11: Debugging | G11: =INDEX(Tong_hop!$R$2:$R$120,MATCH($A11,Tong_hop!$B$2:$B$120,0)) -> 230 | H11: 280 | I11: =IF(H11=0,"",G11/H11) -> 0.82142857 | J11: Có
A12: giangpham003@ptit.edu.vn | B12: Phạm Hoài Giang | C12: Bảng A | D12: Chung kết | E12: COS Pro Level 2 | F12: Design | G12: =INDEX(Tong_hop!$Q$2:$Q$120,MATCH($A12,Tong_hop!$B$2:$B$120,0)) -> 190 | H12: 280 | I12: =IF(H12=0,"",G12/H12) -> 0.67857143 | J12: Có
A13: giangpham003@ptit.edu.vn | B13: Phạm Hoài Giang | C13: Bảng A | D13: Chung kết | E13: COS Pro Level 2 | F13: Đọc hiểu code | G13: =INDEX(Tong_hop!$P$2:$P$120,MATCH($A13,Tong_hop!$B$2:$B$120,0)) -> 360 | H13: 440 | I13: =IF(H13=0,"",G13/H13) -> 0.81818182 | J13: Có
A14: vyho004@ptit.edu.vn | B14: Hồ Hữu Vy | C14: Bảng A | D14: Vòng loại | E14: COS Pro Level 3 | F14: Đọc hiểu code (điền chỗ trống) | G14: =INDEX(Tong_hop!$I$2:$I$120,MATCH($A14,Tong_hop!$B$2:$B$120,0)) -> 350 | H14: 500 | I14: =IF(H14=0,"",G14/H14) -> 0.7 | J14: Có
A15: vyho004@ptit.edu.vn | B15: Hồ Hữu Vy | C15: Bảng A | D15: Vòng loại | E15: COS Pro Level 3 | F15: Thiết kế · viết hàm | G15: =INDEX(Tong_hop!$J$2:$J$120,MATCH($A15,Tong_hop!$B$2:$B$120,0)) -> 210 | H15: 500 | I15: =IF(H15=0,"",G15/H15) -> 0.42 | J15: Có
A16: phucvo005@ptit.edu.vn | B16: Võ Phương Phúc | C16: Bảng A | D16: Vòng loại | E16: COS Pro Level 3 | F16: Đọc hiểu code (điền chỗ trống) | G16: =INDEX(Tong_hop!$I$2:$I$120,MATCH($A16,Tong_hop!$B$2:$B$120,0)) -> 130 | H16: 500 | I16: =IF(H16=0,"",G16/H16) -> 0.26 | J16: Có
A17: phucvo005@ptit.edu.vn | B17: Võ Phương Phúc | C17: Bảng A | D17: Vòng loại | E17: COS Pro Level 3 | F17: Thiết kế · viết hàm | G17: =INDEX(Tong_hop!$J$2:$J$120,MATCH($A17,Tong_hop!$B$2:$B$120,0)) -> 130 | H17: 500 | I17: =IF(H17=0,"",G17/H17) -> 0.26 | J17: Có
A18: hoapham006@ptit.edu.vn | B18: Phạm Khánh Hoa | C18: Bảng A | D18: Vòng loại | E18: COS Pro Level 3 | F18: Đọc hiểu code (điền chỗ trống) | G18: =INDEX(Tong_hop!$I$2:$I$120,MATCH($A18,Tong_hop!$B$2:$B$120,0)) -> 280 | H18: 500 | I18: =IF(H18=0,"",G18/H18) -> 0.56 | J18: Có
A19: hoapham006@ptit.edu.vn | B19: Phạm Khánh Hoa | C19: Bảng A | D19: Vòng loại | E19: COS Pro Level 3 | F19: Thiết kế · viết hàm | G19: =INDEX(Tong_hop!$J$2:$J$120,MATCH($A19,Tong_hop!$B$2:$B$120,0)) -> 280 | H19: 500 | I19: =IF(H19=0,"",G19/H19) -> 0.56 | J19: Có
A20: yenlam007@ptit.edu.vn | B20: Lâm Hoài Yến | C20: Bảng A | D20: Vòng loại | E20: COS Pro Level 3 | F20: Đọc hiểu code (điền chỗ trống) | G20: =INDEX(Tong_hop!$I$2:$I$120,MATCH($A20,Tong_hop!$B$2:$B$120,0)) -> 340 | H20: 500 | I20: =IF(H20=0,"",G20/H20) -> 0.68 | J20: Có
A21: yenlam007@ptit.edu.vn | B21: Lâm Hoài Yến | C21: Bảng A | D21: Vòng loại | E21: COS Pro Level 3 | F21: Thiết kế · viết hàm | G21: =INDEX(Tong_hop!$J$2:$J$120,MATCH($A21,Tong_hop!$B$2:$B$120,0)) -> 190 | H21: 500 | I21: =IF(H21=0,"",G21/H21) -> 0.38 | J21: Có
A22: giangtrinh008@ptit.edu.vn | B22: Trịnh Thị Giang | C22: Bảng A | D22: Vòng loại | E22: COS Pro Level 3 | F22: Đọc hiểu code (điền chỗ trống) | G22: =INDEX(Tong_hop!$I$2:$I$120,MATCH($A22,Tong_hop!$B$2:$B$120,0)) -> 300 | H22: 500 | I22: =IF(H22=0,"",G22/H22) -> 0.6 | J22: Có
A23: giangtrinh008@ptit.edu.vn | B23: Trịnh Thị Giang | C23: Bảng A | D23: Vòng loại | E23: COS Pro Level 3 | F23: Thiết kế · viết hàm | G23: =INDEX(Tong_hop!$J$2:$J$120,MATCH($A23,Tong_hop!$B$2:$B$120,0)) -> 300 | H23: 500 | I23: =IF(H23=0,"",G23/H23) -> 0.6 | J23: Có
A24: yenhoang009@ptit.edu.vn | B24: Hoàng Anh Yến | C24: Bảng A | D24: Vòng loại | E24: COS Pro Level 3 | F24: Đọc hiểu code (điền chỗ trống) | G24: =INDEX(Tong_hop!$I$2:$I$120,MATCH($A24,Tong_hop!$B$2:$B$120,0)) -> 270 | H24: 500 | I24: =IF(H24=0,"",G24/H24) -> 0.54 | J24: Có
A25: yenhoang009@ptit.edu.vn | B25: Hoàng Anh Yến | C25: Bảng A | D25: Vòng loại | E25: COS Pro Level 3 | F25: Thiết kế · viết hàm | G25: =INDEX(Tong_hop!$J$2:$J$120,MATCH($A25,Tong_hop!$B$2:$B$120,0)) -> 210 | H25: 500 | I25: =IF(H25=0,"",G25/H25) -> 0.42 | J25: Có
A26: cuongtran010@ptit.edu.vn | B26: Trần Thanh Cường | C26: Bảng A | D26: Vòng loại | E26: COS Pro Level 3 | F26: Đọc hiểu code (điền chỗ trống) | G26: =INDEX(Tong_hop!$I$2:$I$120,MATCH($A26,Tong_hop!$B$2:$B$120,0)) -> 190 | H26: 500 | I26: =IF(H26=0,"",G26/H26) -> 0.38 | J26: Có
A27: cuongtran010@ptit.edu.vn | B27: Trần Thanh Cường | C27: Bảng A | D27: Vòng loại | E27: COS Pro Level 3 | F27: Thiết kế · viết hàm | G27: =INDEX(Tong_hop!$J$2:$J$120,MATCH($A27,Tong_hop!$B$2:$B$120,0)) -> 220 | H27: 500 | I27: =IF(H27=0,"",G27/H27) -> 0.44 | J27: Có
A28: dungdang011@ptit.edu.vn | B28: Đặng Thu Dũng | C28: Bảng A | D28: Vòng loại | E28: COS Pro Level 3 | F28: Đọc hiểu code (điền chỗ trống) | G28: =INDEX(Tong_hop!$I$2:$I$120,MATCH($A28,Tong_hop!$B$2:$B$120,0)) -> 250 | H28: 500 | I28: =IF(H28=0,"",G28/H28) -> 0.5 | J28: Có
A29: dungdang011@ptit.edu.vn | B29: Đặng Thu Dũng | C29: Bảng A | D29: Vòng loại | E29: COS Pro Level 3 | F29: Thiết kế · viết hàm | G29: =INDEX(Tong_hop!$J$2:$J$120,MATCH($A29,Tong_hop!$B$2:$B$120,0)) -> 70 | H29: 500 | I29: =IF(H29=0,"",G29/H29) -> 0.14 | J29: Có
A30: phongphan012@ptit.edu.vn | B30: Phan Xuân Phong | C30: Bảng A | D30: Vòng loại | E30: COS Pro Level 3 | F30: Đọc hiểu code (điền chỗ trống) | G30: =INDEX(Tong_hop!$I$2:$I$120,MATCH($A30,Tong_hop!$B$2:$B$120,0)) -> 270 | H30: 500 | I30: =IF(H30=0,"",G30/H30) -> 0.54 | J30: Có
A31: phongphan012@ptit.edu.vn | B31: Phan Xuân Phong | C31: Bảng A | D31: Vòng loại | E31: COS Pro Level 3 | F31: Thiết kế · viết hàm | G31: =INDEX(Tong_hop!$J$2:$J$120,MATCH($A31,Tong_hop!$B$2:$B$120,0)) -> 220 | H31: 500 | I31: =IF(H31=0,"",G31/H31) -> 0.44 | J31: Có
A32: phongpham013@ptit.edu.vn | B32: Phạm Thu Phong | C32: Bảng A | D32: Vòng loại | E32: COS Pro Level 3 | F32: Đọc hiểu code (điền chỗ trống) | G32: =INDEX(Tong_hop!$I$2:$I$120,MATCH($A32,Tong_hop!$B$2:$B$120,0)) -> 220 | H32: 500 | I32: =IF(H32=0,"",G32/H32) -> 0.44 | J32: Có
A33: phongpham013@ptit.edu.vn | B33: Phạm Thu Phong | C33: Bảng A | D33: Vòng loại | E33: COS Pro Level 3 | F33: Thiết kế · viết hàm | G33: =INDEX(Tong_hop!$J$2:$J$120,MATCH($A33,Tong_hop!$B$2:$B$120,0)) -> 180 | H33: 500 | I33: =IF(H33=0,"",G33/H33) -> 0.36 | J33: Có
