Workbook

Sheet Dashboard
A1: DASHBOARD — Case study: Làm sạch dữ liệu & nạp CRM (sinh viên PTIT)
A2: • Dữ liệu: 3 nguồn thô ở Booklet 1 (website, Talkshow Google Form, FB Lead Form), toàn bộ là sinh viên PTIT.
A3: • Thông tin cá nhân (tên, email, SĐT, CCCD) đã được thay bằng dữ liệu giả lập để bảo mật.
A4: • Quy trình 5 bước: chuẩn hoá → gộp trùng → hồ sơ vàng (Contact ID) → phân segment → xuất danh sách.
A5: • Mọi con số dưới đây là công thức tham chiếu Master_Contacts, sửa Master là dashboard tự cập nhật.
B7: 1. Dữ liệu thô → dữ liệu sạch
B8: Chỉ số | C8: Giá trị
B9: Số dòng thô trong Booklet 1 (3 sheet) | C9: =191 -> 191
B10: – sheet Data (website) | C10: =132 -> 132
B11: – Talkshow Google Form + FB Lead Form | C11: =59 -> 59
B12: Số liên hệ duy nhất sau khi gộp | C12: =COUNTA(Master_Contacts!$A$10:$A$154) -> 145
B13: Số bản ghi bị gộp (xem Duplicate_Log) | C13: =191-C12 -> 46
B14: Tỉ lệ trùng lặp trong dữ liệu thô | C14: =C13/C9 -> 0.2408377
B16: 2. Phễu kinh doanh
B17: Chỉ số | C17: Giá trị
B18: Liên hệ duy nhất | C18: =COUNTA(Master_Contacts!$A$10:$A$154) -> 145
B19: Đã đăng ký trên website | C19: =COUNTIF(Master_Contacts!$H$10:$H$154,"Có") -> 119
B20: Đã thanh toán (thí sinh chính thức) | C20: =COUNTIF(Master_Contacts!$I$10:$I$154,"Đã thanh toán")+COUNTIF(Master_Contacts!$I$10:$I$154,"Miễn phí (free)") -> 66
B21: Đăng ký nhưng chưa thanh toán | C21: =COUNTIF(Master_Contacts!$I$10:$I$154,"Chưa thanh toán") -> 53
B22: Lead chưa đăng ký (Talkshow/FB) | C22: =COUNTIF(Master_Contacts!$H$10:$H$154,"Không") -> 26
B23: Tỉ lệ thanh toán / đăng ký web | C23: =C20/C19 -> 0.55462185
B24: Doanh thu ghi nhận (VND) | C24: =SUMIF(Master_Contacts!$I$10:$I$154,"Đã thanh toán",Master_Contacts!$J$10:$J$154) -> 18100000
B25: Doanh thu tiềm năng nếu chốt hết nhóm chưa thanh toán (VND) | C25: =SUMIF(Master_Contacts!$I$10:$I$154,"Chưa thanh toán",Master_Contacts!$J$10:$J$154) -> 27250000
B27: 3. Segment cho CRM / email marketing
B28: Segment | C28: Liên hệ | D28: % tổng | E28: Gửi được
B29: S1 · Thí sinh đã thanh toán | C29: =COUNTIF(Master_Contacts!$V$10:$V$154,"S1") -> 66 | D29: =C29/$C$18 -> 0.45517241 | E29: =COUNTIFS(Master_Contacts!$V$10:$V$154,"S1",Master_Contacts!$C$10:$C$154,"<>") -> 66
B30: S2 · Đăng ký web + Talkshow/FB, chưa thanh toán | C30: =COUNTIF(Master_Contacts!$V$10:$V$154,"S2") -> 11 | D30: =C30/$C$18 -> 0.075862069 | E30: =COUNTIFS(Master_Contacts!$V$10:$V$154,"S2",Master_Contacts!$C$10:$C$154,"<>") -> 11
B31: S3 · Đăng ký web, chưa thanh toán | C31: =COUNTIF(Master_Contacts!$V$10:$V$154,"S3") -> 42 | D31: =C31/$C$18 -> 0.28965517 | E31: =COUNTIFS(Master_Contacts!$V$10:$V$154,"S3",Master_Contacts!$C$10:$C$154,"<>") -> 42
B32: S4 · Lead Talkshow chưa đăng ký | C32: =COUNTIF(Master_Contacts!$V$10:$V$154,"S4") -> 10 | D32: =C32/$C$18 -> 0.068965517 | E32: =COUNTIFS(Master_Contacts!$V$10:$V$154,"S4",Master_Contacts!$C$10:$C$154,"<>") -> 9
B33: S5 · Lead FB Form chưa đăng ký | C33: =COUNTIF(Master_Contacts!$V$10:$V$154,"S5") -> 16 | D33: =C33/$C$18 -> 0.11034483 | E33: =COUNTIFS(Master_Contacts!$V$10:$V$154,"S5",Master_Contacts!$C$10:$C$154,"<>") -> 16
B35: 4. Chất lượng dữ liệu đầu vào
B36: Vấn đề | C36: Số lần
B37: Email được sửa tên miền / bỏ khoảng trắng | C37: =COUNTIF(Data_Quality!$A:$A,"Chuẩn hoá email") -> 5
B38: Email không hợp lệ hoặc bỏ trống | C38: =COUNTIF(Data_Quality!$A:$A,"Email không hợp lệ") -> 1
B39: SĐT phải chuẩn hoá về 10 số | C39: =COUNTIF(Data_Quality!$A:$A,"Chuẩn hoá số điện thoại") -> 32
B40: Tỉnh/thành viết khác nhau | C40: =COUNTIF(Data_Quality!$A:$A,"Chuẩn hoá tỉnh/thành") -> 30
B41: Tên trường nhập tự do cần quy về "School A" | C41: =COUNTIF(Data_Quality!$A:$A,"Chuẩn hoá tên trường") -> 132
B42: Liên hệ có cờ cần kiểm tra thủ công | C42: =COUNTIF(Master_Contacts!$Z$10:$Z$154,"<>") -> 16
B44: 5. Danh sách thi Bảng B (sản phẩm cuối)
B45: Điểm thi | C45: Thí sinh
...

Sheet Master_Contacts
A1: MASTER_CONTACTS — Hồ sơ vàng (golden record): 1 dòng = 1 người
A2: • Bảng đích để nạp vào CRM: từ 191 dòng thô của 3 nguồn còn 145 liên hệ duy nhất.
A3: • Quy tắc gộp: trùng email là cùng 1 người; trùng SĐT chỉ gộp khi tên khớp, tránh gộp nhầm anh em ruột.
A4: • Chọn giá trị chuẩn: ưu tiên dòng đã thanh toán, rồi dòng đăng ký web mới nhất, cuối cùng là form ngoài.
A5: • Contact ID (PT-001...) là khoá chính; không dùng tên hay email làm khoá.
A6: • Cột Nguồn dữ liệu và Số bản ghi gộp giữ lịch sử đa kênh của từng người (attribution).
A7: • Trước khi gửi email: lọc bỏ dòng có cờ cần kiểm tra và dòng thiếu email hợp lệ.
A9: Contact ID | B9: Họ tên | C9: Email | D9: SĐT | E9: Bảng | F9: Khu vực | G9: Trường (chuẩn hoá) | H9: Đăng ký web | I9: Trạng thái thanh toán | J9: Lệ phí (VND) | K9: Có tương tác Talkshow/FB | L9: Talkshow Google Form | M9: FB Lead Form | N9: Muốn nhận lịch Talkshow | O9: Câu hỏi / Quan tâm | P9: Tự khai đã đăng ký? | Q9: Số bản ghi gộp | R9: Số dòng trong Data | S9: Nguồn dữ liệu | T9: Tiếp xúc đầu tiên | U9: Ngày đăng ký web | V9: Segment | W9: Tên segment | X9: Sub-segment | Y9: Drip campaign | Z9: Cờ cần kiểm tra | AA9: PIC | AB9: Ghi chú (gộp)
A10: PT-001 | B10: Dương Hoài Nam | C10: duonghoainam380@gmail.com | D10: 0833008389 | E10: Bảng B | F10: Hà Nội | G10: School A | H10: Có | I10: Đã thanh toán | J10: 500000 | K10: Có | M10: Có | N10: Có | Q10: 3 | R10: 2 | S10: Website (Data), FB Lead Form v2 | T10: 46224.758 | U10: 46224.758 | V10: S1 | W10: Thí sinh đã thanh toán | X10: Có tương tác Talkshow/FB | Y10: D1 · Chuẩn bị thi | Z10: Tên viết khác nhau giữa các nguồn | AA10: Nhung | AB10: knm 27/7 knm 29/7: hôm đó kick off mn bảo vào đăng ký thử nên em đk thử thôi ạ 31/7: trùng thông tin đã completed bên dưới || 31/7 add zl htro thêm || đã call, đang cân nhắc
A11: PT-002 | B11: Mai Minh Sơn | C11: maiminhson2005@gmail.com | D11: 0884396213 | E11: Bảng B | F11: Hà Nội | G11: School A | H11: Có | I11: Đã thanh toán | J11: 500000 | K11: Không | Q11: 1 | R11: 1 | S11: Website (Data) | T11: 46225.376 | U11: 46225.376 | V11: S1 | W11: Thí sinh đã thanh toán | X11: Đăng ký trực tiếp qua website | Y11: D1 · Chuẩn bị thi | AA11: Nhung | AB11: done => chặn
A12: PT-003 | B12: Phạm Hoài Giang | C12: pha79dcat944@stu.ptit.edu.vn | D12: 0886855032 | E12: Bảng B | F12: Hà Nội | G12: School A | H12: Có | I12: Đã thanh toán | J12: 500000 | K12: Không | Q12: 1 | R12: 1 | S12: Website (Data) | T12: 46233.521 | U12: 46233.521 | V12: S1 | W12: Thí sinh đã thanh toán | X12: Đăng ký trực tiếp qua website | Y12: D1 · Chuẩn bị thi | AA12: Thắng | AB12: 30/7 đã nhận mail
A13: PT-004 | B13: Hồ Hữu Vy | C13: hoh43dcpt729@stu.ptit.edu.vn | D13: 0762989538 | E13: Bảng B | F13: Hà Nội | G13: School A | H13: Có | I13: Đã thanh toán | J13: 500000 | K13: Không | Q13: 2 | R13: 2 | S13: Website (Data) | T13: 46234.419 | U13: 46234.419 | V13: S1 | W13: Thí sinh đã thanh toán | X13: Đăng ký trực tiếp qua website | Y13: D1 · Chuẩn bị thi | AA13: Nhung | AB13: TRÙNG DATA DƯỚI, ĐÃ COMPLETED 31/7: tắt máy đã ping zzl
A14: PT-005 | B14: Võ Phương Phúc | C14: vophuongphuc@gmail.com | D14: 0826162603 | E14: Bảng B | F14: Hà Nội | G14: School A | H14: Có | I14: Đã thanh toán | J14: 500000 | K14: Có | L14: Có | N14: Có | O14: Đề thi có khó không ạ? | P14: Chưa đăng ký vì còn thắc mắc | Q14: 4 | R14: 1 | S14: Website (Data), Talkshow Google Form | T14: 46236.908 | U14: 46236.908 | V14: S1 | W14: Thí sinh đã thanh toán | X14: Có tương tác Talkshow/FB | Y14: D1 · Chuẩn bị thi | AA14: Thắng | AB14: 3/8 gọi 2 cuộc ko đc, nhắn zl || sẽ tham gia (25/08) sẽ tham gia (27/08) || trùng
A15: PT-006 | B15: Phạm Khánh Hoa | C15: phamkhanhhoa@gmail.com | D15: 0818360186 | E15: Bảng B | F15: Hà Nội | G15: School A | H15: Có | I15: Đã thanh toán | J15: 500000 | K15: Không | Q15: 1 | R15: 1 | S15: Website (Data) | T15: 46239.617 | U15: 46239.617 | V15: S1 | W15: Thí sinh đã thanh toán | X15: Đăng ký trực tiếp qua website | Y15: D1 · Chuẩn bị thi | AA15: Thắng | AB15: 5/8 knm nhắn zl 6/8 gọi knm đã đăng kí
A16: PT-007 | B16: Lâm Hoài Yến | C16: lamhoaiyen@gmail.com | D16: 0828797715 | E16: Bảng B | F16: Hà Nội | G16: School A | H16: Có | I16: Miễn phí (free) | J16: 500000 | K16: Không | Q16: 1 | R16: 1 | S16: Website (Data) | T16: 46241.849 | U16: 46241.849 | V16: S1 | W16: Thí sinh đã thanh toán | X16: Suất miễn phí | Y16: D1 · Chuẩn bị thi | AA16: Nhung | AB16: 9/8: em đang xem lại lịch thi, đang sx c ạ
A17: PT-008 | B17: Trịnh Thị Giang | C17: trinhthigiang@gmail.com | D17: 0760979192 | E17: Bảng B | F17: Hải Phòng | G17: School A | H17: Có | I17: Đã thanh toán | J17: 500000 | K17: Không | Q17: 1 | R17: 1 | S17: Website (Data) | T17: 46243.918 | U17: 46243.918 | V17: S1 | W17: Thí sinh đã thanh toán | X17: Đăng ký trực tiếp qua website | Y17: D1 · Chuẩn bị thi | AA17: Thắng | AB17: 11/8 tham gia talkshow
A18: PT-009 | B18: Hoàng Anh Yến | C18: hoanganhyen@gmail.com | D18: 0850046884 | E18: Bảng A | F18: TP. Hồ Chí Minh | G18: School A | H18: Có | I18: Đã thanh toán | J18: 500000 | K18: Không | Q18: 2 | R18: 2 | S18: Website (Data) | T18: 46249 | U18: 46249 | V18: S1 | W18: Thí sinh đã thanh toán | X18: Đăng ký trực tiếp qua website | Y18: D1 · Chuẩn bị thi | AA18: Thắng | AB18: đã liên hệ tư vấn và gửi tt || ko nghe máy đã nhắn zl - done
A19: PT-010 | B19: Trần Thanh Cường | C19: tranthanhcuong@gmail.com | D19: 0352306865 | E19: Bảng B | F19: Hà Nội | G19: School A | H19: Có | I19: Đã thanh toán | J19: 500000 | K19: Không | Q19: 1 | R19: 1 | S19: Website (Data) | T19: 46252.578 | U19: 46252.578 | V19: S1 | W19: Thí sinh đã thanh toán | X19: Đăng ký trực tiếp qua website | Y19: D1 · Chuẩn bị thi | AA19: Thắng | AB19: 18/8 ko nghe máy, nhắn zl
A20: PT-011 | B20: Đặng Thu Dũng | C20: dangthudung300@gmail.com | D20: 0903588324 | E20: Bảng B | F20: TP. Hồ Chí Minh | G20: School A | H20: Có | I20: Đã thanh toán | J20: 500000 | K20: Không | Q20: 1 | R20: 1 | S20: Website (Data) | T20: 46253.841 | U20: 46253.841 | V20: S1 | W20: Thí sinh đã thanh toán | X20: Đăng ký trực tiếp qua website | Y20: D1 · Chuẩn bị thi | AA20: Thắng | AB20: ko nghe máy đã nhắn zl
A21: PT-012 | B21: Phan Xuân Phong | C21: phanxuanphong@gmail.com | D21: 0358821581 | E21: Bảng B | F21: Hà Nội | G21: School A | H21: Có | I21: Đã thanh toán | J21: 500000 | K21: Không | Q21: 1 | R21: 1 | S21: Website (Data) | T21: 46254.71 | U21: 46254.71 | V21: S1 | W21: Thí sinh đã thanh toán | X21: Đăng ký trực tiếp qua website | Y21: D1 · Chuẩn bị thi | AB21: 258 đã gửi tt group và talkshow
A22: PT-013 | B22: Phạm Thu Phong | C22: phamthuphong108@gmail.com | D22: 0972909387 | E22: Bảng B | F22: TP. Hồ Chí Minh | G22: School A | H22: Có | I22: Đã thanh toán | J22: 500000 | K22: Có | L22: Có | N22: Có | P22: Chưa đăng ký vì còn thắc mắc | Q22: 4 | R22: 3 | S22: Website (Data), Talkshow Google Form | T22: 46253.875 | U22: 46254.849 | V22: S1 | W22: Thí sinh đã thanh toán | X22: Có tương tác Talkshow/FB | Y22: D1 · Chuẩn bị thi | AA22: Thắng | AB22: 21/8 knm, zl ko tìm thấy || DONE - EMAIL || tắt máy - ko tìm thấy zl | knm 27/08 thuê bao
A23: PT-014 | B23: Bùi Khánh Vinh | C23: buikhanhvinh2006@gmail.com | D23: 0705097972 | E23: Bảng B | F23: Hà Nội | G23: School A | H23: Có | I23: Đã thanh toán | J23: 500000 | K23: Không | Q23: 1 | R23: 1 | S23: Website (Data) | T23: 46254.86 | U23: 46254.86 | V23: S1 | W23: Thí sinh đã thanh toán | X23: Đăng ký trực tiếp qua website | Y23: D1 · Chuẩn bị thi | AB23: 25/8 ko nghe máy đã nhắn zl
A24: PT-015 | B24: Lâm Thị Lan | C24: lam48dcat446@student.ptithcm.edu.vn | D24: 0793842274 | E24: Bảng B | F24: TP. Hồ Chí Minh | G24: School A | H24: Có | I24: Đã thanh toán | J24: 500000 | K24: Không | Q24: 2 | R24: 2 | S24: Website (Data) | T24: 46258.409 | U24: 46258.409 | V24: S1 | W24: Thí sinh đã thanh toán | X24: Đăng ký trực tiếp qua website | Y24: D1 · Chuẩn bị thi | AB24: ko gọi đc 25/8 lại knm || done
A25: PT-016 | B25: Lê Hải Vy | C25: lehaivy924@gmail.com | D25: 0882266905 | E25: Bảng B | F25: TP. Hồ Chí Minh | G25: School A | H25: Có | I25: Đã thanh toán | J25: 500000 | K25: Có | L25: Có | N25: Có | O25: Không ạ | P25: Chưa đăng ký vì còn thắc mắc | Q25: 2 | R25: 1 | S25: Website (Data), Talkshow Google Form | T25: 46259.802 | U25: 46259.898 | V25: S1 | W25: Thí sinh đã thanh toán | X25: Có tương tác Talkshow/FB | Y25: D1 · Chuẩn bị thi | AA25: Đạt | AB25: 26/8 đã tư vấn || sẽ tham gia (27/8)
A26: PT-017 | B26: Đặng Xuân Giang | C26: dan51dcat637@student.ptithcm.edu.vn | D26: 0971445857 | E26: Bảng B | F26: TP. Hồ Chí Minh | G26: School A | H26: Có | I26: Đã thanh toán | J26: 500000 | K26: Không | Q26: 2 | R26: 2 | S26: Website (Data) | T26: 46260.322 | U26: 46260.322 | V26: S1 | W26: Thí sinh đã thanh toán | X26: Đăng ký trực tiếp qua website | Y26: D1 · Chuẩn bị thi | AB26: 26/8 knm, nhắn zl, có tham gia talkshow || done
A27: PT-018 | B27: Bùi Thị Trang | C27: buithitrang789@gmail.com | D27: 0376098703 | E27: Bảng B | F27: TP. Hồ Chí Minh | G27: School A | H27: Có | I27: Đã thanh toán | J27: 500000 | K27: Không | Q27: 1 | R27: 1 | S27: Website (Data) | T27: 46260.515 | U27: 46260.515 | V27: S1 | W27: Thí sinh đã thanh toán | X27: Đăng ký trực tiếp qua website | Y27: D1 · Chuẩn bị thi | AB27: 26/8 đã tư vấn
A28: PT-019 | B28: Tạ Thị Trang | C28: tathitrang409@gmail.com | D28: 0326795248 | E28: Bảng B | F28: Hà Nội | G28: School A | H28: Có | I28: Đã thanh toán | J28: 500000 | K28: Không | Q28: 1 | R28: 1 | S28: Website (Data) | T28: 46261.459 | U28: 46261.459 | V28: S1 | W28: Thí sinh đã thanh toán | X28: Đăng ký trực tiếp qua website | Y28: D1 · Chuẩn bị thi | AB28: tuần sau tham gia talkshow
A29: PT-020 | B29: Mai Gia Hải | C29: mai36dcat823@student.ptithcm.edu.vn | D29: 0388244141 | E29: Bảng B | F29: TP. Hồ Chí Minh | G29: School A | H29: Có | I29: Đã thanh toán | J29: 500000 | K29: Không | Q29: 1 | R29: 1 | S29: Website (Data) | T29: 46261.722 | U29: 46261.722 | V29: S1 | W29: Thí sinh đã thanh toán | X29: Đăng ký trực tiếp qua website | Y29: D1 · Chuẩn bị thi | AB29: done
A30: PT-021 | B30: Hoàng Hữu Bình | C30: hoa11dcat848@student.ptithcm.edu.vn | D30: 0846385642 | E30: Bảng B | F30: TP. Hồ Chí Minh | G30: School A | H30: Có | I30: Đã thanh toán | J30: 500000 | K30: Không | Q30: 1 | R30: 1 | S30: Website (Data) | T30: 46261.729 | U30: 46261.729 | V30: S1 | W30: Thí sinh đã thanh toán | X30: Đăng ký trực tiếp qua website | Y30: D1 · Chuẩn bị thi | AB30: done
A31: PT-022 | B31: Mai Hải Hiếu | C31: mai29dcvt741@student.ptithcm.edu.vn | D31: 0363873024 | E31: Bảng B | F31: TP. Hồ Chí Minh | G31: School A | H31: Có | I31: Đã thanh toán | J31: 500000 | K31: Không | Q31: 1 | R31: 1 | S31: Website (Data) | T31: 46262.608 | U31: 46262.608 | V31: S1 | W31: Thí sinh đã thanh toán | X31: Đăng ký trực tiếp qua website | Y31: D1 · Chuẩn bị thi | AB31: 28/8 đã liên hệ htro
A32: PT-023 | B32: Phan Anh Ngân | C32: phananhngan@gmail.com | D32: 0938895089 | E32: Bảng B | F32: TP. Hồ Chí Minh | G32: School A | H32: Có | I32: Đã thanh toán | J32: 500000 | K32: Có | M32: Có | N32: Có | Q32: 2 | R32: 1 | S32: Website (Data), FB Lead Form v2 | T32: 46252.902 | U32: 46263.057 | V32: S1 | W32: Thí sinh đã thanh toán | X32: Có tương tác Talkshow/FB | Y32: D1 · Chuẩn bị thi | AA32: Nhung | AB32: done || knm
A33: PT-024 | B33: Dương Hữu Nhi | C33: duonghuunhi93@gmail.com | D33: 0906532329 | E33: Bảng B | F33: TP. Hồ Chí Minh | G33: School A | H33: Có | I33: Đã thanh toán | J33: 500000 | K33: Có | L33: Có | N33: Có | P33: Chưa đăng ký vì còn thắc mắc | Q33: 2 | R33: 1 | S33: Website (Data), Talkshow Google Form | T33: 46259.826 | U33: 46263.383 | V33: S1 | W33: Thí sinh đã thanh toán | X33: Có tương tác Talkshow/FB | Y33: D1 · Chuẩn bị thi | Z33: Gộp nhiều email của cùng 1 người | AA33: Đạt | AB33: Nhung đã add zalo || sẽ tham gia (27/8)
A34: PT-025 | B34: Vũ Anh Duy | C34: vuanhduy@gmail.com | D34: 0914093541 | E34: Bảng B | F34: TP. Hồ Chí Minh | G34: School A | H34: Có | I34: Đã thanh toán | J34: 500000 | K34: Không | Q34: 1 | R34: 1 | S34: Website (Data) | T34: 46263.633 | U34: 46263.633 | V34: S1 | W34: Thí sinh đã thanh toán | X34: Đăng ký trực tiếp qua website | Y34: D1 · Chuẩn bị thi | AB34: done
A35: PT-026 | B35: Ngô Minh Nam | C35: ngominhnam2008@gmail.com | D35: 0799696057 | E35: Bảng B | F35: TP. Hồ Chí Minh | G35: School A | H35: Có | I35: Đã thanh toán | J35: 500000 | K35: Có | M35: Có | N35: Có | Q35: 3 | R35: 2 | S35: Website (Data), FB Lead Form v2 | T35: 46262.826 | U35: 46263.752 | V35: S1 | W35: Thí sinh đã thanh toán | X35: Có tương tác Talkshow/FB | Y35: D1 · Chuẩn bị thi | Z35: Tên viết khác nhau giữa các nguồn | AA35: Tùng | AB35: đã đk || done || đã call, đang cân nhắc
A36: PT-027 | B36: Trịnh Ngọc Hùng | C36: trinhngochung2007@gmail.com | D36: 0339830090 | E36: Bảng B | F36: TP. Hồ Chí Minh | G36: School A | H36: Có | I36: Đã thanh toán | J36: 500000 | K36: Không | Q36: 1 | R36: 1 | S36: Website (Data) | T36: 46263.755 | U36: 46263.755 | V36: S1 | W36: Thí sinh đã thanh toán | X36: Đăng ký trực tiếp qua website | Y36: D1 · Chuẩn bị thi | AB36: done
A37: PT-028 | B37: Phan Thu Huy | C37: phanthuhuy262@gmail.com | D37: 0908893679 | E37: Bảng B | F37: TP. Hồ Chí Minh | G37: School A | H37: Có | I37: Đã thanh toán | J37: 500000 | K37: Có | L37: Có | N37: Có | P37: Chưa đăng ký vì còn thắc mắc | Q37: 2 | R37: 1 | S37: Website (Data), Talkshow Google Form | T37: 46259.667 | U37: 46264.387 | V37: S1 | W37: Thí sinh đã thanh toán | X37: Có tương tác Talkshow/FB | Y37: D1 · Chuẩn bị thi | AA37: Đạt | AB37: done || knm
A38: PT-029 | B38: Ngô Ngọc Toàn | C38: ngongoctoan554@gmail.com | D38: 0394361551 | E38: Bảng B | F38: Hà Nội | G38: School A | H38: Có | I38: Đã thanh toán | J38: 500000 | K38: Có | M38: Có | N38: Có | Q38: 2 | R38: 1 | S38: Website (Data), FB Lead Form v2 | T38: 46264.381 | U38: 46264.72 | V38: S1 | W38: Thí sinh đã thanh toán | X38: Có tương tác Talkshow/FB | Y38: D1 · Chuẩn bị thi | AA38: Đạt | AB38: done || 15/09: đã đăng ký thi
A39: PT-030 | B39: Nguyễn Đức Thành | C39: ngu20dcpt440@student.ptithcm.edu.vn | D39: 0848208144 | E39: Bảng B | F39: TP. Hồ Chí Minh | G39: School A | H39: Có | I39: Đã thanh toán | J39: 500000 | K39: Không | Q39: 2 | R39: 2 | S39: Website (Data) | T39: 46264.787 | U39: 46264.787 | V39: S1 | W39: Thí sinh đã thanh toán | X39: Đăng ký trực tiếp qua website | Y39: D1 · Chuẩn bị thi | Z39: Gộp nhiều email của cùng 1 người | AB39: done
A40: PT-031 | B40: Đinh Minh Phúc | C40: dinhminhphuc@gmail.com | D40: 0814662764 | E40: Bảng B | F40: TP. Hồ Chí Minh | G40: School A | H40: Có | I40: Đã thanh toán | J40: 500000 | K40: Có | L40: Có | N40: Có | P40: Đã đăng ký | Q40: 2 | R40: 1 | S40: Website (Data), Talkshow Google Form | T40: 46265.903 | U40: 46265.903 | V40: S1 | W40: Thí sinh đã thanh toán | X40: Có tương tác Talkshow/FB | Y40: D1 · Chuẩn bị thi | AA40: Đạt | AB40: done
A41: PT-032 | B41: Phạm Anh Toàn | C41: phamanhtoan2005@gmail.com | D41: 0777140507 | E41: Bảng B | F41: Hà Nội | G41: School A | H41: Có | I41: Đã thanh toán | J41: 650000 | K41: Không | Q41: 1 | R41: 1 | S41: Website (Data) | T41: 46267.646 | U41: 46267.646 | V41: S1 | W41: Thí sinh đã thanh toán | X41: Đăng ký trực tiếp qua website | Y41: D1 · Chuẩn bị thi | AB41: done
...

Sheet Main_Signups_Clean
A1: MAIN_SIGNUPS_CLEAN — Làm sạch dữ liệu website (sheet Data)
A2: • Nguyên tắc vàng: KHÔNG xoá dòng gốc, chỉ gắn cờ Giữ / Trùng – đã gộp để truy ngược được.
A3: • 132 dòng thô → 119 người duy nhất, do nhiều người điền form nhiều lần.
A4: • Mỗi trường có 2 cột: bản gốc và bản chuẩn hoá, để so sánh logic làm sạch.
A5: • Tên trường có 42 cách viết (PTIT, Học viện CNBCVT, ptit hcm...) → quy về danh mục chuẩn School A.
A6: • Email và SĐT: bỏ khoảng trắng, sửa tên miền gõ nhầm (.con thành .com), đưa SĐT về 10 số.
A8: Dòng gốc (Data) | B8: Contact ID | C8: Giữ/Trùng | D8: Thời gian đăng ký | E8: Họ tên (chuẩn hoá) | F8: Họ tên (gốc) | G8: Email (chuẩn hoá) | H8: Email (gốc) | I8: SĐT (chuẩn hoá) | J8: SĐT (gốc) | K8: Bảng | L8: Khu vực (chuẩn hoá) | M8: Trường (chuẩn hoá) | N8: Trường (gốc) | O8: Ngày sinh | P8: Số CCCD | Q8: Lệ phí | R8: payment_status | S8: Partner | T8: Mã khuyến mãi | U8: PIC | V8: Ghi chú
A9: 2 | B9: PT-001 | C9: Trùng – đã gộp | D9: 46224.758 | E9: Dương Hoài Nam | F9: Dương Hoài Nam | G9: duonghoainam380@gmail.com | H9: duonghoainam380@gmail.com | I9: 0833008389 | J9: 0833008389 | K9: Bảng B | L9: Hà Nội | M9: School A | N9: Học viện Công nghệ Bưu Chính Viễn Thông - PTIT. | O9: 2006-09-26 | P9: 024710530855 | Q9: 500000 | R9: chưa thanh toán | U9: Nhung | V9: knm 27/7 knm 29/7: hôm đó kick off mn bảo vào đăng ký thử nên em đk thử thôi ạ 31/7: trùng thông tin đã completed bên dưới
A10: 3 | B10: PT-078 | C10: Giữ | D10: 46224.923 | E10: Nguyễn Thanh Trí | F10: Nguyễn Thanh Trí | G10: nguyenthanhtri2007@gmail.com | H10: nguyenthanhtri2007@gmail.com | I10: 0779692414 | J10: 0779692414 | K10: Bảng B | L10: Hà Nội | M10: School A | N10: PTIT | O10: 2003-12-02 | P10: 075850422787 | Q10: 500000 | R10: chưa thanh toán | U10: Nhung | V10: knm gọi lại: ai lấy thông tin của em ấy, chứ em không đăng ký ạ
A11: 4 | B11: PT-002 | C11: Giữ | D11: 46225.376 | E11: Mai Minh Sơn | F11: Mai Minh Sơn | G11: maiminhson2005@gmail.com | H11: maiminhson2005@gmail.com | I11: 0884396213 | J11: 0884396213 | K11: Bảng B | L11: Hà Nội | M11: School A | N11: Học viện Công nghệ Bưu chính Viễn thông - PTIT | O11: 2007-01-10 | P11: 027887450948 | Q11: 500000 | R11: completed | U11: Nhung | V11: done => chặn
A12: 5 | B12: PT-079 | C12: Giữ | D12: 46225.396 | E12: Trịnh Thanh Khang | F12: Trịnh Thanh Khang | G12: trinhthanhkhang16@gmail.com | H12: trinhthanhkhang16@gmail.com | I12: 0334696188 | J12: 0334696188 | K12: Bảng B | L12: Hà Nội | M12: School A | N12: Học viện Công nghệ Bưu Chính Viễn Thông - PTIT | O12: 2007-05-18 | P12: 024818014407 | Q12: 500000 | R12: chưa thanh toán | U12: Nhung | V12: thuê bao | knm
A13: 6 | B13: PT-118 | C13: Giữ | E13: Võ Tuấn Quyên | F13: Võ Tuấn Quyên | G13: votuanquyen@gmail.com | H13: votuanquyen@gmail.com | I13: 0829437580 | J13: 0829437580 | K13: Bảng B | L13: Hà Nội | M13: School A | N13: Học viện Công nghệ Bưu chính Viễn thông | O13: 8/9/2004 | P13: 052116512260 | Q13: 500000 | R13: chưa thanh toán | U13: Nhung | V13: em k đk thi, đang đi làm, o có thời gian
A14: 7 | B14: PT-119 | C14: Giữ | E14: Trịnh Hải Cường | F14: Trịnh Hải Cường | G14: trinhhaicuong2006@gmail.com | H14: trinhhaicuong2006@gmail.com | I14: 0768196891 | J14: 0768196891 | K14: Bảng B | L14: Hà Nội | M14: School A | N14: Học viện Công nghệ Bưu chính Viễn thông | O14: 12/24/2006 | P14: 079578843251 | Q14: 500000 | R14: chưa thanh toán | U14: Nhung | V14: knm 27/07 KNM l2 29/7: tắt máy | zl => cancel
A15: 8 | B15: PT-080 | C15: Giữ | D15: 46230.601 | E15: Trịnh Xuân Linh | F15: Trịnh Xuân Linh | G15: trinhxuanlinh@gmail.com | H15: trinhxuanlinh@gmail.com | I15: 0766116381 | J15: 0766116381 | K15: Bảng B | L15: Hà Nội | M15: School A | N15: PTIT | O15: 2005-05-28 | P15: 038204366965 | Q15: 500000 | R15: chưa thanh toán | U15: Thắng | V15: 27/7: đã tư vấn về cuộc thi, lệ phí thi, thời gian, gửi tt qua zl | cancel
A16: 9 | B16: PT-003 | C16: Giữ | D16: 46233.521 | E16: Phạm Hoài Giang | F16: Phạm Hoài Giang | G16: pha79dcat944@stu.ptit.edu.vn | H16: pha79dcat944@stu.ptit.edu.vn | I16: 0886855032 | J16: 0886855032 | K16: Bảng B | L16: Hà Nội | M16: School A | N16: Học viện Công nghệ Bưu chính Viễn thông - PTIT | O16: 2006-08-22 | P16: 027341481757 | Q16: 500000 | R16: completed | U16: Thắng | V16: 30/7 đã nhận mail
A17: 10 | B17: PT-004 | C17: Trùng – đã gộp | D17: 46234.419 | E17: Hồ Hữu Vy | F17: Hồ Hữu Vy | G17: hoh43dcpt729@stu.ptit.edu.vn | H17: hoh43dcpt729@stu.ptit.edu.vn | I17: 0762989538 | J17: 0762989538 | K17: Bảng B | L17: Hà Nội | M17: School A | N17: Học viện Công Nghệ Bưu Chính Viễn Thông - PTIT | O17: 2006-03-22 | P17: 068471846224 | Q17: 500000 | R17: chưa thanh toán | U17: Nhung | V17: TRÙNG DATA DƯỚI, ĐÃ COMPLETED 31/7: tắt máy đã ping zzl
A18: 11 | B18: PT-001 | C18: Giữ | D18: 46234.448 | E18: Dương Hoài Nam | F18: Dương Hoài Nam | G18: duonghoainam380@gmail.com | H18: duonghoainam380@gmail.com | I18: 0833008389 | J18: 0833008389 | K18: Bảng B | L18: Hà Nội | M18: School A | N18: Học viện Công nghệ Bưu Chính Viễn Thông - PTIT | O18: 2006-09-26 | P18: 024710530855 | Q18: 500000 | R18: completed | U18: Thắng | V18: 31/7 add zl htro thêm
A19: 12 | B19: PT-004 | C19: Giữ | D19: 46234.641 | E19: Hồ Hữu Vy | F19: Hồ Hữu Vy | G19: hoh43dcpt729@stu.ptit.edu.vn | H19: hoh43dcpt729@stu.ptit.edu.vn | I19: 0762989538 | J19: 0762989538 | K19: Bảng B | L19: Hà Nội | M19: School A | N19: Học viện Công nghệ Bưu Chính Viễn Thông - PTIT. | O19: 2006-03-22 | P19: 068471846224 | Q19: 500000 | R19: completed | U19: Nhung
A20: 13 | B20: PT-081 | C20: Giữ | D20: 46234.962 | E20: Hồ Thị Phong | F20: Hồ Thị Phong | G20: hothiphong@gmail.com | H20: hothiphong@gmail.com | I20: 0819654799 | J20: 0819654799 | K20: Bảng B | L20: Đồng Tháp | M20: School A | N20: PTIT | O20: 2007-03-30 | P20: 096094659432 | Q20: 500000 | R20: chưa thanh toán | U20: Nhung | V20: 2/8: tắt máy | knm
A21: 14 | B21: PT-005 | C21: Giữ | D21: 46236.908 | E21: Võ Phương Phúc | F21: Võ Phương Phúc | G21: vophuongphuc@gmail.com | H21: vophuongphuc@gmail.com | I21: 0826162603 | J21: 0826162603 | K21: Bảng B | L21: Hà Nội | M21: School A | N21: PTIT | O21: 2006-11-09 | P21: 038734017039 | Q21: 500000 | R21: completed | U21: Thắng | V21: 3/8 gọi 2 cuộc ko đc, nhắn zl
A22: 15 | B22: PT-082 | C22: Giữ | D22: 46238.438 | E22: Bùi Xuân Khoa | F22: Bùi Xuân Khoa | G22: buixuankhoa@gmail.com | H22: buixuankhoa@gmail.com | I22: 0395888153 | J22: 0395888153 | K22: Bảng B | L22: TP. Hồ Chí Minh | M22: School A | N22: Học viện Công nghệ Bưu chính Viễn thông Cơ sở Thành phố Hồ Chí Minh | O22: 2006-08-09 | P22: 077441807738 | Q22: 500000 | R22: chưa thanh toán | U22: Thắng | V22: 4/6 thay đổi định hướng nên ko tham gia nữa
A23: 16 | B23: PT-006 | C23: Giữ | D23: 46239.617 | E23: Phạm Khánh Hoa | F23: Phạm Khánh Hoa | G23: phamkhanhhoa@gmail.com | H23: phamkhanhhoa@gmail.com | I23: 0818360186 | J23: 0818360186 | K23: Bảng B | L23: Hà Nội | M23: School A | N23: Học viện công nghệ bưu chính viễn thông | O23: 2006-06-12 | P23: 089033348421 | Q23: 500000 | R23: completed | U23: Thắng | V23: 5/8 knm nhắn zl 6/8 gọi knm đã đăng kí
A24: 17 | B24: PT-083 | C24: Giữ | D24: 46241.666 | E24: Đinh Xuân Mai | F24: Đinh Xuân Mai | G24: dinhxuanmai778@gmail.com | H24: dinhxuanmai778@gmail.com | I24: 0911519426 | J24: 0911519426 | K24: Bảng B | L24: Bắc Ninh | M24: School A | N24: Học viện công nghệ bưu chính viễn thông | O24: 2007-01-06 | P24: 089063735143 | Q24: 500000 | R24: chưa thanh toán | U24: Thắng | V24: tháng 10 thì tham gia đc, tối tham gia talk show | knm
A25: 18 | B25: PT-084 | C25: Giữ | D25: 46241.761 | E25: Dương Xuân Hùng | F25: Dương Xuân Hùng | G25: duongxuanhung@gmail.com | H25: duongxuanhung@gmail.com | I25: 0912718917 | J25: 0912718917 | K25: Bảng B | L25: Hà Nội | M25: School A | N25: PTIT | O25: 2003-06-25 | P25: 027064967593 | Q25: 500000 | R25: chưa thanh toán | U25: Nhung | V25: 9/8: e sắp đi nc. ngoài rồi c ạ nên k tg, bạn e bảo bấm thử thui
A26: 19 | B26: PT-085 | C26: Giữ | D26: 46241.763 | E26: Dang Son | F26: dang son | G26: dangquangson2007@gmail.com | H26: dangquangson2007@gmail.com | I26: 0330188487 | J26: 0330188487 | K26: Bảng B | L26: Hà Nội | M26: School A | N26: Học viện Công nghệ Bưu Chính Viễn Thông - PTIT. | O26: 2007-08-07 | P26: 036685267442 | Q26: 500000 | R26: chưa thanh toán | U26: Thắng | V26: 9/8: sai số
A27: 20 | B27: PT-086 | C27: Giữ | D27: 46241.83 | E27: Tạ Trung Quân | F27: Tạ Trung Quân | G27: tatrungquan2008@gmail.com | H27: tatrungquan2008@gmail.com | I27: 0967618918 | J27: 0967618918 | K27: Bảng B | L27: Hà Nội | M27: School A | N27: PTIT | O27: 2006-02-02 | P27: 042565509399 | Q27: 500000 | R27: chưa thanh toán | U27: Thắng | V27: 9/8 sai số
A28: 21 | B28: PT-007 | C28: Giữ | D28: 46241.849 | E28: Lâm Hoài Yến | F28: Lâm Hoài Yến | G28: lamhoaiyen@gmail.com | H28: lamhoaiyen@gmail.com | I28: 0828797715 | J28: 0828797715 | K28: Bảng B | L28: Hà Nội | M28: School A | N28: Học viện Công nghệ Bưu Chính Viễn Thông - PTIT. | O28: 2006-09-18 | P28: 036861826221 | Q28: 500000 | R28: free | S28: info | U28: Nhung | V28: 9/8: em đang xem lại lịch thi, đang sx c ạ
A29: 22 | B29: PT-008 | C29: Giữ | D29: 46243.918 | E29: Trịnh Thị Giang | F29: Trịnh Thị Giang | G29: trinhthigiang@gmail.com | H29: trinhthigiang@gmail.com | I29: 0760979192 | J29: 0760979192 | K29: Bảng B | L29: Hải Phòng | M29: School A | N29: Học viện Công nghệ Bưu Chính Viễn Thông -PTIT | O29: 2007-01-08 | P29: 042451832242 | Q29: 500000 | R29: completed | U29: Thắng | V29: 11/8 tham gia talkshow
A30: 23 | B30: PT-087 | C30: Giữ | D30: 46245.952 | E30: Vu Ngan | F30: vu ngan | G30: vubaongan@wrold.cm | H30: vubaongan@wrold.cm | I30: 0976703934 | J30: 0976703934 | K30: Bảng B | L30: Hà Nội | M30: School A | N30: Học viện Công nghệ Bưu Chính Viễn Thông - PTIT | O30: 2006-06-07 | P30: 068977255989 | Q30: 500000 | R30: chưa thanh toán | U30: Thắng | V30: 12/8 sai tt
A31: 24 | B31: PT-088 | C31: Giữ | D31: 46246.427 | E31: Trịnh Gia Hoa | F31: Trịnh Gia Hoa | G31: trinhgiahoa220@gmail.com | H31: trinhgiahoa220@gmail.com | I31: 0886010172 | J31: 0886010172 | K31: Bảng B | L31: Hà Nội | M31: School A | N31: Học viện Công nghệ Bưu Chính Viễn Thông | O31: 2005-08-02 | P31: 001658978524 | Q31: 500000 | R31: chưa thanh toán | U31: Thắng | V31: 12/8 đki thử thôi chứ ko tham gia
A32: 25 | B32: PT-089 | C32: Giữ | D32: 46246.474 | E32: Le Phuc | F32: Le Phuc | G32: levanphuc832@msa.com | H32: levanphuc832@msa.com | I32: 0972473963 | J32: 0972473963 | K32: Bảng B | L32: TP. Hồ Chí Minh | M32: School A | N32: Bưu chính | O32: 2002-10-15 | P32: 86054456262 | Q32: 500000 | R32: chưa thanh toán | U32: Nhung | V32: 13/08 bạn này có vẻ đk bừa, check zl người lớn tuổi
A33: 26 | B33: PT-090 | C33: Giữ | D33: 46246.658 | E33: Lâm Văn Khôi | F33: Lâm Văn Khôi | G33: lam78dcvt270@student.ptithcm.edu.vn | H33: lam78dcvt270@student.ptithcm.edu.vn | I33: 0781062700 | J33: 0781062700 | K33: Bảng B | L33: TP. Hồ Chí Minh | M33: School A | N33: PTITHCM | O33: 2003-02-10 | P33: 082873820582 | Q33: 500000 | R33: chưa thanh toán | U33: Thắng | V33: đã tư vấn và gửi tt
A34: 27 | B34: PT-091 | C34: Giữ | D34: 46248.546 | E34: Đặng Trung An | F34: Đặng Trung An | G34: dangtrungan2006@gmail.com | H34: dangtrungan2006@gmail.com | I34: 0960963315 | J34: 0960963315 | K34: Bảng B | L34: Phú Thọ | M34: School A | N34: Học viện Công Nghệ Bưu Chính Viễn Thông - PTIT | O34: 2008-10-28 | P34: 056286856489 | Q34: 500000 | R34: chưa thanh toán | S34: info | U34: Nhung | V34: 15/8 KNM
A35: 28 | B35: PT-092 | C35: Giữ | D35: 46248.833 | E35: Mai Toan | F35: mai toan | G35: maingoctoan931@gmail.com | H35: maingoctoan931@gmail.com | I35: 0972723624 | J35: 0972723624 | K35: Bảng B | L35: Hà Nội | M35: School A | N35: PTIT | O35: 1978-07-06 | P35: 033519738122 | Q35: 500000 | R35: chưa thanh toán | U35: Nhung
A36: 29 | B36: PT-009 | C36: Trùng – đã gộp | D36: 46249 | E36: Hoàng Anh Yến | F36: Hoàng Anh Yến | G36: hoanganhyen@gmail.com | H36: hoanganhyen@gmail.com | I36: 0850046884 | J36: 0850046884 | K36: Bảng B | L36: TP. Hồ Chí Minh | M36: School A | N36: Học viện Công nghệ Bưu chính Viễn Thông HCM | O36: 2008-01-07 | P36: 038144692928 | Q36: 500000 | R36: chưa thanh toán | U36: Thắng | V36: đã liên hệ tư vấn và gửi tt
A37: 30 | B37: PT-093 | C37: Giữ | D37: 46249.781 | E37: Phạm Tuấn Phong | F37: Phạm Tuấn Phong | G37: phamtuanphong@gmail.com | H37: phamtuanphong@gmail.com | I37: 0337151048 | J37: 0337151048 | K37: Bảng B | L37: Hà Nội | M37: School A | N37: Học viện Công nghệ bưu chính Viễn Thông | O37: 2006-10-17 | P37: 031978401987 | Q37: 500000 | R37: chưa thanh toán | U37: Thắng | V37: đã liên hệ tư vấn và gửi tt | knm
A38: 31 | B38: PT-094 | C38: Giữ | D38: 46250.865 | E38: Lý Thị An | F38: Lý Thị An | G38: lythian5@gmail.com | H38: lythian5@gmail.com | I38: 0989261898 | J38: 0989261898 | K38: Bảng B | L38: Hà Nội | M38: School A | N38: Học viện công nghệ Bưu Chính Viễn Thông | O38: 2005-02-27 | P38: 042549995310 | Q38: 500000 | R38: chưa thanh toán | U38: Thắng | V38: 17/8 thuê bao, nhắn zl | tb
A39: 32 | B39: PT-095 | C39: Giữ | D39: 46251.582 | E39: Phan Thanh Vy | F39: Phan Thanh Vy | G39: phanthanhvy627@gmail.com | H39: phanthanhvy627@gmail.com | I39: 0829505190 | J39: 0829505190 | K39: Bảng B | L39: Hà Nội | M39: School A | N39: ptit | O39: 2000-02-10 | P39: 148587061 | Q39: 500000 | R39: chưa thanh toán | U39: Thắng | V39: sai số máy
A40: 33 | B40: PT-010 | C40: Giữ | D40: 46252.578 | E40: Trần Thanh Cường | F40: Trần Thanh Cường | G40: tranthanhcuong@gmail.com | H40: tranthanhcuong@gmail.com | I40: 0352306865 | J40: 0352306865 | K40: Bảng B | L40: Hà Nội | M40: School A | N40: Học viện Công nghệ Bưu chính Viễn thông | O40: 2005-01-14 | P40: 049921687524 | Q40: 500000 | R40: completed | U40: Thắng | V40: 18/8 ko nghe máy, nhắn zl
A41: 34 | B41: PT-067 | C41: Giữ | D41: 46253.764 | E41: Lâm Văn Thủy | F41: Lâm Văn Thủy | G41: lamvanthuy@gmail.com | H41: lamvanthuy@gmail.com | I41: 0768634349 | J41: 0768634349 | K41: Bảng B | L41: TP. Hồ Chí Minh | M41: School A | N41: Học Viện Công Nghệ Bưu Chính Viễn Thông | O41: 2007-04-20 | P41: 087283329195 | Q41: 500000 | R41: chưa thanh toán | U41: Thắng | V41: 20/8 ko nghe máy đã nhắn zl | knm
...

Sheet External_Leads_Clean
A1: EXTERNAL_LEADS_CLEAN - Lead từ Talkshow Google Form & FB Lead Form
A2: • Lead kênh ngoài phải đối chiếu với Data trước khi nhập CRM, nếu không sẽ sinh hồ sơ trùng.
A3: • 3 kết quả: đã có trong Data, trùng trong file ngoài (điền form 2 lần), hoặc giữ vì là lead mới.
A4: • Gộp không làm mất dữ liệu: lịch sử Talkshow/FB vẫn nằm ở cột Nguồn dữ liệu của Master_Contacts.
A5: • Cạm bẫy: cùng 1 người nhưng email viết hoa, sai tên miền, SĐT dạng +84, tên không dấu.
A6: • Tự khai “Đã đăng ký” nhưng không có trong Data thì phải xác minh, không mặc nhiên coi là thí sinh.
A8: Nguồn | B8: Dòng gốc | C8: Contact ID | D8: Kết quả làm sạch | E8: Segment | F8: Thời gian | G8: Họ tên (chuẩn hoá) | H8: Họ tên (gốc) | I8: Email (chuẩn hoá) | J8: Email (gốc) | K8: SĐT (chuẩn hoá) | L8: SĐT (gốc) | M8: Bảng quan tâm | N8: Khu vực (chuẩn hoá) | O8: Trường (gốc) | P8: Muốn nhận lịch Talkshow | Q8: Tự khai đã đăng ký | R8: Câu hỏi | S8: Campaign / Kênh | T8: PIC | U8: Ghi chú
A9: FB Lead Form v2 | B9: 2 | C9: PT-132 | D9: Giữ (lead mới) | E9: S5 | F9: 46248.069 | G9: Duong Ngoc Binh | H9: Duong Ngoc Binh | I9: duongngocbinh986@gmail.com | J9: duongngocbinh986@gmail.com | K9: 0962519652 | L9: p:+84962519652 | M9: Bảng B | N9: TP. Hồ Chí Minh | P9: Không | S9: 1808 Lead | Uni | T9: Thắng | U9: 16/9 ko nghe máy đã nhắn zl
A10: FB Lead Form v2 | B10: 3 | C10: PT-075 | D10: Đã có trong Data – gộp vào hồ sơ | E10: S2 | F10: 46260.367 | G10: Đặng Long | H10: Đặng Long | I10: danganhlong@gmail.com | J10: danganhlong@gmail.com | K10: 0364050093 | L10: p:+84364050093 | M10: Bảng B | N10: Hà Nội | P10: Có | S10: PM 1808 | SuperAds test3
A11: FB Lead Form v2 | B11: 4 | C11: PT-026 | D11: Đã có trong Data – gộp vào hồ sơ | E11: S1 | F11: 46262.826 | G11: Ngo Minh Nam | H11: Ngo Minh Nam | I11: ngominhnam2008@gmail.com | J11: ngominhnam2008@gmail.con | K11: 0799696057 | L11: p:+84799696057 | M11: Bảng B | N11: Hà Nội | P11: Có | S11: 1808 Lead | Uni | T11: Tùng | U11: đã call, đang cân nhắc
A12: FB Lead Form v2 | B12: 5 | C12: PT-077 | D12: Đã có trong Data – gộp vào hồ sơ | E12: S2 | F12: 46267.738 | G12: Lê An | H12: Lê An | I12: lekhanhan827@gmail.com | J12: lekhanhan827@gmail.com | K12: 0378513033 | L12: p:+84378513033 | M12: Bảng B | N12: Hà Nội | P12: Có | S12: Bạn không có đủ quyền. Vui lòng tham khảo trợ giúp sau: https://www.facebook.com/business/help/766393076839635 | T12: Đạt | U12: 7/9: đã gửi link ts qua zalo
A13: FB Lead Form v2 | B13: 6 | C13: PT-142 | D13: Giữ (lead mới) | E13: S5 | F13: 46270.557 | G13: Phạm Thu Phúc | H13: Phạm Thu Phúc | I13: phamthuphuc@gmail.com | J13: phamthuphuc@gmail.com | K13: 0783504437 | L13: p:+84783504437 | M13: Bảng B | N13: Hà Nội | P13: Có | S13: PM 0808 | SuperAd test DN -> HCM | T13: Thắng | U13: knm
A14: FB Lead Form v2 | B14: 7 | C14: PT-131 | D14: Giữ (lead mới) | E14: S5 | F14: 46247.193 | G14: Do Bao Thao | H14: Do Bao Thao | I14: dobaothao@icloud.com | J14: dobaothao@icloud.com | K14: 0357780225 | L14: p:+84357780225 | M14: Bảng B | N14: Đà Nẵng | P14: Có | S14: SuperAd test2
A15: FB Lead Form v2 | B15: 8 | C15: PT-144 | D15: Giữ (lead mới) | E15: S5 | F15: 46271.786 | G15: Võ Phương Phong | H15: Võ Phương Phong | I15: vophuongphong572@gmail.com | J15: vophuongphong572@gmail.com | K15: 0831590359 | L15: p:+84831590359 | M15: Bảng B | N15: Hà Nội | P15: Có | S15: PM 0808 | SuperAd test DN -> HCM | T15: Nhung
A16: FB Lead Form v2 | B16: 9 | C16: PT-067 | D16: Đã có trong Data – gộp vào hồ sơ | E16: S2 | F16: 46250.849 | G16: Lam Van Thuy | H16: Lam Van Thuy | I16: lamvanthuy@gmail.com | J16: lamvanthuy@gmail.com | K16: 0768634349 | L16: p:+84768634349 | M16: Bảng B | N16: TP. Hồ Chí Minh | P16: Có | S16: SuperAd test2 | T16: Tùng | U16: em chưa join TS, add zl gửi tt tư vấn
A17: FB Lead Form v2 | B17: 10 | C17: PT-130 | D17: Giữ (lead mới) | E17: S5 | F17: 46246.704 | G17: Dang Duc Ngan | H17: Dang Duc Ngan | I17: dangducngan@icloud.com | J17: dangducngan@icloud.com | K17: 0886556000 | L17: p:+84886556000 | M17: Bảng B | N17: Hà Nội | P17: Có | S17: 1808 Lead | Uni | T17: Nhung | U17: ng dùng bận
A18: FB Lead Form v2 | B18: 11 | C18: PT-133 | D18: Giữ (lead mới) | E18: S5 | F18: 46248.527 | G18: Do Duc Cuong | H18: Do Duc Cuong | I18: doduccuong317@gmail.com | J18: doduccuong317@gmail.com | K18: 0381290678 | L18: p:+84381290678 | M18: Bảng A | N18: Hà Nội | P18: Có | S18: PM 0808 | SuperAd test DN -> HCM | T18: Nhung | U18: đã gửi tt zalo
A19: FB Lead Form v2 | B19: 12 | C19: PT-133 | D19: Trùng trong file ngoài – gộp | E19: S5 | F19: 46248.527 | G19: Do Duc Cuong | H19: Do Duc Cuong | I19: doduccuong317@gmail.com | J19: doduccuong317@gmail.com | K19: 0381290678 | L19: p:+84381290678 | M19: Bảng A | N19: Hà Nội | P19: Có | S19: PM 0808 | SuperAd test DN -> HCM | T19: Nhung | U19: đã gửi tt zalo
A20: FB Lead Form v2 | B20: 13 | C20: PT-140 | D20: Giữ (lead mới) | E20: S5 | F20: 46264.138 | G20: Hoàng Thanh Phúc | H20: Hoàng Thanh Phúc | I20: hoangthanhphuc@icloud.com | J20: hoangthanhphuc@icloud.com | K20: 0975436752 | L20: p:+84975436752 | M20: Bảng A | N20: Đà Nẵng | P20: Có | S20: PM 0808 | SuperAd test DN -> HCM | T20: Nhung | U20: knm
A21: FB Lead Form v2 | B21: 14 | C21: PT-135 | D21: Giữ (lead mới) | E21: S5 | F21: 46253.357 | G21: Ngo Minh Thuy | H21: Ngo Minh Thuy | I21: ngominhthuy@gmail.com | J21: ngominhthuy@gmail.com | K21: 0964811740 | L21: p:+84964811740 | M21: Bảng A | N21: TP. Hồ Chí Minh | P21: Không | S21: PM 0808 | SuperAd test DN -> HCM | T21: Thắng | U21: đã gửi tt zalo
A22: FB Lead Form v2 | B22: 15 | C22: PT-141 | D22: Giữ (lead mới) | E22: S5 | F22: 46268.485 | G22: Hồ Minh Trí | H22: Hồ Minh Trí | I22: hominhtri906@gmail.com | J22: hominhtri906@gmail.com | K22: 0947542540 | L22: p:+84947542540 | M22: Bảng B | N22: Hà Nội | P22: Không | S22: 1808 Lead | Uni | T22: Thắng | U22: 16/9 ko nghe máy đã nhắn zl
A23: FB Lead Form v2 | B23: 16 | C23: PT-139 | D23: Giữ (lead mới) | E23: S5 | F23: 46261.225 | G23: Trần Hữu Thịnh | H23: Trần Hữu Thịnh | I23: tranhuuthinh@gmail.com | J23: tranhuuthinh@gmail.com | K23: 0811382637 | L23: p:+84811382637 | M23: Bảng B | N23: Hà Nội | P23: Có | S23: SuperAd test2 | T23: Nhung | U23: đã gửi tt zalo | 16/9 ko nghe máy đã nhắn zl
A24: FB Lead Form v2 | B24: 17 | C24: PT-035 | D24: Đã có trong Data – gộp vào hồ sơ | E24: S1 | F24: 46270.571 | G24: Hoàng Dũng | H24: Hoàng Dũng | I24: hoanganhdung.0409@gmail.com | J24: hoanganhdung.0409@gmail.com | K24: 0975711221 | L24: p:+84975711221 | M24: Bảng B | N24: Hà Nội | P24: Có | S24: SuperAd test2 | T24: Nhung | U24: đã call, đang cân nhắc
A25: FB Lead Form v2 | B25: 18 | C25: PT-069 | D25: Đã có trong Data – gộp vào hồ sơ | E25: S2 | F25: 46254.565 | G25: Ngô Khôi | H25: Ngô Khôi | I25: ngotrungkhoi@gmail.com | J25: ngotrungkhoi@gmail.com | K25: 0849573862 | L25: p:+84849573862 | M25: Bảng B | N25: Hà Nội | P25: Không | S25: SuperAd test2 - Copy | T25: Thắng | U25: knm
A26: FB Lead Form v2 | B26: 19 | C26: PT-070 | D26: Đã có trong Data – gộp vào hồ sơ | E26: S2 | F26: 46259.387 | G26: Trần Phương Tú | H26: Trần Phương Tú | I26: tranphuongtu2005@gmail.com | J26: tranphuongtu2005@gmail.com | K26: 0943210536 | L26: p:+84943210536 | M26: Bảng B | N26: Hà Nội | P26: Có | S26: PM 1808 | SuperAds test3 | T26: Thắng
A27: FB Lead Form v2 | B27: 20 | C27: PT-143 | D27: Giữ (lead mới) | E27: S5 | F27: 46270.689 | G27: Tạ Trung Thịnh | H27: Tạ Trung Thịnh | I27: tatrungthinh2007@icloud.com | J27: tatrungthinh2007@icloud.com | K27: 0320112955 | L27: p:+84320112955 | M27: Bảng B | N27: TP. Hồ Chí Minh | P27: Có | S27: SuperAd test2 | U27: knm
A28: FB Lead Form v2 | B28: 21 | C28: PT-076 | D28: Đã có trong Data – gộp vào hồ sơ | E28: S2 | F28: 46250.827 | G28: Hoàng Lâm | H28: Hoàng Lâm | I28: hoangphuonglam@gmail.com | J28: hoangphuonglam@gmail.com | K28: 0700926088 | L28: p:+84700926088 | M28: Bảng B | N28: TP. Hồ Chí Minh | P28: Có | S28: SuperAd test2 | T28: Thắng | U28: 18/8 ko nghe máy, nhắn zl
A29: FB Lead Form v2 | B29: 22 | C29: PT-134 | D29: Giữ (lead mới) | E29: S5 | F29: 46253.173 | G29: Vo Hai Trang | H29: Vo Hai Trang | I29: vohaitrang2004@gmail.com | J29: vohaitrang2004@gmail.con | K29: 0918000166 | L29: p:+84918000166 | M29: Bảng B | N29: Hà Nội | P29: Có | S29: 1808 Lead | Uni | T29: Thắng | U29: 16/9 ko nghe máy đã nhắn zl
A30: FB Lead Form v2 | B30: 23 | C30: PT-029 | D30: Đã có trong Data – gộp vào hồ sơ | E30: S1 | F30: 46264.381 | G30: Ngô Ngọc Toàn | H30: Ngô Ngọc Toàn | I30: ngongoctoan554@gmail.com | J30: ngongoctoan554@gmail.com | K30: 0394361551 | L30: p:+84394361551 | M30: Bảng B | N30: Hà Nội | P30: Có | T30: Đạt | U30: 15/09: đã đăng ký thi
A31: FB Lead Form v2 | B31: 24 | C31: PT-040 | D31: Đã có trong Data – gộp vào hồ sơ | E31: S1 | F31: 46257.823 | G31: Trinh Quyen | H31: Trinh Quyen | I31: trinhhaiquyen2007@gmail.com | J31: trinhhaiquyen2007@gmail.com | K31: 0963060225 | L31: p:+84963060225 | M31: Bảng B | N31: Miền Nam | P31: Không | S31: 2208| SuperAds 4 | T31: Thắng
A32: FB Lead Form v2 | B32: 25 | C32: PT-136 | D32: Giữ (lead mới) | E32: S5 | F32: 46256.735 | G32: Đỗ Khánh Giang | H32: Đỗ Khánh Giang | I32: dokhanhgiang2005@gmail.com | J32: dokhanhgiang2005@gmail.com | K32: 0773082635 | L32: p:+84773082635 | M32: Bảng B | N32: TP. Hồ Chí Minh | P32: Có | S32: PM 0808 | SuperAd test DN -> HCM | T32: Nhung | U32: knm
A33: FB Lead Form v2 | B33: 26 | C33: PT-145 | D33: Giữ (lead mới) | E33: S5 | F33: 46273.111 | G33: Hoàng Gia Lâm | H33: Hoàng Gia Lâm | I33: hoanggialam689@gmail.com | J33: hoanggialam689@gmail.com | K33: 0814990681 | L33: p:+84814990681 | M33: Bảng A | N33: TP. Hồ Chí Minh | P33: Có | S33: 1808 Lead | Uni | T33: Thắng | U33: knm
A34: FB Lead Form v2 | B34: 27 | C34: PT-023 | D34: Đã có trong Data – gộp vào hồ sơ | E34: S1 | F34: 46252.902 | G34: Phan Anh Ngân | H34: Phan Anh Ngân | I34: phananhngan@gmail.com | J34: phananhngan@gmail.com | K34: 0938895089 | L34: p:+84938895089 | M34: Bảng B | N34: Thành Phố Thủ Đức | P34: Có | S34: PM 1808 | SuperAds test3 | T34: Nhung | U34: knm
A35: FB Lead Form v2 | B35: 28 | C35: PT-001 | D35: Đã có trong Data – gộp vào hồ sơ | E35: S1 | F35: 46251.797 | G35: Dương Nam | H35: Dương Nam | I35: duonghoainam380@gmail.com | J35: duonghoainam380@gmail.com | K35: 0833008389 | L35: p:+84833008389 | M35: Bảng B | N35: TP. Hồ Chí Minh | P35: Có | S35: 1808 Lead | Uni | T35: Tùng | U35: đã call, đang cân nhắc
A36: FB Lead Form v2 | B36: 29 | C36: PT-131 | D36: Trùng trong file ngoài – gộp | E36: S5 | F36: 46247.193 | G36: Do Bao Thao | H36: Do Bao Thao | I36: dobaothao@icloud.com | J36: dobaothao@icloud.com | K36: 0357780225 | L36: p:+84357780225 | M36: Bảng B | N36: Đà Nẵng | P36: Có | S36: SuperAd test2
A37: FB Lead Form v2 | B37: 30 | C37: PT-137 | D37: Giữ (lead mới) | E37: S5 | F37: 46256.803 | G37: Phạm Hải Quân | H37: Phạm Hải Quân | I37: phamhaiquan2008@gmail.com | J37: phamhaiquan2008@gmail.com | K37: 0885034519 | L37: p:+84885034519 | M37: Bảng B | N37: Hà Nội | P37: Có | S37: 1808 Lead | Uni | U37: knm | 16/9 ko nghe máy đã nhắn zl
A38: FB Lead Form v2 | B38: 31 | C38: PT-145 | D38: Trùng trong file ngoài – gộp | E38: S5 | F38: 46273.111 | G38: Hoàng Gia Lâm | H38: Hoàng Gia Lâm | I38: hoanggialam689@gmail.com | J38: hoanggialam689@gmail.com | K38: 0814990681 | L38: p:+84814990681 | M38: Bảng A | N38: TP. Hồ Chí Minh | P38: Có | S38: 1808 Lead | Uni | T38: Thắng | U38: knm
A39: FB Lead Form v2 | B39: 32 | C39: PT-138 | D39: Giữ (lead mới) | E39: S5 | F39: 46259.9 | G39: Phạm Ngọc Tâm | H39: Phạm Ngọc Tâm | I39: phamngoctam@icloud.com | J39: phamngoctam@icloud.com | K39: 0391056402 | L39: p:+84391056402 | M39: Bảng B | N39: TP. Hồ Chí Minh | P39: Không | S39: PM 0808 | SuperAd test DN -> HCM | T39: Thắng | U39: knm
A40: Talkshow Google Form | B40: 2 | C40: PT-124 | D40: Giữ (lead mới) | E40: S4 | F40: 46260.808 | G40: Lâm Bảo Hiếu | H40: Lâm Bảo Hiếu | I40: lambaohieu361@yahoo.com | J40: lambaohieu361@yahoo.com | K40: 0829280955 | L40: 0829280955 | M40: Bảng B | O40: Học viện công nghệ bưu chính viễn thông | P40: Có | Q40: Chưa đăng ký vì còn thắc mắc | R40: Em muốn hỏi lệ phí thi bao nhiêu ạ? | S40: Nhà trường, thầy cô hoặc bạn bè giới thiệu | T40: Nhung
A41: Talkshow Google Form | B41: 3 | C41: PT-042 | D41: Đã có trong Data – gộp vào hồ sơ | E41: S1 | F41: 46267.913 | G41: Phạm Văn Khôi | H41: Phạm Văn Khôi | I41: pha69dcat323@student.ptithcm.edu.vn | J41: pha69dcat323@student.ptithcm.edu.vn | K41: 0940479450 | L41: 0940479450 | M41: Bảng B | O41: Học viện Công nghệ Bưu chính Viễn thông | P41: Có | Q41: Chưa đăng ký vì còn thắc mắc | R41: Em học Python cơ bản thì thi được không? | S41: Bạn bè giới thiệu | T41: Thắng
...

Sheet Duplicate_Log
A1: DUPLICATE_LOG — Nhật ký gộp trùng (audit trail)
A2: • Mọi thao tác gộp phải ghi lại: nguồn, dòng gốc, lý do, bản ghi được giữ – bắt buộc khi migrate CRM.
A3: • Khi thí sinh khiếu nại “em đăng ký rồi”, log này cho biết dòng nào đã bị gộp và vì sao.
A4: • Tổng cộng 46 bản ghi bị gộp: 13 từ sheet Data, 33 từ 2 form ngoài.
A5: • Bài tập: thử gộp chỉ bằng email, rồi chỉ bằng SĐT, so với log này để thấy rủi ro gộp nhầm.
A7: Nguồn | B7: Dòng gốc | C7: Contact ID | D7: Họ tên (gốc) | E7: Email (gốc) | F7: payment_status | G7: Lý do
A8: Data | B8: 2 | C8: PT-001 | D8: Dương Hoài Nam | E8: duonghoainam380@gmail.com | F8: chưa thanh toán | G8: Trùng email – giữ dòng 11 (completed)
A9: Data | B9: 10 | C9: PT-004 | D9: Hồ Hữu Vy | E9: hoh43dcpt729@stu.ptit.edu.vn | F9: chưa thanh toán | G9: Trùng email – giữ dòng 12 (completed)
A10: Data | B10: 29 | C10: PT-009 | D10: Hoàng Anh Yến | E10: hoanganhyen@gmail.com | F10: chưa thanh toán | G10: Trùng email – giữ dòng 93 (completed)
A11: Data | B11: 44 | C11: PT-013 | D11: Phạm Thu Phong | E11: phamthuphong108@gmail.com | F11: chưa thanh toán | G11: Trùng email – giữ dòng 79 (completed)
A12: Data | B12: 48 | C12: PT-015 | D12: Lâm Thị Lan | E12: lam48dcat446@student.ptithcm.edu.vn | F12: chưa thanh toán | G12: Trùng email – giữ dòng 69 (completed)
A13: Data | B13: 55 | C13: PT-017 | D13: Đặng Xuân Giang | E13: dan51dcat637@student.ptithcm.edu.vn | F13: chưa thanh toán | G13: Trùng email – giữ dòng 67 (completed)
A14: Data | B14: 75 | C14: PT-026 | D14: Ngô Minh Nam | E14: ngominhnam2008@gmail.com | F14: chưa thanh toán | G14: Trùng email – giữ dòng 76 (completed)
A15: Data | B15: 78 | C15: PT-013 | D15: Phạm Thu Phong | E15: phamthuphong108@gmail.com | F15: chưa thanh toán | G15: Trùng email – giữ dòng 79 (completed)
A16: Data | B16: 84 | C16: PT-030 | D16: Nguyễn Đức Thành | E16: nguyenducthanh937@gmail.com | F16: chưa thanh toán | G16: Trùng SĐT + tên – giữ dòng 83 (completed)
A17: Data | B17: 96 | C17: PT-035 | D17: Hoàng Anh Dũng | E17: hoanganhdung.0409@gmail.com | F17: chưa thanh toán | G17: Trùng SĐT + tên – giữ dòng 106 (completed)
A18: Data | B18: 98 | C18: PT-035 | D18: Hoàng Anh Dũng | E18: hoanganhdung.0409@gmail.com | F18: chưa thanh toán | G18: Trùng SĐT + tên – giữ dòng 106 (completed)
A19: Data | B19: 102 | C19: PT-038 | D19: Lê Minh Tiến | E19: leminhtien@gmail.com | F19: chưa thanh toán | G19: Trùng SĐT + tên – giữ dòng 132 (completed)
A20: Data | B20: 103 | C20: PT-038 | D20: Lê Minh Tiến | E20: lem79dcvt131@student.ptithcm.edu.vn | F20: chưa thanh toán | G20: Trùng email – giữ dòng 132 (completed)
A21: FB Lead Form v2 | B21: 28 | C21: PT-001 | D21: Dương Nam | E21: duonghoainam380@gmail.com | G21: Đã có trong Data – gộp vào hồ sơ
A22: Talkshow Google Form | B22: 6 | C22: PT-005 | D22: Võ Phương Phúc | E22: vophuongphuc@gmail.com | G22: Đã có trong Data – gộp vào hồ sơ
A23: Talkshow Google Form | B23: 25 | C23: PT-005 | D23: Võ Phương Phúc | E23: vophuongphuc@gmail.com | G23: Đã có trong Data – gộp vào hồ sơ
A24: Talkshow Google Form | B24: 28 | C24: PT-005 | D24: Võ Phương Phúc | E24: vophuongphuc@gmai.com | G24: Đã có trong Data – gộp vào hồ sơ
A25: Talkshow Google Form | B25: 17 | C25: PT-013 | D25: Phạm Thu Phong | E25: phamthuphong108@gmail.com | G25: Đã có trong Data – gộp vào hồ sơ
A26: Talkshow Google Form | B26: 22 | C26: PT-016 | D26: Lê Hải Vy | E26: lehaivy924@gmail.com | G26: Đã có trong Data – gộp vào hồ sơ
A27: FB Lead Form v2 | B27: 27 | C27: PT-023 | D27: Phan Anh Ngân | E27: phananhngan@gmail.com | G27: Đã có trong Data – gộp vào hồ sơ
A28: Talkshow Google Form | B28: 8 | C28: PT-024 | D28: Dương Hữu Nhi | E28: duo63dcpt410@student.ptithcm.edu.vn | G28: Đã có trong Data – gộp vào hồ sơ
A29: FB Lead Form v2 | B29: 4 | C29: PT-026 | D29: Ngo Minh Nam | E29: ngominhnam2008@gmail.con | G29: Đã có trong Data – gộp vào hồ sơ
A30: Talkshow Google Form | B30: 13 | C30: PT-028 | D30: Phan Thu Huy | E30: phanthuhuy262@gmail.com | G30: Đã có trong Data – gộp vào hồ sơ
A31: FB Lead Form v2 | B31: 23 | C31: PT-029 | D31: Ngô Ngọc Toàn | E31: ngongoctoan554@gmail.com | G31: Đã có trong Data – gộp vào hồ sơ
A32: Talkshow Google Form | B32: 7 | C32: PT-031 | D32: Đinh Minh Phúc | E32: dinhminhphuc@gmail.com | G32: Đã có trong Data – gộp vào hồ sơ
... A53: FB Lead Form v2 | B53: 31 | C53: PT-145 | D53: Hoàng Gia Lâm | E53: hoanggialam689@gmail.com | G53: Trùng trong file ngoài – gộp

Sheet Data_Quality
A1: DATA_QUALITY — Nhật ký lỗi & chuẩn hoá dữ liệu
A2: • Liệt kê từng lỗi kèm giá trị trước và sau khi sửa, dùng để báo cáo chất lượng dữ liệu đầu vào.
A3: • 5 nhóm lỗi: email sai tên miền, email thiếu, SĐT sai định dạng, tỉnh/thành và tên trường không đồng nhất.
A4: • Nguyên nhân gốc là form nhập tự do; giải pháp là dropdown danh mục và validate ngay trên form.
A5: • Hậu quả thực tế: email sai thì thí sinh không nhận được tài khoản ôn thi và thông tin phòng thi.
A7: Loại vấn đề | B7: Nguồn | C7: Dòng gốc | D7: Giá trị gốc | E7: Giá trị sau chuẩn hoá | F7: Ghi chú
A8: Chuẩn hoá tên trường | B8: Data | C8: 2 | D8: Học viện Công nghệ Bưu Chính Viễn Thông - PTIT. | E8: School A | F8: Quy về 1 tên trường chuẩn trong danh mục
A9: Chuẩn hoá tên trường | B9: Data | C9: 3 | D9: PTIT | E9: School A | F9: Quy về 1 tên trường chuẩn trong danh mục
A10: Chuẩn hoá tên trường | B10: Data | C10: 4 | D10: Học viện Công nghệ Bưu chính Viễn thông - PTIT | E10: School A | F10: Quy về 1 tên trường chuẩn trong danh mục
A11: Chuẩn hoá tên trường | B11: Data | C11: 5 | D11: Học viện Công nghệ Bưu Chính Viễn Thông - PTIT | E11: School A | F11: Quy về 1 tên trường chuẩn trong danh mục
A12: Chuẩn hoá tên trường | B12: Data | C12: 6 | D12: Học viện Công nghệ Bưu chính Viễn thông | E12: School A | F12: Quy về 1 tên trường chuẩn trong danh mục
A13: Chuẩn hoá tên trường | B13: Data | C13: 7 | D13: Học viện Công nghệ Bưu chính Viễn thông | E13: School A | F13: Quy về 1 tên trường chuẩn trong danh mục
A14: Chuẩn hoá tên trường | B14: Data | C14: 8 | D14: PTIT | E14: School A | F14: Quy về 1 tên trường chuẩn trong danh mục
A15: Chuẩn hoá tên trường | B15: Data | C15: 9 | D15: Học viện Công nghệ Bưu chính Viễn thông - PTIT | E15: School A | F15: Quy về 1 tên trường chuẩn trong danh mục
A16: Chuẩn hoá tên trường | B16: Data | C16: 10 | D16: Học viện Công Nghệ Bưu Chính Viễn Thông - PTIT | E16: School A | F16: Quy về 1 tên trường chuẩn trong danh mục
A17: Chuẩn hoá tên trường | B17: Data | C17: 11 | D17: Học viện Công nghệ Bưu Chính Viễn Thông - PTIT | E17: School A | F17: Quy về 1 tên trường chuẩn trong danh mục
A18: Chuẩn hoá tên trường | B18: Data | C18: 12 | D18: Học viện Công nghệ Bưu Chính Viễn Thông - PTIT. | E18: School A | F18: Quy về 1 tên trường chuẩn trong danh mục
A19: Chuẩn hoá tên trường | B19: Data | C19: 13 | D19: PTIT | E19: School A | F19: Quy về 1 tên trường chuẩn trong danh mục
... A172: Chuẩn hoá số điện thoại | B172: Talkshow_GGForm | C172: 16 | D172: +84880497802 | E172: 0880497802 | F172: Đưa về dạng 10 số, bỏ tiền tố p:+84
A173: Email không hợp lệ | B173: Talkshow_GGForm | C173: 18 | F173: Bỏ trống – không liên hệ được qua email
A174: Chuẩn hoá email | B174: Talkshow_GGForm | C174: 28 | D174: vophuongphuc@gmai.com | E174: vophuongphuc@gmail.com | F174: Bỏ khoảng trắng / sửa tên miền gõ nhầm (.con, gmai)
A175: Chuẩn hoá số điện thoại | B175: FB Form v2 | C175: 2 | D175: p:+84962519652 | E175: 0962519652 | F175: Đưa về dạng 10 số, bỏ tiền tố p:+84
A176: Chuẩn hoá số điện thoại | B176: FB Form v2 | C176: 3 | D176: p:+84364050093 | E176: 0364050093 | F176: Đưa về dạng 10 số, bỏ tiền tố p:+84
A177: Chuẩn hoá email | B177: FB Form v2 | C177: 4 | D177: ngominhnam2008@gmail.con | E177: ngominhnam2008@gmail.com | F177: Bỏ khoảng trắng / sửa tên miền gõ nhầm (.con, gmai)
A178: Chuẩn hoá số điện thoại | B178: FB Form v2 | C178: 4 | D178: p:+84799696057 | E178: 0799696057 | F178: Đưa về dạng 10 số, bỏ tiền tố p:+84
A179: Chuẩn hoá số điện thoại | B179: FB Form v2 | C179: 5 | D179: p:+84378513033 | E179: 0378513033 | F179: Đưa về dạng 10 số, bỏ tiền tố p:+84
A180: Chuẩn hoá số điện thoại | B180: FB Form v2 | C180: 6 | D180: p:+84783504437 | E180: 0783504437 | F180: Đưa về dạng 10 số, bỏ tiền tố p:+84
A181: Chuẩn hoá số điện thoại | B181: FB Form v2 | C181: 7 | D181: p:+84357780225 | E181: 0357780225 | F181: Đưa về dạng 10 số, bỏ tiền tố p:+84
A182: Chuẩn hoá số điện thoại | B182: FB Form v2 | C182: 8 | D182: p:+84831590359 | E182: 0831590359 | F182: Đưa về dạng 10 số, bỏ tiền tố p:+84
A183: Chuẩn hoá số điện thoại | B183: FB Form v2 | C183: 9 | D183: p:+84768634349 | E183: 0768634349 | F183: Đưa về dạng 10 số, bỏ tiền tố p:+84
A184: Chuẩn hoá số điện thoại | B184: FB Form v2 | C184: 10 | D184: p:+84886556000 | E184: 0886556000 | F184: Đưa về dạng 10 số, bỏ tiền tố p:+84
A185: Chuẩn hoá số điện thoại | B185: FB Form v2 | C185: 11 | D185: p:+84381290678 | E185: 0381290678 | F185: Đưa về dạng 10 số, bỏ tiền tố p:+84
... A207: Chuẩn hoá số điện thoại | B207: FB Form v2 | C207: 32 | D207: p:+84391056402 | E207: 0391056402 | F207: Đưa về dạng 10 số, bỏ tiền tố p:+84

Sheet Drip_Segments
A1: DRIP_SEGMENTS — Phân nhóm để chạy email marketing
A2: • CRM chỉ hiệu quả khi mỗi liên hệ thuộc đúng 1 nhóm, có điều kiện vào và ra rõ ràng.
A3: • Segment suy ra từ 2 câu hỏi: đã đăng ký web chưa, đã thanh toán chưa, cộng lịch sử Talkshow/FB.
A4: • Khi trạng thái đổi (ví dụ thanh toán xong), liên hệ phải thoát drip cũ và sang drip mới.
A5: • Cột Số liên hệ là công thức COUNTIF chạy trên Master_Contacts, sửa Master là số tự cập nhật.
A7: Drip | B7: Segment | C7: Điều kiện vào | D7: Mục tiêu | E7: Điều kiện ra | F7: Số liên hệ | G7: Gửi được (có email)
A8: D1 | B8: S1 · Thí sinh đã thanh toán | C8: payment_status = completed / free | D8: Giữ nhiệt, hướng dẫn ôn thi và dự thi đầy đủ | E8: Sau kỳ thi | F8: =COUNTIF(Master_Contacts!$V$10:$V$154,"S1") -> 66 | G8: =COUNTIFS(Master_Contacts!$V$10:$V$154,"S1",Master_Contacts!$C$10:$C$154,"<>") -> 66
A9: D2 | B9: S2 · Đăng ký web + tương tác Talkshow/FB, chưa thanh toán | C9: Có trong Data, chưa thanh toán, có trong form ngoài | D9: Chốt thanh toán – nhóm ấm nhất, ưu tiên gọi trước | E9: Khi thanh toán → D1 | F9: =COUNTIF(Master_Contacts!$V$10:$V$154,"S2") -> 11 | G9: =COUNTIFS(Master_Contacts!$V$10:$V$154,"S2",Master_Contacts!$C$10:$C$154,"<>") -> 11
A10: D3 | B10: S3 · Đăng ký web, chưa thanh toán, không qua Talkshow/FB | C10: Có trong Data, chưa thanh toán, không có ở form ngoài | D10: Hâm nóng bằng nội dung + xử lý phản đối về giá | E10: Khi thanh toán → D1 | F10: =COUNTIF(Master_Contacts!$V$10:$V$154,"S3") -> 42 | G10: =COUNTIFS(Master_Contacts!$V$10:$V$154,"S3",Master_Contacts!$C$10:$C$154,"<>") -> 42
A11: D4 | B11: S4 · Lead Talkshow, chưa đăng ký thi | C11: Chỉ có ở Talkshow Google Form | D11: Đưa về website để đăng ký | E11: Khi xuất hiện trong Data → D2 | F11: =COUNTIF(Master_Contacts!$V$10:$V$154,"S4") -> 10 | G11: =COUNTIFS(Master_Contacts!$V$10:$V$154,"S4",Master_Contacts!$C$10:$C$154,"<>") -> 9
A12: D5 | B12: S5 · Lead FB Form, chưa đăng ký thi | C12: Chỉ có ở FB Lead Form | D12: Nuôi dưỡng bằng Talkshow, đề thi thử | E12: Khi đăng ký Talkshow → D4 | F12: =COUNTIF(Master_Contacts!$V$10:$V$154,"S5") -> 16 | G12: =COUNTIFS(Master_Contacts!$V$10:$V$154,"S5",Master_Contacts!$C$10:$C$154,"<>") -> 16

Sheet Bảng B – Hà Nội
A1: BẢNG B – HÀ NỘI — Danh sách thí sinh đã thanh toán (sản phẩm cuối)
A2: • Kết quả cuối: từ 3 nguồn thô đến danh sách thí sinh chính thức để xếp phòng thi.
A3: • Chỉ gồm payment_status = completed hoặc free; người chưa thanh toán thuộc drip D2/D3.
A4: • Cột Trường đã chuẩn hoá thành School A, minh hoạ việc đưa dữ liệu tự do về danh mục chuẩn.
A5: • Địa điểm thi suy ra từ khu vực; tỉnh lân cận gán về điểm thi gần nhất và cần gọi xác nhận lại.
A6: • Ngày thi và Giờ thi để trống vì chờ BTC chốt lịch, đây không phải lỗi thiếu dữ liệu.
A8: STT | B8: Contact ID | C8: Họ và tên | D8: Ngày sinh | E8: Số CCCD | F8: Email | G8: Số điện thoại | H8: Bảng | I8: Trường | J8: Khu vực | K8: Trạng thái thanh toán | L8: Lệ phí (VND) | M8: Địa điểm thi | N8: Ngày thi | O8: Giờ thi | P8: Ghi chú
A9: 1 | B9: PT-014 | C9: Bùi Khánh Vinh | D9: 2008-03-08 | E9: 031140145044 | F9: buikhanhvinh2006@gmail.com | G9: 0705097972 | H9: Bảng B | I9: School A | J9: Hà Nội | K9: Đã thanh toán | L9: 500000 | M9: Hà Nội – PTIT Hà Nội: 122 Hoàng Quốc Việt, Nghĩa Đô, Hà Nội
A10: 2 | B10: PT-001 | C10: Dương Hoài Nam | D10: 2006-09-26 | E10: 024710530855 | F10: duonghoainam380@gmail.com | G10: 0833008389 | H10: Bảng B | I10: School A | J10: Hà Nội | K10: Đã thanh toán | L10: 500000 | M10: Hà Nội – PTIT Hà Nội: 122 Hoàng Quốc Việt, Nghĩa Đô, Hà Nội | P10: Tên viết khác nhau giữa các nguồn
A11: 3 | B11: PT-034 | C11: Hoàng Nhật Lan | D11: 2006-01-27 | E11: 089782766836 | F11: hoangnhatlan@gmail.com | G11: 0781457070 | H11: Bảng B | I11: School A | J11: Hà Nội | K11: Đã thanh toán | L11: 500000 | M11: Hà Nội – PTIT Hà Nội: 122 Hoàng Quốc Việt, Nghĩa Đô, Hà Nội
A12: 4 | B12: PT-004 | C12: Hồ Hữu Vy | D12: 2006-03-22 | E12: 068471846224 | F12: hoh43dcpt729@stu.ptit.edu.vn | G12: 0762989538 | H12: Bảng B | I12: School A | J12: Hà Nội | K12: Đã thanh toán | L12: 500000 | M12: Hà Nội – PTIT Hà Nội: 122 Hoàng Quốc Việt, Nghĩa Đô, Hà Nội
A13: 5 | B13: PT-007 | C13: Lâm Hoài Yến | D13: 2006-09-18 | E13: 036861826221 | F13: lamhoaiyen@gmail.com | G13: 0828797715 | H13: Bảng B | I13: School A | J13: Hà Nội | K13: Miễn phí (free) | L13: 500000 | M13: Hà Nội – PTIT Hà Nội: 122 Hoàng Quốc Việt, Nghĩa Đô, Hà Nội
A14: 6 | B14: PT-002 | C14: Mai Minh Sơn | D14: 2007-01-10 | E14: 027887450948 | F14: maiminhson2005@gmail.com | G14: 0884396213 | H14: Bảng B | I14: School A | J14: Hà Nội | K14: Đã thanh toán | L14: 500000 | M14: Hà Nội – PTIT Hà Nội: 122 Hoàng Quốc Việt, Nghĩa Đô, Hà Nội
